File: SiC3/Temperature Dependance/SiC3_temp_dep.rso.dat.csv
[Header]
TITLE,MPMS RSO Measurement
BYAPP,MPMS Measurement,1.1,Summary
FILEOPENTIME, 1616827283.442000 3/27/2021, 7:41:23 AM

INFO, APPNAME, MPMS MultiVu Application, Revision 1.61,  Build 082

INFO, NAME, SF-14
INFO, WEIGHT, 24.596
INFO, AREA, 1.000
INFO, LENGTH, 1.000
INFO, SHAPE, 0
INFO, COMMENT, 47.366/22.770
INFO, SEQUENCE FILE: SiC_measuring_sequence.seq


INFO, BACKGROUND DATA FILE:, None


STARTUPAXIS,X,4,LINEAR,AUTO,0.000000,0.000000
STARTUPAXIS,Y1,5,LINEAR,AUTO,0.000000,0.000000


STARTUPGROUP,Longitudinal
FIELDGROUP,Longitudinal,1,2,3,4,5,6,7,8,9,10,11,19,20,21,22,23,35
FIELDGROUP,Transverse,1,2,3,4,12,13,14,15,16,17,18,24,25,26,27,28,35

PLOT_APPEARANCE,ALL,HORZ_GRID_ON,VERT_GRID_ON,MARKERS_AND_LINES

[Data]
Time,Comment,Field (Oe),Temperature (K),Long Moment (emu),Long Scan Std Dev,Long Offset (cm),Long Offset Std Dev,Long Algorithm,Long Reg Fit,Long Reg Factor,Trans Moment (emu),Trans Scan Std Dev,Trans Offset (cm),Trans Offset Std Dev,Trans Algorithm,Trans Reg Fit,Trans Reg Factor,Long Moment [w/o ABS] (emu),Long Scan Std Dev [w/o ABS],Long Offset [w/o ABS] (cm),Long Offset Std Dev [w/o ABS],Long Reg Fit [w/o ABS],Trans Moment [w/o ABS] (emu),Trans Scan Std Dev [w/o ABS],Trans Offset [w/o ABS] (cm),Trans Offset Std Dev [w/o ABS],Trans Reg Fit [w/o ABS],RSO Position (deg),Amplitude (cm),Frequency,Cycles to Average,Scans per Measurement,Delta Temp (K),Error,EC Comp. Running,Using ABS,
1616827283.442,,1.000000e+003,5.002031e+000,-1.276542e-006,8.527150e-009,2.921872e-001,5.792981e-003,3,6.457057e-001,1.825000e+000,,,,,,,,,,,,,,,,,,0,3.000000e+000,1.000000e+000,10,5,3.976822e-003,0,,0,
1616827549.746,,1.000000e+003,1.000329e+001,-1.446804e-006,7.165363e-009,2.274187e-001,9.646987e-004,3,6.866090e-001,1.825000e+000,,,,,,,,,,,,,,,,,,0,3.000000e+000,1.000000e+000,10,5,6.149292e-003,0,,0,
1616827815.576,,1.000000e+003,1.500162e+001,-1.506645e-006,5.438397e-009,2.111110e-001,3.641492e-003,3,7.017139e-001,1.825000e+000,,,,,,,,,,,,,,,,,,0,3.000000e+000,1.000000e+000,10,5,7.040024e-003,0,,0,
1616828082.794,,1.000000e+003,1.999851e+001,-1.539345e-006,6.946562e-009,2.008952e-001,4.547289e-003,3,7.066930e-001,1.825000e+000,,,,,,,,,,,,,,,,,,0,3.000000e+000,1.000000e+000,10,5,8.180618e-003,0,,0,
1616828391.362,,1.000000e+003,2.500070e+001,-1.561604e-006,8.647384e-009,1.957627e-001,3.045341e-003,3,7.110682e-001,1.825000e+000,,,,,,,,,,,,,,,,,,0,3.000000e+000,1.000000e+000,10,5,5.170822e-003,0,,0,
1616828708.177,,1.000000e+003,3.000084e+001,-1.572624e-006,3.601643e-009,1.972321e-001,4.341287e-003,3,7.122275e-001,1.825000e+000,,,,,,,,,,,,,,,,,,0,3.000000e+000,1.000000e+000,10,5,2.889633e-003,0,,0,
1616829036.309,,1.000000e+003,3.500146e+001,-1.578482e-006,6.722393e-009,1.952829e-001,2.380637e-003,3,7.133044e-001,1.825000e+000,,,,,,,,,,,,,,,,,,0,3.000000e+000,1.000000e+000,10,5,4.619598e-003,0,,0,
1616829365.342,,1.000000e+003,4.000027e+001,-1.592921e-006,6.578517e-009,1.916444e-001,5.105155e-003,3,7.153836e-001,1.825000e+000,,,,,,,,,,,,,,,,,,0,3.000000e+000,1.000000e+000,10,5,3.940582e-003,0,,0,
1616829663.997,,1.000000e+003,4.500034e+001,-1.589731e-006,6.034051e-009,1.955628e-001,4.291871e-003,3,7.174206e-001,1.825000e+000,,,,,,,,,,,,,,,,,,0,3.000000e+000,1.000000e+000,10,5,3.681183e-003,0,,0,
1616829946.460,,1.000000e+003,5.000587e+001,-1.601650e-006,5.946360e-009,1.949568e-001,6.972924e-004,3,7.179871e-001,1.825000e+000,,,,,,,,,,,,,,,,,,0,3.000000e+000,1.000000e+000,10,5,1.491928e-002,0,,0,
1616830223.095,,1.000000e+003,5.501099e+001,-1.598515e-006,4.837906e-009,1.949359e-001,5.659334e-003,3,7.178410e-001,1.825000e+000,,,,,,,,,,,,,,,,,,0,3.000000e+000,1.000000e+000,10,5,2.670288e-002,0,,0,
1616830501.549,,1.000000e+003,6.001238e+001,-1.604920e-006,8.057591e-009,1.993279e-001,3.486497e-003,3,7.148113e-001,1.825000e+000,,,,,,,,,,,,,,,,,,0,3.000000e+000,1.000000e+000,10,5,2.725983e-002,0,,0,
1616830782.696,,1.000000e+003,6.501949e+001,-1.610828e-006,4.597236e-009,1.978563e-001,6.129224e-003,3,7.162664e-001,1.825000e+000,,,,,,,,,,,,,,,,,,0,3.000000e+000,1.000000e+000,10,5,3.896332e-002,0,,0,
1616831066.237,,1.000000e+003,7.002486e+001,-1.612066e-006,6.917007e-009,1.941110e-001,1.954764e-003,3,7.165313e-001,1.825000e+000,,,,,,,,,,,,,,,,,,0,3.000000e+000,1.000000e+000,10,5,4.193878e-002,0,,0,
1616831353.760,,1.000000e+003,7.502831e+001,-1.614990e-006,4.208831e-009,1.998462e-001,2.230920e-003,3,7.102206e-001,1.825000e+000,,,,,,,,,,,,,,,,,,0,3.000000e+000,1.000000e+000,10,5,5.407715e-002,0,,0,
1616831659.485,,1.000000e+003,8.002114e+001,-1.615397e-006,9.501870e-009,2.021801e-001,2.781529e-003,3,7.095680e-001,1.825000e+000,,,,,,,,,,,,,,,,,,0,3.000000e+000,1.000000e+000,10,5,3.227234e-002,0,,0,
1616831945.432,,1.000000e+003,8.503798e+001,-1.623748e-006,6.706583e-009,2.075493e-001,4.233170e-003,3,7.097529e-001,1.825000e+000,,,,,,,,,,,,,,,,,,0,3.000000e+000,1.000000e+000,10,5,7.217407e-002,0,,0,
1616832229.993,,1.000000e+003,9.003972e+001,-1.626226e-006,6.767391e-009,2.054095e-001,1.891763e-003,3,7.098007e-001,1.825000e+000,,,,,,,,,,,,,,,,,,0,3.000000e+000,1.000000e+000,10,5,7.125092e-002,0,,0,
1616832515.985,,1.000000e+003,9.504279e+001,-1.628770e-006,7.142701e-009,2.081374e-001,5.117856e-003,3,7.068877e-001,1.825000e+000,,,,,,,,,,,,,,,,,,0,3.000000e+000,1.000000e+000,10,5,7.866669e-002,0,,0,
1616832799.015,,1.000000e+003,1.000501e+002,-1.627648e-006,6.178491e-009,2.085416e-001,4.064174e-003,3,7.042527e-001,1.825000e+000,,,,,,,,,,,,,,,,,,0,3.000000e+000,1.000000e+000,10,5,9.189606e-002,0,,0,
1616833076.087,,1.000000e+003,1.050605e+002,-1.734584e-006,4.351568e-008,8.994564e-002,3.847509e-002,3,8.893765e-001,1.825000e+000,,,,,,,,,,,,,,,,,,0,3.000000e+000,1.000000e+000,10,5,8.879852e-002,0,,0,
1616833353.273,,1.000000e+003,1.100651e+002,-1.766023e-006,5.357235e-009,7.566307e-002,3.840446e-003,3,9.198970e-001,1.825000e+000,,,,,,,,,,,,,,,,,,0,3.000000e+000,1.000000e+000,10,5,1.131973e-001,0,,0,
1616833628.950,,1.000000e+003,1.150719e+002,-1.764844e-006,4.124412e-009,7.742558e-002,2.905289e-003,3,9.221706e-001,1.825000e+000,,,,,,,,,,,,,,,,,,0,3.000000e+000,1.000000e+000,10,5,1.265030e-001,0,,0,
1616833924.694,,1.000000e+003,1.200521e+002,-1.773166e-006,3.525189e-009,7.612659e-002,2.177833e-003,3,9.256941e-001,1.825000e+000,,,,,,,,,,,,,,,,,,0,3.000000e+000,1.000000e+000,10,5,1.215973e-001,0,,0,
1616834201.375,,1.000000e+003,1.250694e+002,-1.772293e-006,2.988069e-009,7.850137e-002,1.219315e-003,3,9.185307e-001,1.825000e+000,,,,,,,,,,,,,,,,,,0,3.000000e+000,1.000000e+000,10,5,1.352997e-001,0,,0,
1616834479.075,,1.000000e+003,1.300620e+002,-1.781103e-006,9.413679e-009,7.815347e-002,2.295472e-003,3,9.222118e-001,1.825000e+000,,,,,,,,,,,,,,,,,,0,3.000000e+000,1.000000e+000,10,5,1.013947e-001,0,,0,
1616834759.581,,1.000000e+003,1.350627e+002,-1.784674e-006,1.845609e-009,8.129917e-002,2.553898e-003,3,9.192956e-001,1.825000e+000,,,,,,,,,,,,,,,,,,0,3.000000e+000,1.000000e+000,10,5,1.181946e-001,0,,0,
1616835044.294,,1.000000e+003,1.400614e+002,-1.788865e-006,6.831350e-009,8.271854e-002,1.730438e-003,3,9.202491e-001,1.825000e+000,,,,,,,,,,,,,,,,,,0,3.000000e+000,1.000000e+000,10,5,1.365967e-001,0,,0,
1616835330.965,,1.000000e+003,1.450599e+002,-1.796062e-006,9.539542e-009,8.511443e-002,5.260885e-003,3,9.213474e-001,1.825000e+000,,,,,,,,,,,,,,,,,,0,3.000000e+000,1.000000e+000,10,5,1.296082e-001,0,,0,
1616835618.222,,1.000000e+003,1.500625e+002,-1.798971e-006,1.272521e-008,8.466585e-002,3.634259e-003,3,9.205069e-001,1.825000e+000,,,,,,,,,,,,,,,,,,0,3.000000e+000,1.000000e+000,10,5,1.381989e-001,0,,0,
1616835905.690,,1.000000e+003,1.550572e+002,-1.810980e-006,6.685251e-009,8.509017e-002,1.634035e-003,3,9.192913e-001,1.825000e+000,,,,,,,,,,,,,,,,,,0,3.000000e+000,1.000000e+000,10,5,1.409912e-001,0,,0,
1616836196.380,,1.000000e+003,1.600614e+002,-1.807090e-006,5.314061e-009,9.098912e-002,3.640811e-003,3,9.177993e-001,1.825000e+000,,,,,,,,,,,,,,,,,,0,3.000000e+000,1.000000e+000,10,5,1.302032e-001,0,,0,
1616836486.163,,1.000000e+003,1.650590e+002,-1.811153e-006,6.929233e-009,8.975559e-002,3.373442e-003,3,9.192435e-001,1.825000e+000,,,,,,,,,,,,,,,,,,0,3.000000e+000,1.000000e+000,10,5,1.519012e-001,0,,0,
1616836777.824,,1.000000e+003,1.700603e+002,-1.818216e-006,3.201429e-009,9.283334e-002,4.599425e-003,3,9.189820e-001,1.825000e+000,,,,,,,,,,,,,,,,,,0,3.000000e+000,1.000000e+000,10,5,1.464081e-001,0,,0,
1616837070.978,,1.000000e+003,1.750543e+002,-1.815659e-006,7.493127e-009,9.468509e-002,2.293699e-003,3,9.190460e-001,1.825000e+000,,,,,,,,,,,,,,,,,,0,3.000000e+000,1.000000e+000,10,5,1.470032e-001,0,,0,
1616837362.262,,1.000000e+003,1.800541e+002,-1.819869e-006,8.688992e-009,9.483363e-002,1.115285e-003,3,9.169644e-001,1.825000e+000,,,,,,,,,,,,,,,,,,0,3.000000e+000,1.000000e+000,10,5,1.306915e-001,0,,0,
1616837654.794,,1.000000e+003,1.850552e+002,-1.829633e-006,8.442463e-009,9.938002e-002,6.032252e-003,3,9.143590e-001,1.825000e+000,,,,,,,,,,,,,,,,,,0,3.000000e+000,1.000000e+000,10,5,1.464996e-001,0,,0,
1616837947.118,,1.000000e+003,1.900526e+002,-1.822745e-006,4.434556e-009,9.963126e-002,2.281480e-003,3,9.165798e-001,1.825000e+000,,,,,,,,,,,,,,,,,,0,3.000000e+000,1.000000e+000,10,5,1.451111e-001,0,,0,
1616838275.649,,1.000000e+003,1.950137e+002,-1.835370e-006,7.312660e-009,9.805207e-002,3.046188e-003,3,9.161665e-001,1.825000e+000,,,,,,,,,,,,,,,,,,0,3.000000e+000,1.000000e+000,10,5,4.779053e-002,0,,0,
1616838605.257,,1.000000e+003,2.000146e+002,-1.842158e-006,1.255091e-008,1.044683e-001,4.172846e-003,3,9.200398e-001,1.825000e+000,,,,,,,,,,,,,,,,,,0,3.000000e+000,1.000000e+000,10,5,5.010986e-002,0,,0,
1616838933.772,,1.000000e+003,2.050420e+002,-1.840686e-006,1.062406e-008,1.016438e-001,4.193847e-003,3,9.174747e-001,1.825000e+000,,,,,,,,,,,,,,,,,,0,3.000000e+000,1.000000e+000,10,5,1.681976e-001,0,,0,
1616839249.148,,1.000000e+003,2.100474e+002,-1.850321e-006,4.121171e-009,1.070191e-001,3.271746e-003,3,9.149225e-001,1.825000e+000,,,,,,,,,,,,,,,,,,0,3.000000e+000,1.000000e+000,10,5,1.654053e-001,0,,0,
1616839580.813,,1.000000e+003,2.150298e+002,-1.848945e-006,1.738037e-008,1.071290e-001,5.180888e-003,3,9.159601e-001,1.825000e+000,,,,,,,,,,,,,,,,,,0,3.000000e+000,1.000000e+000,10,5,1.560059e-001,0,,0,
1616839879.823,,1.000000e+003,2.200479e+002,-1.855588e-006,4.950535e-009,1.106367e-001,3.368629e-003,3,9.158375e-001,1.825000e+000,,,,,,,,,,,,,,,,,,0,3.000000e+000,1.000000e+000,10,5,1.452026e-001,0,,0,
1616840177.555,,1.000000e+003,2.250496e+002,-1.862684e-006,1.329589e-008,1.104539e-001,4.775957e-003,3,9.173579e-001,1.825000e+000,,,,,,,,,,,,,,,,,,0,3.000000e+000,1.000000e+000,10,5,1.582031e-001,0,,0,
1616840475.601,,1.000000e+003,2.300501e+002,-1.866395e-006,1.526261e-008,1.161203e-001,5.136156e-003,3,9.161634e-001,1.825000e+000,,,,,,,,,,,,,,,,,,0,3.000000e+000,1.000000e+000,10,5,1.454010e-001,0,,0,
1616840761.968,,1.000000e+003,2.350770e+002,-1.874679e-006,4.730496e-009,1.215066e-001,2.271548e-003,3,9.157690e-001,1.825000e+000,,,,,,,,,,,,,,,,,,0,3.000000e+000,1.000000e+000,10,5,2.071991e-001,0,,0,
1616841060.274,,1.000000e+003,2.400429e+002,-1.878810e-006,6.867171e-009,1.226145e-001,4.172317e-003,3,9.183946e-001,1.825000e+000,,,,,,,,,,,,,,,,,,0,3.000000e+000,1.000000e+000,10,5,1.585999e-001,0,,0,
1616841361.519,,1.000000e+003,2.450458e+002,-1.881581e-006,8.305253e-009,1.278269e-001,3.263048e-003,3,9.146169e-001,1.825000e+000,,,,,,,,,,,,,,,,,,0,3.000000e+000,1.000000e+000,10,5,1.428070e-001,0,,0,
1616841661.360,,1.000000e+003,2.500466e+002,-1.882056e-006,4.023896e-009,1.238162e-001,2.003084e-003,3,9.189336e-001,1.825000e+000,,,,,,,,,,,,,,,,,,0,3.000000e+000,1.000000e+000,10,5,1.643982e-001,0,,0,
1616841961.082,,1.000000e+003,2.550437e+002,-1.883485e-006,1.596675e-008,1.305578e-001,5.064109e-003,3,9.218431e-001,1.825000e+000,,,,,,,,,,,,,,,,,,0,3.000000e+000,1.000000e+000,10,5,1.466980e-001,0,,0,
1616842262.180,,1.000000e+003,2.600455e+002,-1.883016e-006,1.249791e-008,1.320261e-001,2.642847e-003,3,9.160529e-001,1.825000e+000,,,,,,,,,,,,,,,,,,0,3.000000e+000,1.000000e+000,10,5,1.442261e-001,0,,0,
1616842564.671,,1.000000e+003,2.650420e+002,-1.908516e-006,8.488445e-009,1.320665e-001,1.377245e-003,3,9.187805e-001,1.825000e+000,,,,,,,,,,,,,,,,,,0,3.000000e+000,1.000000e+000,10,5,1.412048e-001,0,,0,
1616842908.855,,1.000000e+003,2.700248e+002,-1.910213e-006,1.385525e-008,1.394318e-001,4.353064e-003,3,9.149640e-001,1.825000e+000,,,,,,,,,,,,,,,,,,0,3.000000e+000,1.000000e+000,10,5,1.376953e-001,0,,0,
1616843210.414,,1.000000e+003,2.750364e+002,-1.906147e-006,4.766352e-009,1.400730e-001,2.055150e-003,3,9.156009e-001,1.825000e+000,,,,,,,,,,,,,,,,,,0,3.000000e+000,1.000000e+000,10,5,1.336975e-001,0,,0,
1616843538.433,,1.000000e+003,2.800064e+002,-1.910738e-006,7.478156e-009,1.434548e-001,1.498747e-003,3,9.150634e-001,1.825000e+000,,,,,,,,,,,,,,,,,,0,3.000000e+000,1.000000e+000,10,5,3.961182e-002,0,,0,
1616843882.387,,1.000000e+003,2.850020e+002,-1.918872e-006,2.824795e-009,1.499780e-001,3.350457e-003,3,9.151710e-001,1.825000e+000,,,,,,,,,,,,,,,,,,0,3.000000e+000,1.000000e+000,10,5,2.059937e-002,0,,0,
1616844185.484,,1.000000e+003,2.900351e+002,-1.921341e-006,4.358019e-009,1.537339e-001,2.791163e-003,3,9.180064e-001,1.825000e+000,,,,,,,,,,,,,,,,,,0,3.000000e+000,1.000000e+000,10,5,1.281738e-001,0,,0,
1616844491.511,,1.000000e+003,2.950312e+002,-1.925617e-006,4.075221e-009,1.595055e-001,2.128486e-003,3,9.153436e-001,1.825000e+000,,,,,,,,,,,,,,,,,,0,3.000000e+000,1.000000e+000,10,5,1.218262e-001,0,,0,
1616844797.826,,1.000000e+003,3.000400e+002,-1.932872e-006,5.743077e-009,1.671771e-001,2.379274e-003,3,9.123480e-001,1.825000e+000,,,,,,,,,,,,,,,,,,0,3.000000e+000,1.000000e+000,10,5,1.262817e-001,0,,0,