File: SiC3/Temperature Dependance/SiC3_temp_dep.rso.raw
[Header]
TITLE,MPMS RSO Measurement
BYAPP,MPMS Measurement,2.1,Raw with ABS
FILEOPENTIME, 1616827283.442000 3/27/2021, 7:41:23 AM

INFO, APPNAME, MPMS MultiVu Application, Revision 1.61,  Build 082

INFO, NAME, SF-14
INFO, WEIGHT, 24.596
INFO, AREA, 1.000
INFO, LENGTH, 1.000
INFO, SHAPE, 0
INFO, COMMENT, 47.366/22.770
INFO, SEQUENCE FILE: SiC_measuring_sequence.seq


INFO, BACKGROUND DATA FILE:, None


STARTUPAXIS,X,8,LINEAR,AUTO,0.000000,0.000000
STARTUPAXIS,Y1,9,LINEAR,AUTO,0.000000,0.000000


STARTUPGROUP,Longitudinal
FIELDGROUP,Longitudinal,1,2,3,4,5,6,7,8,9,10,11,12,13,14,15,16,17,18,19,20,21,22
FIELDGROUP,Transverse,1,2,3,4,5,6,7,8,23,24,25,26,27,28,29,30,31,32,33,34,35,36

PLOT_APPEARANCE,ALL,HORZ_GRID_ON,VERT_GRID_ON,MARKERS_ONLY

[Data]
Time,Comment,Field (Oe),Start Temperature (K),End Temperature (K),Scan,Rejected,Position (cm),Long Voltage,Long Average Voltage,Long Detrended Voltage,Long Demeaned Voltage,Long Reg Fit,Long Detrended Fit,Long Demeaned Fit,Long Scaled Response,Long Avg. Scaled Response,Long Background Response,Long Response [w/ABS],Long Detrended Resp. [w/ABS],Long Fit [w/ABS],Long Detrended Fit [w/ABS],Trans Voltage,Trans Average Voltage,Trans Detrended Voltage,Trans Demeaned Voltage,Trans Reg Fit,Trans Detrended Fit,Trans Demeaned Fit,Trans Scaled Response,Trans Avg. Scaled Response,Trans Background Response,Trans Response [w/ABS],Trans Detrended Resp. [w/ABS],Trans Adjusted Fit,Trans Detrended Fit [w/ABS],
1616827283.442,,1.000000e+003,5.004889e+000,5.002794e+000,1,0,2.066901e+000,5.182043e-001,,,,,,,1.277356e-005,,,,,,,,,,,,,,,,,,,,,
1616827283.442,,1.000000e+003,5.004889e+000,5.002794e+000,1,0,2.790000e+000,6.154057e-001,,,,,,,1.516955e-005,,,,,,,,,,,,,,,,,,,,,
1616827283.442,,1.000000e+003,5.002794e+000,5.001853e+000,2,0,3.337495e+000,5.565050e-001,,,,,,,1.371766e-005,,,,,,,,,,,,,,,,,,,,,
1616827283.442,,1.000000e+003,5.001853e+000,5.001330e+000,3,0,3.460844e+000,5.511643e-001,,,,,,,1.358602e-005,,,,,,,,,,,,,,,,,,,,,
1616827283.442,,1.000000e+003,5.001330e+000,5.000912e+000,4,0,2.969555e+000,5.494857e-001,,,,,,,1.354464e-005,,,,,,,,,,,,,,,,,,,,,
1616827283.442,,1.000000e+003,5.000912e+000,5.001644e+000,5,0,2.204126e+000,5.011140e-001,5.052950e-001,-7.513471e-002,-5.131805e-002,4.944397e-001,-8.599000e-002,-6.217334e-002,1.235229e-005,1.245535e-005,,,,,,,,,,,,,,,,,,,,
1616827549.746,,1.000000e+003,1.000125e+001,1.000740e+001,1,0,1.432674e+000,5.966368e-001,,,,,,,1.470690e-005,,,,,,,,,,,,,,,,,,,,,
1616827549.746,,1.000000e+003,1.000740e+001,1.000363e+001,2,0,8.219406e-001,6.456191e-001,,,,,,,1.591429e-005,,,,,,,,,,,,,,,,,,,,,
1616827549.746,,1.000000e+003,1.000363e+001,1.000221e+001,3,0,5.068322e-001,6.869717e-001,,,,,,,1.693362e-005,,,,,,,,,,,,,,,,,,,,,
1616827549.746,,1.000000e+003,1.000221e+001,1.000174e+001,4,0,8.197287e-001,6.746116e-001,,,,,,,1.662895e-005,,,,,,,,,,,,,,,,,,,,,
1616827549.746,,1.000000e+003,1.000174e+001,1.000174e+001,5,0,1.528727e+000,5.580309e-001,5.565050e-001,-5.244521e-002,-4.986811e-002,5.761374e-001,-3.281281e-002,-3.023571e-002,1.375528e-005,1.371766e-005,,,,,,,,,,,,,,,,,,,,
1616827549.746,,1.000000e+003,1.000174e+001,1.000174e+001,5,0,2.326840e+000,5.858028e-001,5.807367e-001,-6.558149e-002,-2.563643e-002,5.492963e-001,-9.702193e-002,-5.707687e-002,1.443984e-005,1.431497e-005,,,,,,,,,,,,,,,,,,,,
1616827815.576,,1.000000e+003,1.500224e+001,1.500537e+001,1,0,2.993784e+000,5.790887e-001,,,,,,,1.427434e-005,,,,,,,,,,,,,,,,,,,,,
1616827815.576,,1.000000e+003,1.500537e+001,1.500224e+001,2,0,3.449352e+000,6.167791e-001,,,,,,,1.520340e-005,,,,,,,,,,,,,,,,,,,,,
1616827815.576,,1.000000e+003,1.500224e+001,1.499990e+001,3,0,3.351439e+000,6.155583e-001,,,,,,,1.517331e-005,,,,,,,,,,,,,,,,,,,,,
1616827815.576,,1.000000e+003,1.500067e+001,1.499990e+001,4,0,2.730202e+000,5.778680e-001,,,,,,,1.424425e-005,,,,,,,,,,,,,,,,,,,,,
1616827815.576,,1.000000e+003,1.499990e+001,1.499833e+001,5,0,1.934378e+000,4.843287e-001,5.121006e-001,-8.973101e-002,-7.150048e-002,5.139479e-001,-8.788368e-002,-6.965315e-002,1.193854e-005,1.262311e-005,,,,,,,,,,,,,,,,,,,,
1616828082.794,,1.000000e+003,2.000028e+001,1.999688e+001,1,0,1.211234e+000,5.127109e-001,,,,,,,1.263815e-005,,,,,,,,,,,,,,,,,,,,,
1616828082.794,,1.000000e+003,1.999688e+001,1.999347e+001,2,0,6.638509e-001,6.363109e-001,,,,,,,1.568485e-005,,,,,,,,,,,,,,,,,,,,,
1616828082.794,,1.000000e+003,1.999347e+001,1.999960e+001,3,0,5.403769e-001,6.277657e-001,,,,,,,1.547422e-005,,,,,,,,,,,,,,,,,,,,,
1616828082.794,,1.000000e+003,1.999960e+001,2.000165e+001,4,0,1.031567e+000,5.253761e-001,,,,,,,1.295035e-005,,,,,,,,,,,,,,,,,,,,,
1616828082.794,,1.000000e+003,2.000165e+001,2.000165e+001,5,0,1.797050e+000,4.319895e-001,4.339122e-001,-9.638810e-002,-9.560400e-002,4.554001e-001,-7.490018e-002,-7.411608e-002,1.064840e-005,1.069579e-005,,,,,,,,,,,,,,,,,,,,
1616828082.794,,1.000000e+003,2.000165e+001,2.000165e+001,5,0,2.568450e+000,4.953154e-001,5.001984e-001,-5.284083e-002,-2.931780e-002,4.736067e-001,-7.943249e-002,-5.590945e-002,1.220936e-005,1.232972e-005,,,,,,,,,,,,,,,,,,,,
1616828391.362,,1.000000e+003,2.500039e+001,2.500452e+001,1,0,3.179362e+000,4.371776e-001,,,,,,,1.077628e-005,,,,,,,,,,,,,,,,,,,,,
1616828391.362,,1.000000e+003,2.500142e+001,2.500142e+001,2,0,3.494335e+000,5.227820e-001,,,,,,,1.288640e-005,,,,,,,,,,,,,,,,,,,,,
1616828391.362,,1.000000e+003,2.499935e+001,2.499935e+001,3,0,3.181543e+000,4.152043e-001,,,,,,,1.023465e-005,,,,,,,,,,,,,,,,,,,,,
1616828391.362,,1.000000e+003,2.500039e+001,2.499935e+001,4,0,2.472598e+000,3.711051e-001,,,,,,,9.147617e-006,,,,,,,,,,,,,,,,,,,,,
1616828391.362,,1.000000e+003,2.500142e+001,2.499935e+001,5,0,1.674437e+000,3.747673e-001,3.888668e-001,-6.601663e-002,-6.077302e-002,3.947635e-001,-6.012000e-002,-5.487639e-002,9.237889e-006,9.585438e-006,,,,,,,,,,,,,,,,,,,,
1616828708.177,,1.000000e+003,3.000243e+001,3.000099e+001,1,0,1.007629e+000,3.711051e-001,,,,,,,9.147617e-006,,,,,,,,,,,,,,,,,,,,,
1616828708.177,,1.000000e+003,3.000243e+001,3.000099e+001,2,0,5.518638e-001,4.364147e-001,,,,,,,1.075748e-005,,,,,,,,,,,,,,,,,,,,,
1616828708.177,,1.000000e+003,3.000099e+001,2.999954e+001,3,0,6.496627e-001,4.315317e-001,,,,,,,1.063711e-005,,,,,,,,,,,,,,,,,,,,,
1616828708.177,,1.000000e+003,2.999954e+001,3.000099e+001,4,0,1.270931e+000,3.827021e-001,,,,,,,9.433479e-006,,,,,,,,,,,,,,,,,,,,,
1616828708.177,,1.000000e+003,3.000099e+001,2.999954e+001,5,0,2.066779e+000,2.771081e-001,2.531205e-001,-1.218980e-001,-1.218980e-001,2.711197e-001,-1.038988e-001,-1.038988e-001,6.830622e-006,6.239336e-006,,,,,,,,,,,,,,,,,,,,
1616828708.177,,1.000000e+003,3.000099e+001,2.999954e+001,5,0,2.789919e+000,3.613392e-001,3.366192e-001,-3.845191e-002,-3.839931e-002,3.245828e-001,-5.048826e-002,-5.043566e-002,8.906890e-006,8.297550e-006,,,,,,,,,,,,,,,,,,,,
1616829036.309,,1.000000e+003,3.500308e+001,3.500230e+001,1,0,3.337460e+000,3.094577e-001,,,,,,,7.628029e-006,,,,,,,,,,,,,,,,,,,,,
1616829036.309,,1.000000e+003,3.500154e+001,3.500000e+001,2,0,3.460712e+000,3.190710e-001,,,,,,,7.864995e-006,,,,,,,,,,,,,,,,,,,,,
1616829036.309,,1.000000e+003,3.500000e+001,3.500077e+001,3,0,2.969543e+000,2.604755e-001,,,,,,,6.420634e-006,,,,,,,,,,,,,,,,,,,,,
1616829036.309,,1.000000e+003,3.500077e+001,3.499923e+001,4,0,2.204042e+000,2.333140e-001,,,,,,,5.751112e-006,,,,,,,,,,,,,,,,,,,,,
1616829036.309,,1.000000e+003,3.500385e+001,3.500308e+001,5,0,1.432727e+000,2.600177e-001,2.784509e-001,-3.179744e-002,-3.675103e-002,2.832517e-001,-2.699659e-002,-3.195018e-002,6.409350e-006,6.863721e-006,,,,,,,,,,,,,,,,,,,,
1616829365.342,,1.000000e+003,4.000087e+001,3.999987e+001,1,0,8.218027e-001,3.260903e-001,,,,,,,8.038017e-006,,,,,,,,,,,,,,,,,,,,,
1616829365.342,,1.000000e+003,3.999987e+001,3.999987e+001,2,0,5.069075e-001,3.715629e-001,,,,,,,9.158901e-006,,,,,,,,,,,,,,,,,,,,,
1616829365.342,,1.000000e+003,3.999987e+001,3.999889e+001,3,0,8.197305e-001,3.530991e-001,,,,,,,8.703777e-006,,,,,,,,,,,,,,,,,,,,,
1616829365.342,,1.000000e+003,3.999889e+001,4.000283e+001,4,0,1.528700e+000,2.273629e-001,,,,,,,5.604420e-006,,,,,,,,,,,,,,,,,,,,,
1616829365.342,,1.000000e+003,3.999889e+001,4.000283e+001,4,0,2.326766e+000,1.988281e-001,,,,,,,4.901046e-006,,,,,,,,,,,,,,,,,,,,,
1616829365.342,,1.000000e+003,4.000283e+001,3.999889e+001,5,0,2.993745e+000,2.934355e-001,2.577288e-001,-2.958367e-002,-4.687259e-002,2.654903e-001,-2.182216e-002,-3.911108e-002,7.233087e-006,6.352930e-006,,,,,,,,,,,,,,,,,,,,
1616829663.997,,1.000000e+003,4.500107e+001,4.500107e+001,1,0,3.449402e+000,2.793970e-001,,,,,,,6.887042e-006,,,,,,,,,,,,,,,,,,,,,
1616829663.997,,1.000000e+003,4.500107e+001,4.500230e+001,2,0,3.351416e+000,2.265999e-001,,,,,,,5.585613e-006,,,,,,,,,,,,,,,,,,,,,
1616829663.997,,1.000000e+003,4.500230e+001,4.499862e+001,3,0,2.730175e+000,1.843318e-001,,,,,,,4.543717e-006,,,,,,,,,,,,,,,,,,,,,
1616829663.997,,1.000000e+003,4.499862e+001,4.499862e+001,4,0,1.934343e+000,1.561022e-001,,,,,,,3.847867e-006,,,,,,,,,,,,,,,,,,,,,
1616829663.997,,1.000000e+003,4.499862e+001,4.500107e+001,5,0,1.211153e+000,2.389599e-001,2.500076e-001,1.114530e-003,-8.650929e-003,2.506516e-001,1.758528e-003,-8.006930e-003,5.890283e-006,6.162605e-006,,,,,,,,,,,,,,,,,,,,
1616829946.460,,1.000000e+003,5.001661e+001,5.000766e+001,1,0,6.636494e-001,2.855006e-001,,,,,,,7.037496e-006,,,,,,,,,,,,,,,,,,,,,
1616829946.460,,1.000000e+003,5.000766e+001,5.000616e+001,2,0,5.405744e-001,2.960295e-001,,,,,,,7.297030e-006,,,,,,,,,,,,,,,,,,,,,
1616829946.460,,1.000000e+003,5.000616e+001,5.000318e+001,3,0,1.031849e+000,2.319407e-001,,,,,,,5.717260e-006,,,,,,,,,,,,,,,,,,,,,
1616829946.460,,1.000000e+003,5.000318e+001,5.000318e+001,4,0,1.797221e+000,1.382488e-001,,,,,,,3.407788e-006,,,,,,,,,,,,,,,,,,,,,
1616829946.460,,1.000000e+003,5.000318e+001,5.000318e+001,4,0,2.568596e+000,1.609851e-001,,,,,,,3.968230e-006,,,,,,,,,,,,,,,,,,,,,
1616829946.460,,1.000000e+003,5.000318e+001,5.000169e+001,5,0,3.179454e+000,2.031007e-001,1.911069e-001,-1.816095e-002,-4.120992e-002,2.110657e-001,1.797845e-003,-2.125113e-002,5.006364e-006,4.710721e-006,,,,,,,,,,,,,,,,,,,,
1616830223.095,,1.000000e+003,5.502434e+001,5.501899e+001,1,0,3.494365e+000,2.476577e-001,,,,,,,6.104680e-006,,,,,,,,,,,,,,,,,,,,,
1616830223.095,,1.000000e+003,5.501899e+001,5.501188e+001,2,0,3.181437e+000,2.226325e-001,,,,,,,5.487818e-006,,,,,,,,,,,,,,,,,,,,,
1616830223.095,,1.000000e+003,5.501188e+001,5.501009e+001,3,0,2.472465e+000,1.176489e-001,,,,,,,2.900005e-006,,,,,,,,,,,,,,,,,,,,,
1616830223.095,,1.000000e+003,5.501009e+001,5.500298e+001,4,0,1.674394e+000,1.098666e-001,,,,,,,2.708176e-006,,,,,,,,,,,,,,,,,,,,,
1616830223.095,,1.000000e+003,5.500298e+001,5.499764e+001,5,0,1.007478e+000,2.812281e-001,2.558061e-001,3.004175e-002,1.878810e-002,2.503464e-001,2.458196e-002,1.332831e-002,6.932178e-006,6.305536e-006,,,,,,,,,,,,,,,,,,,,
1616830501.549,,1.000000e+003,6.002769e+001,6.002140e+001,1,0,5.517870e-001,2.694784e-001,,,,,,,6.642554e-006,,,,,,,,,,,,,,,,,,,,,
1616830501.549,,1.000000e+003,6.002140e+001,6.001092e+001,2,0,6.498268e-001,2.726829e-001,,,,,,,6.721542e-006,,,,,,,,,,,,,,,,,,,,,
1616830501.549,,1.000000e+003,6.001092e+001,6.001301e+001,3,0,1.271235e+000,1.840266e-001,,,,,,,4.536195e-006,,,,,,,,,,,,,,,,,,,,,
1616830501.549,,1.000000e+003,6.001301e+001,6.000253e+001,4,0,2.067035e+000,1.162755e-001,,,,,,,2.866153e-006,,,,,,,,,,,,,,,,,,,,,
1616830501.549,,1.000000e+003,6.001301e+001,6.000253e+001,4,0,2.790118e+000,1.780755e-001,,,,,,,4.389502e-006,,,,,,,,,,,,,,,,,,,,,
1616830501.549,,1.000000e+003,6.000253e+001,6.000043e+001,5,0,3.337594e+000,1.434370e-001,1.816767e-001,-4.503722e-004,-2.539897e-002,2.017388e-001,1.961172e-002,-5.336881e-003,3.535674e-006,4.478270e-006,,,,,,,,,,,,,,,,,,,,
1616830782.696,,1.000000e+003,6.504213e+001,6.503482e+001,1,0,3.460723e+000,1.596118e-001,,,,,,,3.934378e-006,,,,,,,,,,,,,,,,,,,,,
1616830782.696,,1.000000e+003,6.503239e+001,6.502022e+001,2,0,2.969401e+000,9.674367e-002,,,,,,,2.384699e-006,,,,,,,,,,,,,,,,,,,,,
1616830782.696,,1.000000e+003,6.502022e+001,6.501535e+001,3,0,2.203935e+000,7.934812e-002,,,,,,,1.955905e-006,,,,,,,,,,,,,,,,,,,,,
1616830782.696,,1.000000e+003,6.501535e+001,6.500560e+001,4,0,1.432616e+000,1.132237e-001,,,,,,,2.790926e-006,,,,,,,,,,,,,,,,,,,,,
1616830782.696,,1.000000e+003,6.500560e+001,6.500317e+001,5,0,8.217963e-001,2.317881e-001,2.167425e-001,5.297377e-002,4.122601e-002,2.041274e-001,4.035874e-002,2.861099e-002,5.713499e-006,5.342629e-006,,,,,,,,,,,,,,,,,,,,
1616831066.237,,1.000000e+003,7.005171e+001,7.003214e+001,1,0,5.068553e-001,2.772607e-001,,,,,,,6.834383e-006,,,,,,,,,,,,,,,,,,,,,
1616831066.237,,1.000000e+003,7.003214e+001,7.002374e+001,2,0,8.197998e-001,2.526933e-001,,,,,,,6.228805e-006,,,,,,,,,,,,,,,,,,,,,
1616831066.237,,1.000000e+003,7.002374e+001,7.001814e+001,3,0,1.528839e+000,1.403851e-001,,,,,,,3.460447e-006,,,,,,,,,,,,,,,,,,,,,
1616831066.237,,1.000000e+003,7.002374e+001,7.001814e+001,3,0,2.326915e+000,9.765923e-002,,,,,,,2.407268e-006,,,,,,,,,,,,,,,,,,,,,
1616831066.237,,1.000000e+003,7.002095e+001,7.001814e+001,4,0,2.993840e+000,1.365703e-001,,,,,,,3.366413e-006,,,,,,,,,,,,,,,,,,,,,
1616831066.237,,1.000000e+003,7.001814e+001,7.000977e+001,5,0,3.449446e+000,1.733451e-001,1.925413e-001,1.796020e-002,-1.008476e-002,2.057994e-001,3.121836e-002,3.173396e-003,4.272900e-006,4.746079e-006,,,,,,,,,,,,,,,,,,,,
1616831353.760,,1.000000e+003,7.506044e+001,7.504135e+001,1,0,3.351416e+000,2.238533e-001,,,,,,,5.517908e-006,,,,,,,,,,,,,,,,,,,,,
1616831353.760,,1.000000e+003,7.504135e+001,7.503180e+001,2,0,2.729973e+000,1.042207e-001,,,,,,,2.569006e-006,,,,,,,,,,,,,,,,,,,,,
1616831353.760,,1.000000e+003,7.503180e+001,7.501590e+001,3,0,1.934251e+000,7.873775e-002,,,,,,,1.940859e-006,,,,,,,,,,,,,,,,,,,,,
1616831353.760,,1.000000e+003,7.501590e+001,7.501907e+001,4,0,1.211108e+000,1.879940e-001,,,,,,,4.633990e-006,,,,,,,,,,,,,,,,,,,,,
1616831353.760,,1.000000e+003,7.501907e+001,7.500636e+001,5,0,6.636579e-001,2.830592e-001,2.692953e-001,6.838068e-002,5.681685e-002,2.482632e-001,4.734853e-002,3.578469e-002,6.977315e-006,6.638040e-006,,,,,,,,,,,,,,,,,,,,
1616831659.485,,1.000000e+003,8.004660e+001,8.002866e+001,1,0,5.404669e-001,2.511673e-001,,,,,,,6.191191e-006,,,,,,,,,,,,,,,,,,,,,
1616831659.485,,1.000000e+003,8.002866e+001,8.001791e+001,2,0,1.031832e+000,2.426222e-001,,,,,,,5.980555e-006,,,,,,,,,,,,,,,,,,,,,
1616831659.485,,1.000000e+003,8.001791e+001,8.001433e+001,3,0,1.797335e+000,1.039155e-001,,,,,,,2.561483e-006,,,,,,,,,,,,,,,,,,,,,
1616831659.485,,1.000000e+003,8.001791e+001,8.001433e+001,3,0,2.568670e+000,1.219214e-001,,,,,,,3.005323e-006,,,,,,,,,,,,,,,,,,,,,
1616831659.485,,1.000000e+003,8.001433e+001,8.001433e+001,4,0,3.179549e+000,1.197852e-001,,,,,,,2.952664e-006,,,,,,,,,,,,,,,,,,,,,
1616831659.485,,1.000000e+003,8.001433e+001,8.001433e+001,5,0,3.494371e+000,1.832636e-001,1.923582e-001,2.293915e-002,-3.877729e-003,2.038387e-001,3.441972e-002,7.602841e-003,4.517388e-006,4.741565e-006,,,,,,,,,,,,,,,,,,,,
1616831945.432,,1.000000e+003,8.508050e+001,8.506043e+001,1,0,3.181258e+000,1.524400e-001,,,,,,,3.757594e-006,,,,,,,,,,,,,,,,,,,,,
1616831945.432,,1.000000e+003,8.506043e+001,8.503637e+001,2,0,2.472244e+000,6.179998e-002,,,,,,,1.523349e-006,,,,,,,,,,,,,,,,,,,,,
1616831945.432,,1.000000e+003,8.503637e+001,8.502835e+001,3,0,1.674216e+000,1.179540e-001,,,,,,,2.907528e-006,,,,,,,,,,,,,,,,,,,,,
1616831945.432,,1.000000e+003,8.502835e+001,8.502034e+001,4,0,1.007321e+000,1.861629e-001,,,,,,,4.588854e-006,,,,,,,,,,,,,,,,,,,,,
1616831945.432,,1.000000e+003,8.502034e+001,8.500832e+001,5,0,5.517771e-001,2.362133e-001,2.480239e-001,7.683092e-002,6.671576e-002,2.197658e-001,4.857278e-002,3.845762e-002,5.822578e-006,6.113707e-006,,,,,,,,,,,,,,,,,,,,
1616832229.993,,1.000000e+003,9.008069e+001,9.005843e+001,1,0,6.499254e-001,2.270577e-001,,,,,,,5.596897e-006,,,,,,,,,,,,,,,,,,,,,
1616832229.993,,1.000000e+003,9.005843e+001,9.004060e+001,2,0,1.271312e+000,1.644948e-001,,,,,,,4.054741e-006,,,,,,,,,,,,,,,,,,,,,
1616832229.993,,1.000000e+003,9.004951e+001,9.003171e+001,3,0,2.067059e+000,6.836146e-002,,,,,,,1.685087e-006,,,,,,,,,,,,,,,,,,,,,
1616832229.993,,1.000000e+003,9.004951e+001,9.003171e+001,3,0,2.790139e+000,1.236000e-001,,,,,,,3.046698e-006,,,,,,,,,,,,,,,,,,,,,
1616832229.993,,1.000000e+003,9.003171e+001,9.001834e+001,4,0,3.337643e+000,1.428266e-001,,,,,,,3.520629e-006,,,,,,,,,,,,,,,,,,,,,
1616832229.993,,1.000000e+003,9.001834e+001,9.000944e+001,5,0,3.460717e+000,1.831111e-001,1.726127e-001,1.440089e-002,-1.281124e-002,1.897017e-001,3.148989e-002,4.277751e-003,4.513627e-006,4.254845e-006,,,,,,,,,,,,,,,,,,,,
1616832515.985,,1.000000e+003,9.509148e+001,9.506687e+001,1,0,2.969396e+000,9.933775e-002,,,,,,,2.448642e-006,,,,,,,,,,,,,,,,,,,,,
1616832515.985,,1.000000e+003,9.506687e+001,9.504229e+001,2,0,2.203981e+000,4.684591e-002,,,,,,,1.154736e-006,,,,,,,,,,,,,,,,,,,,,
1616832515.985,,1.000000e+003,9.504229e+001,9.503737e+001,3,0,1.432608e+000,1.423689e-001,,,,,,,3.509345e-006,,,,,,,,,,,,,,,,,,,,,
1616832515.985,,1.000000e+003,9.502263e+001,9.502263e+001,4,0,8.218932e-001,2.513199e-001,,,,,,,6.194953e-006,,,,,,,,,,,,,,,,,,,,,
1616832515.985,,1.000000e+003,9.502263e+001,9.501281e+001,5,0,5.068443e-001,2.650532e-001,2.562334e-001,7.926621e-002,6.914231e-002,2.252080e-001,4.824085e-002,3.811695e-002,6.533474e-006,6.316068e-006,,,,,,,,,,,,,,,,,,,,
1616832799.015,,1.000000e+003,1.001066e+002,1.000741e+002,1,0,8.197842e-001,2.978607e-001,,,,,,,7.342166e-006,,,,,,,,,,,,,,,,,,,,,
1616832799.015,,1.000000e+003,1.000741e+002,1.000498e+002,2,0,1.528891e+000,1.176489e-001,,,,,,,2.900005e-006,,,,,,,,,,,,,,,,,,,,,
1616832799.015,,1.000000e+003,1.000741e+002,1.000498e+002,2,0,2.326976e+000,7.080294e-002,,,,,,,1.745269e-006,,,,,,,,,,,,,,,,,,,,,
1616832799.015,,1.000000e+003,1.000498e+002,1.000309e+002,3,0,2.993808e+000,1.036103e-001,,,,,,,2.553960e-006,,,,,,,,,,,,,,,,,,,,,
1616832799.015,,1.000000e+003,1.000336e+002,1.000336e+002,4,0,3.449433e+000,1.669362e-001,,,,,,,4.114923e-006,,,,,,,,,,,,,,,,,,,,,
1616832799.015,,1.000000e+003,1.000336e+002,1.000147e+002,5,0,3.351429e+000,2.214118e-001,1.745964e-001,-8.579841e-003,-3.390589e-002,2.035678e-001,2.039158e-002,-4.934475e-003,5.457727e-006,4.303743e-006,,,,,,,,,,,,,,,,,,,,
1616833076.087,,1.000000e+003,1.051085e+002,1.050848e+002,1,0,2.729818e+000,1.251259e-001,,,,,,,3.084311e-006,,,,,,,,,,,,,,,,,,,,,
1616833076.087,,1.000000e+003,1.050848e+002,1.050670e+002,2,0,1.933939e+000,4.150517e-002,,,,,,,1.023089e-006,,,,,,,,,,,,,,,,,,,,,
1616833076.087,,1.000000e+003,1.050670e+002,1.050433e+002,3,0,1.210900e+000,1.796014e-001,,,,,,,4.427116e-006,,,,,,,,,,,,,,,,,,,,,
1616833076.087,,1.000000e+003,1.050433e+002,1.050433e+002,4,0,6.635226e-001,2.053896e-001,,,,,,,5.062785e-006,,,,,,,,,,,,,,,,,,,,,
1616833076.087,,1.000000e+003,1.050433e+002,1.050197e+002,5,0,5.405527e-001,2.420118e-001,2.400586e-001,6.291761e-002,5.986406e-002,2.281340e-001,5.099301e-002,4.793946e-002,5.965510e-006,5.917364e-006,,,,,,,,,,,,,,,,,,,,
1616833353.273,,1.000000e+003,1.101249e+002,1.100958e+002,1,0,1.031994e+000,1.814325e-001,,,,,,,4.472251e-006,,,,,,,,,,,,,,,,,,,,,
1616833353.273,,1.000000e+003,1.100958e+002,1.100796e+002,2,0,1.796876e+000,1.071200e-001,,,,,,,2.640472e-006,,,,,,,,,,,,,,,,,,,,,
1616833353.273,,1.000000e+003,1.100958e+002,1.100796e+002,2,0,2.568327e+000,1.385540e-001,,,,,,,3.415311e-006,,,,,,,,,,,,,,,,,,,,,
1616833353.273,,1.000000e+003,1.100667e+002,1.100473e+002,3,0,3.179232e+000,1.947081e-001,,,,,,,4.799489e-006,,,,,,,,,,,,,,,,,,,,,
1616833353.273,,1.000000e+003,1.100473e+002,1.100408e+002,4,0,3.494381e+000,2.664266e-001,,,,,,,6.567327e-006,,,,,,,,,,,,,,,,,,,,,
1616833353.273,,1.000000e+003,1.100408e+002,1.100117e+002,5,0,3.181634e+000,2.095096e-001,2.040773e-001,7.233508e-003,1.730293e-003,2.145479e-001,1.770412e-002,1.220091e-002,5.164341e-006,5.030437e-006,,,,,,,,,,,,,,,,,,,,
1616833628.950,,1.000000e+003,1.151295e+002,1.151014e+002,1,0,2.472485e+000,8.941923e-002,,,,,,,2.204154e-006,,,,,,,,,,,,,,,,,,,,,
1616833628.950,,1.000000e+003,1.150944e+002,1.150873e+002,2,0,1.674476e+000,1.264992e-001,,,,,,,3.118164e-006,,,,,,,,,,,,,,,,,,,,,
1616833628.950,,1.000000e+003,1.150873e+002,1.150662e+002,3,0,1.007542e+000,2.125614e-001,,,,,,,5.239568e-006,,,,,,,,,,,,,,,,,,,,,
1616833628.950,,1.000000e+003,1.150662e+002,1.150417e+002,4,0,5.518777e-001,2.731407e-001,,,,,,,6.732826e-006,,,,,,,,,,,,,,,,,,,,,
1616833628.950,,1.000000e+003,1.150417e+002,1.150030e+002,5,0,6.497204e-001,2.691732e-001,2.557756e-001,5.138263e-002,5.008687e-002,2.518137e-001,4.742068e-002,4.612492e-002,6.635031e-006,6.304784e-006,,,,,,,,,,,,,,,,,,,,
1616833924.694,,1.000000e+003,1.201342e+002,1.200848e+002,1,0,1.271106e+000,1.513718e-001,,,,,,,3.731265e-006,,,,,,,,,,,,,,,,,,,,,
1616833924.694,,1.000000e+003,1.200848e+002,1.200582e+002,2,0,2.066914e+000,8.285776e-002,,,,,,,2.042416e-006,,,,,,,,,,,,,,,,,,,,,
1616833924.694,,1.000000e+003,1.200848e+002,1.200582e+002,2,0,2.790009e+000,1.695303e-001,,,,,,,4.178866e-006,,,,,,,,,,,,,,,,,,,,,
1616833924.694,,1.000000e+003,1.200582e+002,1.200354e+002,3,0,3.337479e+000,2.429273e-001,,,,,,,5.988078e-006,,,,,,,,,,,,,,,,,,,,,
1616833924.694,,1.000000e+003,1.200164e+002,1.200126e+002,4,0,3.460784e+000,2.473525e-001,,,,,,,6.097157e-006,,,,,,,,,,,,,,,,,,,,,
1616833924.694,,1.000000e+003,1.200126e+002,1.200240e+002,5,0,2.969555e+000,1.426740e-001,1.740165e-001,-1.865413e-002,-2.356683e-002,1.818513e-001,-1.081934e-002,-1.573204e-002,3.516867e-006,4.289450e-006,,,,,,,,,,,,,,,,,,,,
1616834201.375,,1.000000e+003,1.251502e+002,1.251174e+002,1,0,2.204373e+000,8.957183e-002,,,,,,,2.207916e-006,,,,,,,,,,,,,,,,,,,,,
1616834201.375,,1.000000e+003,1.251174e+002,1.250600e+002,2,0,1.432945e+000,1.112400e-001,,,,,,,2.742028e-006,,,,,,,,,,,,,,,,,,,,,
1616834201.375,,1.000000e+003,1.250600e+002,1.250436e+002,3,0,8.221186e-001,2.484207e-001,,,,,,,6.123487e-006,,,,,,,,,,,,,,,,,,,,,
1616834201.375,,1.000000e+003,1.250436e+002,1.250436e+002,4,0,5.068853e-001,2.095096e-001,,,,,,,5.164341e-006,,,,,,,,,,,,,,,,,,,,,
1616834201.375,,1.000000e+003,1.250436e+002,1.250149e+002,5,0,8.194456e-001,2.204962e-001,2.171697e-001,3.446949e-002,3.329368e-002,2.173761e-001,3.467584e-002,3.350003e-002,5.435159e-006,5.353161e-006,,,,,,,,,,,,,,,,,,,,
1616834479.075,,1.000000e+003,1.301352e+002,1.300955e+002,1,0,1.528194e+000,1.521348e-001,,,,,,,3.750072e-006,,,,,,,,,,,,,,,,,,,,,
1616834479.075,,1.000000e+003,1.301352e+002,1.300955e+002,1,0,2.326316e+000,1.167333e-001,,,,,,,2.877437e-006,,,,,,,,,,,,,,,,,,,,,
1616834479.075,,1.000000e+003,1.300955e+002,1.300558e+002,2,0,2.993166e+000,1.818903e-001,,,,,,,4.483536e-006,,,,,,,,,,,,,,,,,,,,,
1616834479.075,,1.000000e+003,1.300558e+002,1.300338e+002,3,0,3.449143e+000,2.659688e-001,,,,,,,6.556043e-006,,,,,,,,,,,,,,,,,,,,,
1616834479.075,,1.000000e+003,1.300338e+002,1.300338e+002,4,0,3.351912e+000,2.575762e-001,,,,,,,6.349168e-006,,,,,,,,,,,,,,,,,,,,,
1616834479.075,,1.000000e+003,1.300426e+002,1.300382e+002,5,0,2.730732e+000,1.852474e-001,1.702017e-001,-4.945045e-002,-5.357452e-002,1.719951e-001,-4.765704e-002,-5.178110e-002,4.566285e-006,4.195416e-006,,,,,,,,,,,,,,,,,,,,
1616834759.581,,1.000000e+003,1.351440e+002,1.350920e+002,1,0,1.935156e+000,1.022370e-001,,,,,,,2.520108e-006,,,,,,,,,,,,,,,,,,,,,
1616834759.581,,1.000000e+003,1.350920e+002,1.350683e+002,2,0,1.211945e+000,1.853999e-001,,,,,,,4.570047e-006,,,,,,,,,,,,,,,,,,,,,
1616834759.581,,1.000000e+003,1.350683e+002,1.350399e+002,3,0,6.643423e-001,2.513199e-001,,,,,,,6.194953e-006,,,,,,,,,,,,,,,,,,,,,
1616834759.581,,1.000000e+003,1.350399e+002,1.350258e+002,4,0,5.403082e-001,2.999969e-001,,,,,,,7.394825e-006,,,,,,,,,,,,,,,,,,,,,
1616834759.581,,1.000000e+003,1.350258e+002,1.350305e+002,5,0,1.031147e+000,2.088992e-001,2.188482e-001,7.079139e-003,6.394297e-003,2.225641e-001,1.079504e-002,1.011020e-002,5.149296e-006,5.394536e-006,,,,,,,,,,,,,,,,,,,,
1616835044.294,,1.000000e+003,1.401514e+002,1.401008e+002,1,0,1.796785e+000,1.345866e-001,,,,,,,3.317516e-006,,,,,,,,,,,,,,,,,,,,,
1616835044.294,,1.000000e+003,1.401514e+002,1.401008e+002,1,0,2.568236e+000,1.722770e-001,,,,,,,4.246570e-006,,,,,,,,,,,,,,,,,,,,,
1616835044.294,,1.000000e+003,1.401008e+002,1.400603e+002,2,0,3.179050e+000,1.986755e-001,,,,,,,4.897285e-006,,,,,,,,,,,,,,,,,,,,,
1616835044.294,,1.000000e+003,1.400553e+002,1.400452e+002,3,0,3.494320e+000,2.577288e-001,,,,,,,6.352930e-006,,,,,,,,,,,,,,,,,,,,,
1616835044.294,,1.000000e+003,1.400452e+002,1.400199e+002,4,0,3.181799e+000,1.979125e-001,,,,,,,4.878478e-006,,,,,,,,,,,,,,,,,,,,,
1616835044.294,,1.000000e+003,1.400199e+002,1.400148e+002,5,0,2.472883e+000,9.369183e-002,1.168859e-001,-8.697062e-002,-9.070873e-002,1.148034e-001,-8.905315e-002,-9.279125e-002,2.309472e-006,2.881198e-006,,,,,,,,,,,,,,,,,,,,
1616835330.965,,1.000000e+003,1.451495e+002,1.450847e+002,1,0,1.674639e+000,1.734977e-001,,,,,,,4.276661e-006,,,,,,,,,,,,,,,,,,,,,
1616835330.965,,1.000000e+003,1.450847e+002,1.450685e+002,2,0,1.007835e+000,2.076785e-001,,,,,,,5.119205e-006,,,,,,,,,,,,,,,,,,,,,
1616835330.965,,1.000000e+003,1.450469e+002,1.450469e+002,3,0,5.519493e-001,3.028962e-001,,,,,,,7.466291e-006,,,,,,,,,,,,,,,,,,,,,
1616835330.965,,1.000000e+003,1.450469e+002,1.450253e+002,4,0,6.496285e-001,2.764977e-001,,,,,,,6.815576e-006,,,,,,,,,,,,,,,,,,,,,
1616835330.965,,1.000000e+003,1.450253e+002,1.450199e+002,5,0,1.270904e+000,1.808222e-001,1.973632e-001,-2.870203e-002,-2.931386e-002,2.032934e-001,-2.277180e-002,-2.338363e-002,4.457206e-006,4.864937e-006,,,,,,,,,,,,,,,,,,,,
1616835618.222,,1.000000e+003,1.501454e+002,1.500993e+002,1,0,2.066818e+000,1.225318e-001,,,,,,,3.020368e-006,,,,,,,,,,,,,,,,,,,,,
1616835618.222,,1.000000e+003,1.501454e+002,1.500993e+002,1,0,2.789954e+000,2.098148e-001,,,,,,,5.171864e-006,,,,,,,,,,,,,,,,,,,,,
1616835618.222,,1.000000e+003,1.500993e+002,1.500648e+002,2,0,3.337402e+000,2.882473e-001,,,,,,,7.105200e-006,,,,,,,,,,,,,,,,,,,,,
1616835618.222,,1.000000e+003,1.500648e+002,1.500475e+002,3,0,3.460786e+000,3.035066e-001,,,,,,,7.481336e-006,,,,,,,,,,,,,,,,,,,,,
1616835618.222,,1.000000e+003,1.500475e+002,1.500245e+002,4,0,2.969695e+000,2.276681e-001,,,,,,,5.611942e-006,,,,,,,,,,,,,,,,,,,,,
1616835618.222,,1.000000e+003,1.500245e+002,1.500072e+002,5,0,2.204313e+000,1.580859e-001,1.419111e-001,-1.170792e-001,-1.199549e-001,1.394618e-001,-1.195285e-001,-1.224042e-001,3.896764e-006,3.498061e-006,,,,,,,,,,,,,,,,,,,,
1616835905.690,,1.000000e+003,1.551516e+002,1.550964e+002,1,0,1.432794e+000,1.989807e-001,,,,,,,4.904808e-006,,,,,,,,,,,,,,,,,,,,,
1616835905.690,,1.000000e+003,1.550964e+002,1.550535e+002,2,0,8.221179e-001,2.447584e-001,,,,,,,6.033214e-006,,,,,,,,,,,,,,,,,,,,,
1616835905.690,,1.000000e+003,1.550535e+002,1.550290e+002,3,0,5.068774e-001,3.373821e-001,,,,,,,8.316357e-006,,,,,,,,,,,,,,,,,,,,,
1616835905.690,,1.000000e+003,1.550290e+002,1.550290e+002,4,0,8.195339e-001,2.557451e-001,,,,,,,6.304032e-006,,,,,,,,,,,,,,,,,,,,,
1616835905.690,,1.000000e+003,1.550106e+002,1.550229e+002,5,0,1.528573e+000,1.483200e-001,1.657766e-001,-6.881650e-002,-6.909098e-002,1.705721e-001,-6.402092e-002,-6.429540e-002,3.656038e-006,4.086337e-006,,,,,,,,,,,,,,,,,,,,
1616835905.690,,1.000000e+003,1.550106e+002,1.550229e+002,5,0,2.326656e+000,1.161229e-001,1.313211e-001,-9.929189e-002,-1.035464e-001,1.208835e-001,-1.097295e-001,-1.139840e-001,2.862392e-006,3.237023e-006,,,,,,,,,,,,,,,,,,,,
1616836196.380,,1.000000e+003,1.601512e+002,1.600991e+002,1,0,2.993598e+000,2.540666e-001,,,,,,,6.262657e-006,,,,,,,,,,,,,,,,,,,,,
1616836196.380,,1.000000e+003,1.600991e+002,1.600601e+002,2,0,3.449350e+000,2.751244e-001,,,,,,,6.781724e-006,,,,,,,,,,,,,,,,,,,,,
1616836196.380,,1.000000e+003,1.600601e+002,1.600340e+002,3,0,3.351566e+000,3.137303e-001,,,,,,,7.733347e-006,,,,,,,,,,,,,,,,,,,,,
1616836196.380,,1.000000e+003,1.600340e+002,1.600276e+002,4,0,2.730183e+000,1.692251e-001,,,,,,,4.171343e-006,,,,,,,,,,,,,,,,,,,,,
1616836196.380,,1.000000e+003,1.600276e+002,1.600210e+002,5,0,1.934428e+000,8.636738e-002,1.285134e-001,-1.147532e-001,-1.159484e-001,1.257393e-001,-1.175274e-001,-1.187226e-001,2.128927e-006,3.167813e-006,,,,,,,,,,,,,,,,,,,,
1616836486.163,,1.000000e+003,1.651598e+002,1.650977e+002,1,0,1.211207e+000,2.314829e-001,,,,,,,5.705976e-006,,,,,,,,,,,,,,,,,,,,,
1616836486.163,,1.000000e+003,1.650977e+002,1.650631e+002,2,0,6.637848e-001,2.450636e-001,,,,,,,6.040737e-006,,,,,,,,,,,,,,,,,,,,,
1616836486.163,,1.000000e+003,1.650631e+002,1.650355e+002,3,0,5.404134e-001,3.080843e-001,,,,,,,7.594177e-006,,,,,,,,,,,,,,,,,,,,,
1616836486.163,,1.000000e+003,1.650355e+002,1.650148e+002,4,0,1.031629e+000,2.233955e-001,,,,,,,5.506624e-006,,,,,,,,,,,,,,,,,,,,,
1616836486.163,,1.000000e+003,1.650148e+002,1.650079e+002,5,0,1.797059e+000,1.451155e-001,1.224097e-001,-1.083475e-001,-1.084616e-001,1.271030e-001,-1.036542e-001,-1.037684e-001,3.577049e-006,3.017359e-006,,,,,,,,,,,,,,,,,,,,
1616836486.163,,1.000000e+003,1.650148e+002,1.650079e+002,5,0,2.568469e+000,1.829585e-001,1.570177e-001,-7.042954e-002,-7.385361e-002,1.509235e-001,-7.652380e-002,-7.994787e-002,4.509865e-006,3.870435e-006,,,,,,,,,,,,,,,,,,,,
1616836777.824,,1.000000e+003,1.701540e+002,1.701027e+002,1,0,3.179256e+000,2.050844e-001,,,,,,,5.055262e-006,,,,,,,,,,,,,,,,,,,,,
1616836777.824,,1.000000e+003,1.701027e+002,1.700661e+002,2,0,3.494400e+000,2.569658e-001,,,,,,,6.334123e-006,,,,,,,,,,,,,,,,,,,,,
1616836777.824,,1.000000e+003,1.700661e+002,1.700369e+002,3,0,3.181654e+000,2.539140e-001,,,,,,,6.258896e-006,,,,,,,,,,,,,,,,,,,,,
1616836777.824,,1.000000e+003,1.700369e+002,1.700150e+002,4,0,2.472800e+000,1.501511e-001,,,,,,,3.701174e-006,,,,,,,,,,,,,,,,,,,,,
1616836777.824,,1.000000e+003,1.700150e+002,1.700076e+002,5,0,1.674600e+000,1.336711e-001,1.375774e-001,-8.542790e-002,-8.700335e-002,1.367265e-001,-8.627885e-002,-8.785430e-002,3.294947e-006,3.391238e-006,,,,,,,,,,,,,,,,,,,,
1616837070.978,,1.000000e+003,1.751542e+002,1.750845e+002,1,0,1.007672e+000,2.494888e-001,,,,,,,6.149816e-006,,,,,,,,,,,,,,,,,,,,,
1616837070.978,,1.000000e+003,1.750845e+002,1.750535e+002,2,0,5.519372e-001,3.503525e-001,,,,,,,8.636072e-006,,,,,,,,,,,,,,,,,,,,,
1616837070.978,,1.000000e+003,1.750535e+002,1.750381e+002,3,0,6.496525e-001,3.343303e-001,,,,,,,8.241130e-006,,,,,,,,,,,,,,,,,,,,,
1616837070.978,,1.000000e+003,1.750381e+002,1.750149e+002,4,0,1.271001e+000,2.479629e-001,,,,,,,6.112203e-006,,,,,,,,,,,,,,,,,,,,,
1616837070.978,,1.000000e+003,1.750149e+002,1.750072e+002,5,0,2.066792e+000,1.774651e-001,1.469161e-001,-1.309756e-001,-1.309756e-001,1.537692e-001,-1.241225e-001,-1.241225e-001,4.374456e-006,3.621433e-006,,,,,,,,,,,,,,,,,,,,
1616837070.978,,1.000000e+003,1.750149e+002,1.750072e+002,5,0,2.789949e+000,2.720725e-001,2.387158e-001,-3.866392e-002,-3.917591e-002,2.356698e-001,-4.170994e-002,-4.222193e-002,6.706497e-006,5.884265e-006,,,,,,,,,,,,,,,,,,,,
1616837362.262,,1.000000e+003,1.801440e+002,1.800949e+002,1,0,3.337419e+000,3.117466e-001,,,,,,,7.684449e-006,,,,,,,,,,,,,,,,,,,,,
1616837362.262,,1.000000e+003,1.800949e+002,1.800623e+002,2,0,3.460878e+000,2.972503e-001,,,,,,,7.327120e-006,,,,,,,,,,,,,,,,,,,,,
1616837362.262,,1.000000e+003,1.800541e+002,1.800215e+002,3,0,2.969672e+000,2.673422e-001,,,,,,,6.589895e-006,,,,,,,,,,,,,,,,,,,,,
1616837362.262,,1.000000e+003,1.800215e+002,1.800133e+002,4,0,2.204195e+000,9.872738e-002,,,,,,,2.433597e-006,,,,,,,,,,,,,,,,,,,,,
1616837362.262,,1.000000e+003,1.800133e+002,1.800215e+002,5,0,1.432819e+000,2.128666e-001,2.133549e-001,-4.765435e-002,-4.795249e-002,2.138388e-001,-4.717042e-002,-4.746856e-002,5.247091e-006,5.259127e-006,,,,,,,,,,,,,,,,,,,,
1616837654.794,,1.000000e+003,1.851500e+002,1.850982e+002,1,0,8.220404e-001,3.154088e-001,,,,,,,7.774722e-006,,,,,,,,,,,,,,,,,,,,,
1616837654.794,,1.000000e+003,1.850982e+002,1.850466e+002,2,0,5.068365e-001,3.634754e-001,,,,,,,8.959549e-006,,,,,,,,,,,,,,,,,,,,,
1616837654.794,,1.000000e+003,1.850551e+002,1.850293e+002,3,0,8.195235e-001,2.468947e-001,,,,,,,6.085873e-006,,,,,,,,,,,,,,,,,,,,,
1616837654.794,,1.000000e+003,1.850293e+002,1.850207e+002,4,0,1.528508e+000,2.116459e-001,,,,,,,5.217000e-006,,,,,,,,,,,,,,,,,,,,,
1616837654.794,,1.000000e+003,1.850293e+002,1.850207e+002,4,0,2.326634e+000,1.828059e-001,,,,,,,4.506104e-006,,,,,,,,,,,,,,,,,,,,,
1616837654.794,,1.000000e+003,1.850207e+002,1.850035e+002,5,0,2.993534e+000,2.116459e-001,2.440260e-001,-1.361406e-002,-1.317814e-002,2.465888e-001,-1.105122e-002,-1.061530e-002,5.217000e-006,6.015160e-006,,,,,,,,,,,,,,,,,,,,
1616837947.118,,1.000000e+003,1.901497e+002,1.900953e+002,1,0,3.449379e+000,3.375347e-001,,,,,,,8.320118e-006,,,,,,,,,,,,,,,,,,,,,
1616837947.118,,1.000000e+003,1.900953e+002,1.900590e+002,2,0,3.351649e+000,2.481155e-001,,,,,,,6.115964e-006,,,,,,,,,,,,,,,,,,,,,
1616837947.118,,1.000000e+003,1.900590e+002,1.900227e+002,3,0,2.730236e+000,2.720725e-001,,,,,,,6.706497e-006,,,,,,,,,,,,,,,,,,,,,
1616837947.118,,1.000000e+003,1.900227e+002,1.900046e+002,4,0,1.934511e+000,1.942503e-001,,,,,,,4.788205e-006,,,,,,,,,,,,,,,,,,,,,
1616837947.118,,1.000000e+003,1.900046e+002,1.900136e+002,5,0,1.211324e+000,2.633747e-001,2.733238e-001,-1.262780e-002,-1.211989e-002,2.740650e-001,-1.188656e-002,-1.137865e-002,6.492100e-006,6.737340e-006,,,,,,,,,,,,,,,,,,,,
1616838275.649,,1.000000e+003,1.950548e+002,1.950166e+002,1,0,6.638156e-001,2.903836e-001,,,,,,,7.157860e-006,,,,,,,,,,,,,,,,,,,,,
1616838275.649,,1.000000e+003,1.950166e+002,1.950070e+002,2,0,5.403545e-001,3.440962e-001,,,,,,,8.481857e-006,,,,,,,,,,,,,,,,,,,,,
1616838275.649,,1.000000e+003,1.950070e+002,1.950070e+002,3,0,1.031598e+000,2.890103e-001,,,,,,,7.124007e-006,,,,,,,,,,,,,,,,,,,,,
1616838275.649,,1.000000e+003,1.950070e+002,1.950070e+002,4,0,1.796980e+000,1.641896e-001,,,,,,,4.047219e-006,,,,,,,,,,,,,,,,,,,,,
1616838275.649,,1.000000e+003,1.950070e+002,1.950070e+002,4,0,2.568434e+000,2.020325e-001,,,,,,,4.980035e-006,,,,,,,,,,,,,,,,,,,,,
1616838275.649,,1.000000e+003,1.950070e+002,1.950070e+002,5,0,3.179243e+000,2.504044e-001,2.694784e-001,8.289055e-003,8.269846e-003,2.764013e-001,1.521196e-002,1.519275e-002,6.172384e-006,6.642554e-006,,,,,,,,,,,,,,,,,,,,
1616838605.257,,1.000000e+003,2.000507e+002,2.000207e+002,1,0,3.494447e+000,2.665792e-001,,,,,,,6.571088e-006,,,,,,,,,,,,,,,,,,,,,
1616838605.257,,1.000000e+003,2.000207e+002,2.000106e+002,2,0,3.181752e+000,3.270058e-001,,,,,,,8.060585e-006,,,,,,,,,,,,,,,,,,,,,
1616838605.257,,1.000000e+003,2.000106e+002,2.000106e+002,3,0,2.472723e+000,1.989807e-001,,,,,,,4.904808e-006,,,,,,,,,,,,,,,,,,,,,
1616838605.257,,1.000000e+003,2.000006e+002,2.000006e+002,4,0,1.674669e+000,1.919614e-001,,,,,,,4.731785e-006,,,,,,,,,,,,,,,,,,,,,
1616838605.257,,1.000000e+003,2.000106e+002,2.000106e+002,5,0,1.007711e+000,2.855006e-001,2.949919e-001,1.790038e-002,1.952279e-002,2.943713e-001,1.727981e-002,1.890221e-002,7.037496e-006,7.271452e-006,,,,,,,,,,,,,,,,,,,,
1616838933.772,,1.000000e+003,2.051640e+002,2.050904e+002,1,0,5.520275e-001,3.759880e-001,,,,,,,9.267980e-006,,,,,,,,,,,,,,,,,,,,,
1616838933.772,,1.000000e+003,2.050904e+002,2.050484e+002,2,0,6.494417e-001,3.556933e-001,,,,,,,8.767720e-006,,,,,,,,,,,,,,,,,,,,,
1616838933.772,,1.000000e+003,2.050063e+002,2.050063e+002,3,0,1.270769e+000,2.696310e-001,,,,,,,6.646315e-006,,,,,,,,,,,,,,,,,,,,,
1616838933.772,,1.000000e+003,2.050063e+002,2.050063e+002,4,0,2.066509e+000,1.652577e-001,,,,,,,4.073548e-006,,,,,,,,,,,,,,,,,,,,,
1616838933.772,,1.000000e+003,2.050063e+002,2.050063e+002,4,0,2.789685e+000,2.632221e-001,,,,,,,6.488338e-006,,,,,,,,,,,,,,,,,,,,,
1616838933.772,,1.000000e+003,2.050063e+002,2.049958e+002,5,0,3.337221e+000,3.218177e-001,3.299661e-001,2.799224e-002,3.045160e-002,3.355780e-001,3.360414e-002,3.606349e-002,7.932699e-006,8.133556e-006,,,,,,,,,,,,,,,,,,,,
1616839249.148,,1.000000e+003,2.101643e+002,2.100981e+002,1,0,3.461011e+000,2.819910e-001,,,,,,,6.950985e-006,,,,,,,,,,,,,,,,,,,,,
1616839249.148,,1.000000e+003,2.100981e+002,2.100540e+002,2,0,2.969797e+000,3.042696e-001,,,,,,,7.500143e-006,,,,,,,,,,,,,,,,,,,,,
1616839249.148,,1.000000e+003,2.100209e+002,2.100099e+002,3,0,2.204383e+000,1.609851e-001,,,,,,,3.968230e-006,,,,,,,,,,,,,,,,,,,,,
1616839249.148,,1.000000e+003,2.100099e+002,2.100099e+002,4,0,1.432909e+000,2.328562e-001,,,,,,,5.739828e-006,,,,,,,,,,,,,,,,,,,,,
1616839249.148,,1.000000e+003,2.099989e+002,2.100099e+002,5,0,8.222156e-001,3.273110e-001,3.261818e-001,4.234127e-002,4.331896e-002,3.225602e-001,3.871966e-002,3.969735e-002,8.068107e-006,8.040273e-006,,,,,,,,,,,,,,,,,,,,
1616839580.813,,1.000000e+003,2.151535e+002,2.150899e+002,1,0,5.067800e-001,3.569140e-001,,,,,,,8.797811e-006,,,,,,,,,,,,,,,,,,,,,
1616839580.813,,1.000000e+003,2.150148e+002,2.150090e+002,2,0,8.194660e-001,3.331095e-001,,,,,,,8.211039e-006,,,,,,,,,,,,,,,,,,,,,
1616839580.813,,1.000000e+003,2.150090e+002,2.150032e+002,3,0,1.528446e+000,2.642903e-001,,,,,,,6.514668e-006,,,,,,,,,,,,,,,,,,,,,
1616839580.813,,1.000000e+003,2.150090e+002,2.150032e+002,3,0,2.326576e+000,2.345347e-001,,,,,,,5.781204e-006,,,,,,,,,,,,,,,,,,,,,
1616839580.813,,1.000000e+003,2.150032e+002,2.150090e+002,4,0,2.993431e+000,2.243111e-001,,,,,,,5.529193e-006,,,,,,,,,,,,,,,,,,,,,
1616839580.813,,1.000000e+003,2.150090e+002,2.149975e+002,5,0,3.449301e+000,3.187658e-001,3.298135e-001,4.108997e-002,4.534435e-002,3.324649e-001,4.374134e-002,4.799572e-002,7.857471e-006,8.129794e-006,,,,,,,,,,,,,,,,,,,,
1616839879.823,,1.000000e+003,2.201483e+002,2.200878e+002,1,0,3.351733e+000,3.556933e-001,,,,,,,8.767720e-006,,,,,,,,,,,,,,,,,,,,,
1616839879.823,,1.000000e+003,2.200878e+002,2.200454e+002,2,0,2.730294e+000,2.699362e-001,,,,,,,6.653838e-006,,,,,,,,,,,,,,,,,,,,,
1616839879.823,,1.000000e+003,2.200454e+002,2.200273e+002,3,0,1.934655e+000,1.368755e-001,,,,,,,3.373936e-006,,,,,,,,,,,,,,,,,,,,,
1616839879.823,,1.000000e+003,2.200273e+002,2.200031e+002,4,0,1.211476e+000,2.755821e-001,,,,,,,6.793008e-006,,,,,,,,,,,,,,,,,,,,,
1616839879.823,,1.000000e+003,2.200031e+002,2.200031e+002,5,0,6.639971e-001,3.512681e-001,3.544725e-001,5.621334e-002,5.675265e-002,3.491569e-001,5.089780e-002,5.143711e-002,8.658641e-006,8.737628e-006,,,,,,,,,,,,,,,,,,,,
1616840177.555,,1.000000e+003,2.251578e+002,2.250882e+002,1,0,5.402757e-001,3.816340e-001,,,,,,,9.407150e-006,,,,,,,,,,,,,,,,,,,,,
1616840177.555,,1.000000e+003,2.250882e+002,2.250502e+002,2,0,1.031443e+000,2.670370e-001,,,,,,,6.582372e-006,,,,,,,,,,,,,,,,,,,,,
1616840177.555,,1.000000e+003,2.250375e+002,2.250249e+002,3,0,1.796827e+000,2.032533e-001,,,,,,,5.010126e-006,,,,,,,,,,,,,,,,,,,,,
1616840177.555,,1.000000e+003,2.250375e+002,2.250249e+002,3,0,2.568275e+000,2.417066e-001,,,,,,,5.957987e-006,,,,,,,,,,,,,,,,,,,,,
1616840177.555,,1.000000e+003,2.250249e+002,2.250123e+002,4,0,3.179028e+000,3.134251e-001,,,,,,,7.725825e-006,,,,,,,,,,,,,,,,,,,,,
1616840177.555,,1.000000e+003,2.250123e+002,2.249996e+002,5,0,3.494462e+000,3.309732e-001,3.405561e-001,4.388769e-002,4.796571e-002,3.439146e-001,4.724623e-002,5.132425e-002,8.158380e-006,8.394593e-006,,,,,,,,,,,,,,,,,,,,
1616840475.601,,1.000000e+003,2.301546e+002,2.300951e+002,1,0,3.181789e+000,3.245643e-001,,,,,,,8.000403e-006,,,,,,,,,,,,,,,,,,,,,
1616840475.601,,1.000000e+003,2.300819e+002,2.300488e+002,2,0,2.472768e+000,2.125614e-001,,,,,,,5.239568e-006,,,,,,,,,,,,,,,,,,,,,
1616840475.601,,1.000000e+003,2.300488e+002,2.300224e+002,3,0,1.674622e+000,2.572711e-001,,,,,,,6.341646e-006,,,,,,,,,,,,,,,,,,,,,
1616840475.601,,1.000000e+003,2.300224e+002,2.300092e+002,4,0,1.007868e+000,3.295999e-001,,,,,,,8.124528e-006,,,,,,,,,,,,,,,,,,,,,
1616840475.601,,1.000000e+003,2.300092e+002,2.300092e+002,5,0,5.519812e-001,4.257332e-001,3.925291e-001,6.622459e-002,6.753933e-002,3.816408e-001,5.533628e-002,5.665103e-002,1.049418e-005,9.675711e-006,,,,,,,,,,,,,,,,,,,,
1616840761.968,,1.000000e+003,2.352186e+002,2.351357e+002,1,0,6.495238e-001,3.825495e-001,,,,,,,9.429718e-006,,,,,,,,,,,,,,,,,,,,,
1616840761.968,,1.000000e+003,2.351357e+002,2.350735e+002,2,0,1.270907e+000,2.888577e-001,,,,,,,7.120246e-006,,,,,,,,,,,,,,,,,,,,,
1616840761.968,,1.000000e+003,2.350735e+002,2.350390e+002,3,0,2.066738e+000,2.212592e-001,,,,,,,5.453966e-006,,,,,,,,,,,,,,,,,,,,,
1616840761.968,,1.000000e+003,2.350735e+002,2.350390e+002,3,0,2.789825e+000,3.160192e-001,,,,,,,7.789768e-006,,,,,,,,,,,,,,,,,,,,,
1616840761.968,,1.000000e+003,2.350390e+002,2.350183e+002,4,0,3.337241e+000,3.503525e-001,,,,,,,8.636072e-006,,,,,,,,,,,,,,,,,,,,,
1616840761.968,,1.000000e+003,2.350252e+002,2.350114e+002,5,0,3.461023e+000,3.376873e-001,3.651845e-001,3.843649e-002,4.218796e-002,3.708843e-001,4.413628e-002,4.788774e-002,8.323880e-006,9.001677e-006,,,,,,,,,,,,,,,,,,,,
1616841060.274,,1.000000e+003,2.401539e+002,2.400818e+002,1,0,2.969774e+000,2.719199e-001,,,,,,,6.702735e-006,,,,,,,,,,,,,,,,,,,,,
1616841060.274,,1.000000e+003,2.400818e+002,2.400386e+002,2,0,2.204394e+000,1.638844e-001,,,,,,,4.039696e-006,,,,,,,,,,,,,,,,,,,,,
1616841060.274,,1.000000e+003,2.400386e+002,2.400098e+002,3,0,1.432894e+000,2.336192e-001,,,,,,,5.758635e-006,,,,,,,,,,,,,,,,,,,,,
1616841060.274,,1.000000e+003,2.400098e+002,2.400098e+002,4,0,8.222903e-001,3.587451e-001,,,,,,,8.842947e-006,,,,,,,,,,,,,,,,,,,,,
1616841060.274,,1.000000e+003,2.400098e+002,2.399953e+002,5,0,5.067945e-001,3.895688e-001,3.653676e-001,6.599697e-002,6.711844e-002,3.556373e-001,5.626669e-002,5.738816e-002,9.602741e-006,9.006189e-006,,,,,,,,,,,,,,,,,,,,
1616841361.519,,1.000000e+003,2.451465e+002,2.450864e+002,1,0,8.194415e-001,3.617969e-001,,,,,,,8.918174e-006,,,,,,,,,,,,,,,,,,,,,
1616841361.519,,1.000000e+003,2.450789e+002,2.450488e+002,2,0,1.528414e+000,2.598651e-001,,,,,,,6.405588e-006,,,,,,,,,,,,,,,,,,,,,
1616841361.519,,1.000000e+003,2.450789e+002,2.450488e+002,2,0,2.326549e+000,2.299570e-001,,,,,,,5.668363e-006,,,,,,,,,,,,,,,,,,,,,
1616841361.519,,1.000000e+003,2.450488e+002,2.450187e+002,3,0,2.993337e+000,3.141881e-001,,,,,,,7.744631e-006,,,,,,,,,,,,,,,,,,,,,
1616841361.519,,1.000000e+003,2.450187e+002,2.450037e+002,4,0,3.449223e+000,3.946043e-001,,,,,,,9.726866e-006,,,,,,,,,,,,,,,,,,,,,
1616841361.519,,1.000000e+003,2.450037e+002,2.450037e+002,5,0,3.351861e+000,3.144932e-001,3.501389e-001,2.320005e-002,2.864504e-002,3.600373e-001,3.309848e-002,3.854346e-002,7.752154e-006,8.630806e-006,,,,,,,,,,,,,,,,,,,,
1616841661.360,,1.000000e+003,2.501586e+002,2.500881e+002,1,0,2.730246e+000,2.504044e-001,,,,,,,6.172384e-006,,,,,,,,,,,,,,,,,,,,,
1616841661.360,,1.000000e+003,2.500881e+002,2.500411e+002,2,0,1.934669e+000,2.082888e-001,,,,,,,5.134250e-006,,,,,,,,,,,,,,,,,,,,,
1616841661.360,,1.000000e+003,2.500411e+002,2.500177e+002,3,0,1.211495e+000,3.285317e-001,,,,,,,8.098198e-006,,,,,,,,,,,,,,,,,,,,,
1616841661.360,,1.000000e+003,2.500177e+002,2.500099e+002,4,0,6.640639e-001,3.804132e-001,,,,,,,9.377060e-006,,,,,,,,,,,,,,,,,,,,,
1616841661.360,,1.000000e+003,2.500099e+002,2.499942e+002,5,0,5.402240e-001,4.036073e-001,3.903317e-001,6.617494e-002,6.789610e-002,3.802594e-001,5.610262e-002,5.782378e-002,9.948785e-006,9.621547e-006,,,,,,,,,,,,,,,,,,,,
1616841961.082,,1.000000e+003,2.551464e+002,2.550811e+002,1,0,1.031525e+000,3.135777e-001,,,,,,,7.729585e-006,,,,,,,,,,,,,,,,,,,,,
1616841961.082,,1.000000e+003,2.550811e+002,2.550404e+002,2,0,1.796893e+000,2.546769e-001,,,,,,,6.277702e-006,,,,,,,,,,,,,,,,,,,,,
1616841961.082,,1.000000e+003,2.550811e+002,2.550404e+002,2,0,2.568344e+000,2.897733e-001,,,,,,,7.142814e-006,,,,,,,,,,,,,,,,,,,,,
1616841961.082,,1.000000e+003,2.550404e+002,2.550160e+002,3,0,3.178970e+000,3.086947e-001,,,,,,,7.609222e-006,,,,,,,,,,,,,,,,,,,,,
1616841961.082,,1.000000e+003,2.550160e+002,2.550079e+002,4,0,3.494468e+000,3.741570e-001,,,,,,,9.222844e-006,,,,,,,,,,,,,,,,,,,,,
1616841961.082,,1.000000e+003,2.549997e+002,2.550079e+002,5,0,3.181894e+000,3.384503e-001,3.310953e-001,1.999098e-003,8.010030e-003,3.406566e-001,1.156037e-002,1.757130e-002,8.342687e-006,8.161389e-006,,,,,,,,,,,,,,,,,,,,
1616842262.180,,1.000000e+003,2.601447e+002,2.600853e+002,1,0,2.472865e+000,2.497940e-001,,,,,,,6.157339e-006,,,,,,,,,,,,,,,,,,,,,
1616842262.180,,1.000000e+003,2.600853e+002,2.600345e+002,2,0,1.674751e+000,2.533036e-001,,,,,,,6.243850e-006,,,,,,,,,,,,,,,,,,,,,
1616842262.180,,1.000000e+003,2.600345e+002,2.600260e+002,3,0,1.008021e+000,3.701895e-001,,,,,,,9.125049e-006,,,,,,,,,,,,,,,,,,,,,
1616842262.180,,1.000000e+003,2.600260e+002,2.600090e+002,4,0,5.520704e-001,4.127628e-001,,,,,,,1.017447e-005,,,,,,,,,,,,,,,,,,,,,
1616842262.180,,1.000000e+003,2.600090e+002,2.600005e+002,5,0,6.493610e-001,3.962829e-001,3.989074e-001,5.727267e-002,5.884475e-002,3.950032e-001,5.336848e-002,5.494055e-002,9.768240e-006,9.832936e-006,,,,,,,,,,,,,,,,,,,,
1616842564.671,,1.000000e+003,2.651355e+002,2.650825e+002,1,0,1.270851e+000,2.584918e-001,,,,,,,6.371736e-006,,,,,,,,,,,,,,,,,,,,,
1616842564.671,,1.000000e+003,2.650825e+002,2.650385e+002,2,0,2.066489e+000,1.388592e-001,,,,,,,3.422834e-006,,,,,,,,,,,,,,,,,,,,,
1616842564.671,,1.000000e+003,2.650825e+002,2.650385e+002,2,0,2.789639e+000,2.346873e-001,,,,,,,5.784965e-006,,,,,,,,,,,,,,,,,,,,,
1616842564.671,,1.000000e+003,2.650385e+002,2.650208e+002,3,0,3.337159e+000,3.270058e-001,,,,,,,8.060585e-006,,,,,,,,,,,,,,,,,,,,,
1616842564.671,,1.000000e+003,2.650120e+002,2.650120e+002,4,0,3.461087e+000,3.651540e-001,,,,,,,9.000923e-006,,,,,,,,,,,,,,,,,,,,,
1616842564.671,,1.000000e+003,2.650032e+002,2.649943e+002,5,0,2.969898e+000,3.057955e-001,2.768945e-001,-2.814783e-002,-2.346230e-002,2.846397e-001,-2.040259e-002,-1.571706e-002,7.537757e-006,6.825356e-006,,,,,,,,,,,,,,,,,,,,
1616842908.855,,1.000000e+003,2.701332e+002,2.700781e+002,1,0,2.204453e+000,2.319407e-001,,,,,,,5.717260e-006,,,,,,,,,,,,,,,,,,,,,
1616842908.855,,1.000000e+003,2.700138e+002,2.699955e+002,2,0,1.433191e+000,3.166296e-001,,,,,,,7.804812e-006,,,,,,,,,,,,,,,,,,,,,
1616842908.855,,1.000000e+003,2.699955e+002,2.700046e+002,3,0,8.226297e-001,4.446547e-001,,,,,,,1.096059e-005,,,,,,,,,,,,,,,,,,,,,
1616842908.855,,1.000000e+003,2.700138e+002,2.700046e+002,4,0,5.067618e-001,3.900266e-001,,,,,,,9.614025e-006,,,,,,,,,,,,,,,,,,,,,
1616842908.855,,1.000000e+003,2.700046e+002,2.700046e+002,5,0,8.191588e-001,3.433332e-001,3.889279e-001,4.357447e-002,4.512843e-002,3.886487e-001,4.329534e-002,4.484931e-002,8.463050e-006,9.586943e-006,,,,,,,,,,,,,,,,,,,,
1616843210.414,,1.000000e+003,2.751358e+002,2.750689e+002,1,0,1.528137e+000,2.487259e-001,,,,,,,6.131009e-006,,,,,,,,,,,,,,,,,,,,,
1616843210.414,,1.000000e+003,2.751358e+002,2.750689e+002,1,0,2.326296e+000,2.088992e-001,,,,,,,5.149296e-006,,,,,,,,,,,,,,,,,,,,,
1616843210.414,,1.000000e+003,2.750689e+002,2.750307e+002,2,0,2.993059e+000,3.494369e-001,,,,,,,8.613504e-006,,,,,,,,,,,,,,,,,,,,,
1616843210.414,,1.000000e+003,2.750307e+002,2.750117e+002,3,0,3.449118e+000,3.901792e-001,,,,,,,9.617786e-006,,,,,,,,,,,,,,,,,,,,,
1616843210.414,,1.000000e+003,2.750117e+002,2.750021e+002,4,0,3.352109e+000,3.518784e-001,,,,,,,8.673685e-006,,,,,,,,,,,,,,,,,,,,,
1616843210.414,,1.000000e+003,2.750021e+002,2.750021e+002,5,0,2.730792e+000,3.068636e-001,2.817163e-001,-6.460730e-002,-5.940643e-002,2.847843e-001,-6.153936e-002,-5.633849e-002,7.564086e-006,6.944214e-006,,,,,,,,,,,,,,,,,,,,
1616843538.433,,1.000000e+003,2.800321e+002,2.800123e+002,1,0,1.935084e+000,2.478103e-001,,,,,,,6.108442e-006,,,,,,,,,,,,,,,,,,,,,
1616843538.433,,1.000000e+003,2.800123e+002,2.800024e+002,2,0,1.211699e+000,3.541673e-001,,,,,,,8.730106e-006,,,,,,,,,,,,,,,,,,,,,
1616843538.433,,1.000000e+003,2.800024e+002,2.800024e+002,3,0,6.642497e-001,4.272591e-001,,,,,,,1.053179e-005,,,,,,,,,,,,,,,,,,,,,
1616843538.433,,1.000000e+003,2.800024e+002,2.800024e+002,4,0,5.401186e-001,3.971984e-001,,,,,,,9.790809e-006,,,,,,,,,,,,,,,,,,,,,
1616843538.433,,1.000000e+003,2.800024e+002,2.799925e+002,5,0,1.031187e+000,3.479110e-001,3.630787e-001,1.482551e-002,1.597008e-002,3.682324e-001,1.997917e-002,2.112374e-002,8.575890e-006,8.949769e-006,,,,,,,,,,,,,,,,,,,,
1616843882.387,,1.000000e+003,2.850143e+002,2.849937e+002,1,0,1.796582e+000,2.710043e-001,,,,,,,6.680167e-006,,,,,,,,,,,,,,,,,,,,,
1616843882.387,,1.000000e+003,2.850143e+002,2.849937e+002,1,0,2.568088e+000,3.004547e-001,,,,,,,7.406109e-006,,,,,,,,,,,,,,,,,,,,,
1616843882.387,,1.000000e+003,2.849937e+002,2.850040e+002,2,0,3.178769e+000,3.984192e-001,,,,,,,9.820899e-006,,,,,,,,,,,,,,,,,,,,,
1616843882.387,,1.000000e+003,2.850040e+002,2.850040e+002,3,0,3.494509e+000,3.393658e-001,,,,,,,8.365255e-006,,,,,,,,,,,,,,,,,,,,,
1616843882.387,,1.000000e+003,2.850040e+002,2.849937e+002,4,0,3.182133e+000,3.543199e-001,,,,,,,8.733868e-006,,,,,,,,,,,,,,,,,,,,,
1616843882.387,,1.000000e+003,2.849937e+002,2.850143e+002,5,0,2.473074e+000,2.963347e-001,2.614826e-001,-1.036834e-001,-9.802806e-002,2.595666e-001,-1.055993e-001,-9.994403e-002,7.304553e-006,6.445459e-006,,,,,,,,,,,,,,,,,,,,
1616844185.484,,1.000000e+003,2.901237e+002,2.900703e+002,1,0,1.674835e+000,2.497940e-001,,,,,,,6.157339e-006,,,,,,,,,,,,,,,,,,,,,
1616844185.484,,1.000000e+003,2.900703e+002,2.900276e+002,2,0,1.008158e+000,4.037599e-001,,,,,,,9.952547e-006,,,,,,,,,,,,,,,,,,,,,
1616844185.484,,1.000000e+003,2.900276e+002,2.900169e+002,3,0,5.520815e-001,4.193243e-001,,,,,,,1.033620e-005,,,,,,,,,,,,,,,,,,,,,
1616844185.484,,1.000000e+003,2.900062e+002,2.900062e+002,4,0,6.492437e-001,4.005554e-001,,,,,,,9.873558e-006,,,,,,,,,,,,,,,,,,,,,
1616844185.484,,1.000000e+003,2.900062e+002,2.899955e+002,5,0,1.270674e+000,3.625599e-001,3.364666e-001,-1.824005e-002,-1.708415e-002,3.413516e-001,-1.335506e-002,-1.219916e-002,8.936981e-006,8.293789e-006,,,,,,,,,,,,,,,,,,,,
1616844491.511,,1.000000e+003,2.951198e+002,2.950645e+002,1,0,2.066418e+000,1.988281e-001,,,,,,,4.901046e-006,,,,,,,,,,,,,,,,,,,,,
1616844491.511,,1.000000e+003,2.951198e+002,2.950645e+002,1,0,2.789635e+000,2.948088e-001,,,,,,,7.266939e-006,,,,,,,,,,,,,,,,,,,,,
1616844491.511,,1.000000e+003,2.950645e+002,2.950201e+002,2,0,3.337055e+000,4.005554e-001,,,,,,,9.873558e-006,,,,,,,,,,,,,,,,,,,,,
1616844491.511,,1.000000e+003,2.950201e+002,2.950201e+002,3,0,3.461224e+000,4.309213e-001,,,,,,,1.062207e-005,,,,,,,,,,,,,,,,,,,,,
1616844491.511,,1.000000e+003,2.950091e+002,2.949980e+002,4,0,2.970092e+000,3.077792e-001,,,,,,,7.586654e-006,,,,,,,,,,,,,,,,,,,,,
1616844491.511,,1.000000e+003,2.949980e+002,2.949980e+002,5,0,2.204704e+000,2.543718e-001,2.395093e-001,-1.280510e-001,-1.225689e-001,2.362722e-001,-1.312881e-001,-1.258060e-001,6.270180e-006,5.903823e-006,,,,,,,,,,,,,,,,,,,,
1616844797.826,,1.000000e+003,3.001215e+002,3.000756e+002,1,0,1.433264e+000,3.288369e-001,,,,,,,8.105721e-006,,,,,,,,,,,,,,,,,,,,,
1616844797.826,,1.000000e+003,3.000756e+002,3.000411e+002,2,0,8.226231e-001,4.098636e-001,,,,,,,1.010300e-005,,,,,,,,,,,,,,,,,,,,,
1616844797.826,,1.000000e+003,3.000411e+002,3.000181e+002,3,0,5.067659e-001,4.811243e-001,,,,,,,1.185955e-005,,,,,,,,,,,,,,,,,,,,,
1616844797.826,,1.000000e+003,3.000181e+002,3.000067e+002,4,0,8.191076e-001,4.564043e-001,,,,,,,1.125021e-005,,,,,,,,,,,,,,,,,,,,,
1616844797.826,,1.000000e+003,3.000067e+002,2.999952e+002,5,0,1.528069e+000,2.584918e-001,3.108005e-001,-6.092956e-002,-6.014198e-002,3.176832e-001,-5.404681e-002,-5.325922e-002,6.371736e-006,7.661129e-006,,,,,,,,,,,,,,,,,,,,
1616844797.826,,1.000000e+003,3.000067e+002,2.999952e+002,5,0,2.326234e+000,2.212592e-001,2.705771e-001,-1.125729e-001,-1.003654e-001,2.576540e-001,-1.254960e-001,-1.132885e-001,5.453966e-006,6.669636e-006,,,,,,,,,,,,,,,,,,,,
1616844797.826,,1.000000e+003,3.000067e+002,2.999952e+002,5,0,2.198110e+000,2.165288e-001,2.673422e-001,-1.160048e-001,-1.036003e-001,2.512636e-001,-1.320833e-001,-1.196789e-001,5.337363e-006,6.589895e-006,,,,,,,,,,,,,,,,,,,,