File: SiC glued/Hyst at 30K/SiC1Glued_hyst_30K.rso.dat.csv
[Header]
TITLE,MPMS RSO Measurement
BYAPP,MPMS Measurement,1.1,Summary
FILEOPENTIME, 1616447463.258000 3/22/2021, 10:11:03 PM

INFO, APPNAME, MPMS MultiVu Application, Revision 1.61,  Build 082

INFO, NAME,
INFO, WEIGHT, 1.000
INFO, AREA, 1.000
INFO, LENGTH, 1.000
INFO, SHAPE, 0
INFO, COMMENT,
INFO, SEQUENCE FILE: H5T_Lin_NoO.seq


INFO, BACKGROUND DATA FILE:, None


STARTUPAXIS,X,4,LINEAR,AUTO,0.000000,0.000000
STARTUPAXIS,Y1,5,LINEAR,AUTO,0.000000,0.000000


STARTUPGROUP,Longitudinal
FIELDGROUP,Longitudinal,1,2,3,4,5,6,7,8,9,10,11,19,20,21,22,23,35
FIELDGROUP,Transverse,1,2,3,4,12,13,14,15,16,17,18,24,25,26,27,28,35

PLOT_APPEARANCE,ALL,HORZ_GRID_ON,VERT_GRID_ON,MARKERS_AND_LINES

[Data]
Time,Comment,Field (Oe),Temperature (K),Long Moment (emu),Long Scan Std Dev,Long Offset (cm),Long Offset Std Dev,Long Algorithm,Long Reg Fit,Long Reg Factor,Trans Moment (emu),Trans Scan Std Dev,Trans Offset (cm),Trans Offset Std Dev,Trans Algorithm,Trans Reg Fit,Trans Reg Factor,Long Moment [w/o ABS] (emu),Long Scan Std Dev [w/o ABS],Long Offset [w/o ABS] (cm),Long Offset Std Dev [w/o ABS],Long Reg Fit [w/o ABS],Trans Moment [w/o ABS] (emu),Trans Scan Std Dev [w/o ABS],Trans Offset [w/o ABS] (cm),Trans Offset Std Dev [w/o ABS],Trans Reg Fit [w/o ABS],RSO Position (deg),Amplitude (cm),Frequency,Cycles to Average,Scans per Measurement,Delta Temp (K),Error,EC Comp. Running,Using ABS,
1616447463.258,,0.000000e+000,3.000026e+001,-2.433982e-008,4.101312e-009,0.000000e+000,0.000000e+000,2,3.897990e-002,1.825000e+000,,,,,,,,,,,,,,,,,,0,3.000000e+000,1.000000e+000,10,5,4.339218e-003,0,,0,
1616447652.017,,2.000000e+002,3.000084e+001,-5.986558e-007,3.973307e-009,0.000000e+000,0.000000e+000,2,8.964517e-001,1.825000e+000,,,,,,,,,,,,,,,,,,0,3.000000e+000,1.000000e+000,10,5,2.889633e-003,0,,0,
1616447846.797,,4.000000e+002,3.000041e+001,-1.219413e-006,3.294913e-009,0.000000e+000,0.000000e+000,2,8.697177e-001,1.825000e+000,,,,,,,,,,,,,,,,,,0,3.000000e+000,1.000000e+000,10,5,1.449585e-003,0,,0,
1616448036.016,,6.000000e+002,3.000056e+001,-1.995630e-006,1.148651e-008,0.000000e+000,0.000000e+000,2,8.697315e-001,1.825000e+000,,,,,,,,,,,,,,,,,,0,3.000000e+000,1.000000e+000,10,5,1.449585e-003,0,,0,
1616448224.315,,8.000000e+002,3.000041e+001,-2.891850e-006,5.465482e-009,0.000000e+000,0.000000e+000,2,8.765936e-001,1.825000e+000,,,,,,,,,,,,,,,,,,0,3.000000e+000,1.000000e+000,10,5,4.339218e-003,0,,0,
1616448413.094,,1.000000e+003,3.000128e+001,-3.836964e-006,9.990615e-009,0.000000e+000,0.000000e+000,2,8.844652e-001,1.825000e+000,,,,,,,,,,,,,,,,,,0,3.000000e+000,1.000000e+000,10,5,4.339218e-003,0,,0,
1616448627.774,,1.500000e+003,3.000099e+001,-6.268821e-006,2.112674e-008,0.000000e+000,0.000000e+000,2,8.957297e-001,1.825000e+000,,,,,,,,,,,,,,,,,,0,3.000000e+000,1.000000e+000,10,5,2.889633e-003,0,,0,
1616448823.613,,2.000000e+003,3.000041e+001,-8.724655e-006,1.182102e-008,0.000000e+000,0.000000e+000,2,9.016173e-001,1.825000e+000,,,,,,,,,,,,,,,,,,0,3.000000e+000,1.000000e+000,10,5,1.449585e-003,0,,0,
1616449021.473,,2.500000e+003,3.000027e+001,-1.118597e-005,3.721100e-008,0.000000e+000,0.000000e+000,2,9.042531e-001,1.825000e+000,,,,,,,,,,,,,,,,,,0,3.000000e+000,1.000000e+000,10,5,2.899170e-003,0,,0,
1616449220.312,,3.000000e+003,3.000041e+001,-1.365907e-005,4.190844e-008,0.000000e+000,0.000000e+000,2,9.036031e-001,1.825000e+000,,,,,,,,,,,,,,,,,,0,3.000000e+000,1.000000e+000,10,5,5.788803e-003,0,,0,
1616449416.432,,3.500000e+003,3.000012e+001,-1.615851e-005,3.637053e-008,0.000000e+000,0.000000e+000,2,9.048181e-001,1.825000e+000,,,,,,,,,,,,,,,,,,0,3.000000e+000,1.000000e+000,10,5,4.339218e-003,0,,0,
1616449613.931,,4.000000e+003,3.000070e+001,-1.867537e-005,7.820125e-008,0.000000e+000,0.000000e+000,2,9.060479e-001,1.825000e+000,,,,,,,,,,,,,,,,,,0,3.000000e+000,1.000000e+000,10,5,2.889633e-003,0,,0,
1616449807.530,,5.000000e+003,3.000084e+001,-2.360206e-005,5.291974e-008,0.000000e+000,0.000000e+000,2,9.050786e-001,1.825000e+000,,,,,,,,,,,,,,,,,,0,3.000000e+000,1.000000e+000,10,5,2.889633e-003,0,,0,
1616450006.980,,6.000000e+003,3.000070e+001,-2.856835e-005,6.125696e-008,0.000000e+000,0.000000e+000,2,9.045367e-001,1.825000e+000,,,,,,,,,,,,,,,,,,0,3.000000e+000,1.000000e+000,10,5,4.339218e-003,0,,0,
1616450206.309,,7.000000e+003,3.000113e+001,-3.352357e-005,3.043520e-008,0.000000e+000,0.000000e+000,2,9.042009e-001,1.825000e+000,,,,,,,,,,,,,,,,,,0,3.000000e+000,1.000000e+000,10,5,1.440048e-003,0,,0,
1616450394.398,,8.000000e+003,3.000084e+001,-3.849199e-005,4.509383e-008,0.000000e+000,0.000000e+000,2,9.029759e-001,1.825000e+000,,,,,,,,,,,,,,,,,,0,3.000000e+000,1.000000e+000,10,5,4.339218e-003,0,,0,
1616450573.888,,9.000000e+003,3.000041e+001,-4.346936e-005,5.990089e-008,0.000000e+000,0.000000e+000,2,9.017667e-001,1.825000e+000,,,,,,,,,,,,,,,,,,0,3.000000e+000,1.000000e+000,10,5,4.339218e-003,0,,0,
1616450761.867,,1.000000e+004,3.000142e+001,-4.837478e-005,5.402948e-008,0.000000e+000,0.000000e+000,2,9.002704e-001,1.825000e+000,,,,,,,,,,,,,,,,,,0,3.000000e+000,1.000000e+000,10,5,2.889633e-003,0,,0,
1616450947.027,,1.200000e+004,2.999998e+001,-5.830494e-005,7.256533e-008,0.000000e+000,0.000000e+000,2,8.994551e-001,1.825000e+000,,,,,,,,,,,,,,,,,,0,3.000000e+000,1.000000e+000,10,5,2.899170e-003,0,,0,
1616451139.646,,1.400000e+004,2.999954e+001,-6.840725e-005,8.950110e-008,0.000000e+000,0.000000e+000,2,8.989814e-001,1.825000e+000,,,,,,,,,,,,,,,,,,0,3.000000e+000,1.000000e+000,10,5,2.899170e-003,0,,0,
1616451325.155,,1.600000e+004,3.000012e+001,-7.835856e-005,4.127176e-008,0.000000e+000,0.000000e+000,2,8.983985e-001,1.825000e+000,,,,,,,,,,,,,,,,,,0,3.000000e+000,1.000000e+000,10,5,2.889633e-003,0,,0,
1616451517.075,,1.800000e+004,3.000171e+001,-8.837702e-005,1.156787e-007,0.000000e+000,0.000000e+000,2,8.982387e-001,1.825000e+000,,,,,,,,,,,,,,,,,,0,3.000000e+000,1.000000e+000,10,5,1.440048e-003,0,,0,
1616451703.604,,2.000000e+004,3.000041e+001,-9.836155e-005,1.016582e-007,0.000000e+000,0.000000e+000,2,8.982773e-001,1.825000e+000,,,,,,,,,,,,,,,,,,0,3.000000e+000,1.000000e+000,10,5,2.889633e-003,0,,0,
1616451912.413,,2.500000e+004,3.000084e+001,-1.234162e-004,1.030078e-007,0.000000e+000,0.000000e+000,2,8.979853e-001,1.825000e+000,,,,,,,,,,,,,,,,,,0,3.000000e+000,1.000000e+000,10,5,2.889633e-003,0,,0,
1616452122.252,,3.000000e+004,3.000070e+001,-1.484028e-004,9.172602e-008,0.000000e+000,0.000000e+000,2,8.972783e-001,1.825000e+000,,,,,,,,,,,,,,,,,,0,3.000000e+000,1.000000e+000,10,5,2.889633e-003,0,,0,
1616452331.612,,3.500000e+004,3.000099e+001,-1.734867e-004,1.794907e-007,0.000000e+000,0.000000e+000,2,8.972307e-001,1.825000e+000,,,,,,,,,,,,,,,,,,0,3.000000e+000,1.000000e+000,10,5,2.889633e-003,0,,0,
1616452535.661,,4.000000e+004,3.000214e+001,-1.985731e-004,5.146686e-008,0.000000e+000,0.000000e+000,2,8.969077e-001,1.825000e+000,,,,,,,,,,,,,,,,,,0,3.000000e+000,1.000000e+000,10,5,4.339218e-003,0,,0,
1616452742.260,,4.500000e+004,3.000099e+001,-2.236097e-004,1.193104e-007,0.000000e+000,0.000000e+000,2,8.967832e-001,1.825000e+000,,,,,,,,,,,,,,,,,,0,3.000000e+000,1.000000e+000,10,5,2.889633e-003,0,,0,
1616452948.839,,5.000000e+004,3.000157e+001,-2.487023e-004,1.941583e-007,0.000000e+000,0.000000e+000,2,8.968195e-001,1.825000e+000,,,,,,,,,,,,,,,,,,0,3.000000e+000,1.000000e+000,10,5,4.339218e-003,0,,0,
1616453185.838,,4.500000e+004,3.000027e+001,-2.236197e-004,1.882066e-007,0.000000e+000,0.000000e+000,2,8.970935e-001,1.825000e+000,,,,,,,,,,,,,,,,,,0,3.000000e+000,1.000000e+000,10,5,4.339218e-003,0,,0,
1616453400.738,,4.000000e+004,3.000041e+001,-1.984927e-004,2.090376e-007,0.000000e+000,0.000000e+000,2,8.967789e-001,1.825000e+000,,,,,,,,,,,,,,,,,,0,3.000000e+000,1.000000e+000,10,5,4.339218e-003,0,,0,
1616453607.657,,3.500000e+004,3.000012e+001,-1.734096e-004,1.440856e-007,0.000000e+000,0.000000e+000,2,8.967026e-001,1.825000e+000,,,,,,,,,,,,,,,,,,0,3.000000e+000,1.000000e+000,10,5,2.899170e-003,0,,0,
1616453807.856,,3.000000e+004,3.000012e+001,-1.483397e-004,7.443760e-008,0.000000e+000,0.000000e+000,2,8.971010e-001,1.825000e+000,,,,,,,,,,,,,,,,,,0,3.000000e+000,1.000000e+000,10,5,4.339218e-003,0,,0,
1616454019.115,,2.500000e+004,3.000157e+001,-1.233171e-004,5.360079e-008,0.000000e+000,0.000000e+000,2,8.976740e-001,1.825000e+000,,,,,,,,,,,,,,,,,,0,3.000000e+000,1.000000e+000,10,5,4.339218e-003,0,,0,
1616454222.145,,2.000000e+004,3.000128e+001,-9.828211e-005,1.684167e-007,0.000000e+000,0.000000e+000,2,8.981365e-001,1.825000e+000,,,,,,,,,,,,,,,,,,0,3.000000e+000,1.000000e+000,10,5,2.889633e-003,0,,0,
1616454412.744,,1.800000e+004,3.000070e+001,-8.832132e-005,7.974626e-008,0.000000e+000,0.000000e+000,2,8.982061e-001,1.825000e+000,,,,,,,,,,,,,,,,,,0,3.000000e+000,1.000000e+000,10,5,4.339218e-003,0,,0,
1616454617.993,,1.600000e+004,3.000027e+001,-7.826369e-005,9.427478e-008,0.000000e+000,0.000000e+000,2,8.984168e-001,1.825000e+000,,,,,,,,,,,,,,,,,,0,3.000000e+000,1.000000e+000,10,5,1.449585e-003,0,,0,
1616454803.143,,1.400000e+004,3.000070e+001,-6.833628e-005,4.768485e-008,0.000000e+000,0.000000e+000,2,8.988020e-001,1.825000e+000,,,,,,,,,,,,,,,,,,0,3.000000e+000,1.000000e+000,10,5,2.899170e-003,0,,0,
1616454995.273,,1.200000e+004,3.000084e+001,-5.833499e-005,7.732289e-008,0.000000e+000,0.000000e+000,2,8.996644e-001,1.825000e+000,,,,,,,,,,,,,,,,,,0,3.000000e+000,1.000000e+000,10,5,4.339218e-003,0,,0,
1616455188.382,,1.000000e+004,3.000055e+001,-4.834296e-005,5.798665e-008,0.000000e+000,0.000000e+000,2,9.001105e-001,1.825000e+000,,,,,,,,,,,,,,,,,,0,3.000000e+000,1.000000e+000,10,5,2.889633e-003,0,,0,
1616455374.092,,9.000000e+003,3.000099e+001,-4.335910e-005,2.549050e-008,0.000000e+000,0.000000e+000,2,9.004384e-001,1.825000e+000,,,,,,,,,,,,,,,,,,0,3.000000e+000,1.000000e+000,10,5,4.339218e-003,0,,0,
1616455562.401,,8.000000e+003,3.000055e+001,-3.836196e-005,9.671938e-009,0.000000e+000,0.000000e+000,2,9.007961e-001,1.825000e+000,,,,,,,,,,,,,,,,,,0,3.000000e+000,1.000000e+000,10,5,2.889633e-003,0,,0,
1616455796.671,,7.000000e+003,3.000070e+001,-3.338612e-005,3.404133e-008,0.000000e+000,0.000000e+000,2,9.010858e-001,1.825000e+000,,,,,,,,,,,,,,,,,,0,3.000000e+000,1.000000e+000,10,5,1.449585e-003,0,,0,
1616455995.860,,6.000000e+003,3.000070e+001,-2.843061e-005,2.661598e-008,0.000000e+000,0.000000e+000,2,9.013831e-001,1.825000e+000,,,,,,,,,,,,,,,,,,0,3.000000e+000,1.000000e+000,10,5,2.889633e-003,0,,0,
1616456193.749,,5.000000e+003,3.000041e+001,-2.344305e-005,2.234665e-008,0.000000e+000,0.000000e+000,2,9.007791e-001,1.825000e+000,,,,,,,,,,,,,,,,,,0,3.000000e+000,1.000000e+000,10,5,4.339218e-003,0,,0,
1616456408.859,,4.000000e+003,3.000084e+001,-1.846993e-005,1.792447e-008,0.000000e+000,0.000000e+000,2,9.012806e-001,1.825000e+000,,,,,,,,,,,,,,,,,,0,3.000000e+000,1.000000e+000,10,5,2.889633e-003,0,,0,
1616456654.238,,3.500000e+003,3.000055e+001,-1.601578e-005,1.564767e-008,0.000000e+000,0.000000e+000,2,9.005232e-001,1.825000e+000,,,,,,,,,,,,,,,,,,0,3.000000e+000,1.000000e+000,10,5,5.788803e-003,0,,0,
1616456884.587,,3.000000e+003,3.000070e+001,-1.355834e-005,5.961311e-009,0.000000e+000,0.000000e+000,2,8.985689e-001,1.825000e+000,,,,,,,,,,,,,,,,,,0,3.000000e+000,1.000000e+000,10,5,2.889633e-003,0,,0,
1616457139.326,,2.500000e+003,2.999969e+001,-1.116014e-005,1.965631e-007,0.000000e+000,0.000000e+000,2,8.821595e-001,1.825000e+000,,,,,,,,,,,,,,,,,,0,3.000000e+000,1.000000e+000,10,5,2.899170e-003,0,,0,
1616457358.636,,2.000000e+003,2.999998e+001,-8.624769e-006,5.174274e-008,0.000000e+000,0.000000e+000,2,8.939874e-001,1.825000e+000,,,,,,,,,,,,,,,,,,0,3.000000e+000,1.000000e+000,10,5,1.449585e-003,0,,0,
1616457558.735,,1.500000e+003,3.000099e+001,-6.201504e-006,1.753824e-008,0.000000e+000,0.000000e+000,2,8.826443e-001,1.825000e+000,,,,,,,,,,,,,,,,,,0,3.000000e+000,1.000000e+000,10,5,2.889633e-003,0,,0,
1616457752.124,,1.000000e+003,2.999969e+001,-3.766678e-006,4.805723e-008,0.000000e+000,0.000000e+000,2,8.472720e-001,1.825000e+000,,,,,,,,,,,,,,,,,,0,3.000000e+000,1.000000e+000,10,5,2.899170e-003,0,,0,
1616457940.314,,8.000000e+002,3.000099e+001,-2.875695e-006,2.901152e-008,0.000000e+000,0.000000e+000,2,8.280130e-001,1.825000e+000,,,,,,,,,,,,,,,,,,0,3.000000e+000,1.000000e+000,10,5,4.339218e-003,0,,0,
1616458129.052,,6.000000e+002,3.000070e+001,-1.977315e-006,2.849433e-008,0.000000e+000,0.000000e+000,2,8.029113e-001,1.825000e+000,,,,,,,,,,,,,,,,,,0,3.000000e+000,1.000000e+000,10,5,2.889633e-003,0,,0,
1616458317.730,,4.000000e+002,3.000012e+001,-1.132352e-006,2.493497e-008,0.000000e+000,0.000000e+000,2,6.910426e-001,1.825000e+000,,,,,,,,,,,,,,,,,,0,3.000000e+000,1.000000e+000,10,5,2.899170e-003,0,,0,
1616458512.059,,2.000000e+002,3.000041e+001,-3.694463e-007,5.637683e-008,0.000000e+000,0.000000e+000,2,2.323902e-001,1.825000e+000,,,,,,,,,,,,,,,,,,0,3.000000e+000,1.000000e+000,10,5,2.889633e-003,0,,0,
1616458706.487,,0.000000e+000,3.000070e+001,2.562728e-007,4.262145e-008,0.000000e+000,0.000000e+000,2,2.616569e-001,1.825000e+000,,,,,,,,,,,,,,,,,,0,3.000000e+000,1.000000e+000,10,5,2.889633e-003,0,,0,
1616458900.616,,-2.000000e+002,3.000128e+001,6.379857e-007,4.082990e-008,0.000000e+000,0.000000e+000,2,7.191143e-001,1.825000e+000,,,,,,,,,,,,,,,,,,0,3.000000e+000,1.000000e+000,10,5,2.889633e-003,0,,0,
1616459094.654,,-4.000000e+002,2.999983e+001,1.259013e-006,3.557277e-008,0.000000e+000,0.000000e+000,2,8.448964e-001,1.825000e+000,,,,,,,,,,,,,,,,,,0,3.000000e+000,1.000000e+000,10,5,2.899170e-003,0,,0,
1616459283.673,,-6.000000e+002,3.000128e+001,2.020574e-006,6.230565e-008,0.000000e+000,0.000000e+000,2,8.635308e-001,1.825000e+000,,,,,,,,,,,,,,,,,,0,3.000000e+000,1.000000e+000,10,5,2.889633e-003,0,,0,
1616459472.051,,-8.000000e+002,3.000041e+001,2.974992e-006,4.459670e-008,0.000000e+000,0.000000e+000,2,8.396011e-001,1.825000e+000,,,,,,,,,,,,,,,,,,0,3.000000e+000,1.000000e+000,10,5,1.449585e-003,0,,0,
1616459665.360,,-1.000000e+003,3.000099e+001,3.857616e-006,4.027154e-008,0.000000e+000,0.000000e+000,2,8.731669e-001,1.825000e+000,,,,,,,,,,,,,,,,,,0,3.000000e+000,1.000000e+000,10,5,0.000000e+000,0,,0,
1616459877.468,,-1.500000e+003,2.999983e+001,6.279619e-006,2.199043e-008,0.000000e+000,0.000000e+000,2,8.849134e-001,1.825000e+000,,,,,,,,,,,,,,,,,,0,3.000000e+000,1.000000e+000,10,5,2.899170e-003,0,,0,
1616460098.216,,-2.000000e+003,3.000128e+001,8.755842e-006,1.225453e-008,0.000000e+000,0.000000e+000,2,8.938464e-001,1.825000e+000,,,,,,,,,,,,,,,,,,0,3.000000e+000,1.000000e+000,10,5,1.440048e-003,0,,0,
1616460342.955,,-2.500000e+003,3.000027e+001,1.121994e-005,2.617311e-008,0.000000e+000,0.000000e+000,2,8.961801e-001,1.825000e+000,,,,,,,,,,,,,,,,,,0,3.000000e+000,1.000000e+000,10,5,2.889633e-003,0,,0,
1616460532.593,,-3.000000e+003,3.000055e+001,1.361829e-005,1.079207e-007,0.000000e+000,0.000000e+000,2,8.895634e-001,1.825000e+000,,,,,,,,,,,,,,,,,,0,3.000000e+000,1.000000e+000,10,5,2.889633e-003,0,,0,
1616460730.072,,-3.500000e+003,3.000012e+001,1.615267e-005,3.914943e-008,0.000000e+000,0.000000e+000,2,9.005724e-001,1.825000e+000,,,,,,,,,,,,,,,,,,0,3.000000e+000,1.000000e+000,10,5,1.449585e-003,0,,0,
1616460925.660,,-4.000000e+003,3.000041e+001,1.862787e-005,3.423580e-008,0.000000e+000,0.000000e+000,2,9.007002e-001,1.825000e+000,,,,,,,,,,,,,,,,,,0,3.000000e+000,1.000000e+000,10,5,1.449585e-003,0,,0,
1616461118.858,,-5.000000e+003,3.000099e+001,2.356883e-005,2.845889e-008,0.000000e+000,0.000000e+000,2,9.013599e-001,1.825000e+000,,,,,,,,,,,,,,,,,,0,3.000000e+000,1.000000e+000,10,5,4.339218e-003,0,,0,
1616461318.487,,-6.000000e+003,3.000012e+001,2.853944e-005,5.276267e-008,0.000000e+000,0.000000e+000,2,9.006507e-001,1.825000e+000,,,,,,,,,,,,,,,,,,0,3.000000e+000,1.000000e+000,10,5,2.899170e-003,0,,0,
1616461517.625,,-7.000000e+003,3.000099e+001,3.351051e-005,2.030009e-008,0.000000e+000,0.000000e+000,2,9.003384e-001,1.825000e+000,,,,,,,,,,,,,,,,,,0,3.000000e+000,1.000000e+000,10,5,2.889633e-003,0,,0,
1616461706.284,,-8.000000e+003,3.000084e+001,3.847106e-005,3.183085e-008,0.000000e+000,0.000000e+000,2,9.001166e-001,1.825000e+000,,,,,,,,,,,,,,,,,,0,3.000000e+000,1.000000e+000,10,5,4.339218e-003,0,,0,
1616461887.683,,-9.000000e+003,3.000084e+001,4.345986e-005,4.162528e-008,0.000000e+000,0.000000e+000,2,9.000403e-001,1.825000e+000,,,,,,,,,,,,,,,,,,0,3.000000e+000,1.000000e+000,10,5,4.339218e-003,0,,0,
1616462074.482,,-1.000000e+004,3.000070e+001,4.842778e-005,3.001366e-008,0.000000e+000,0.000000e+000,2,8.999613e-001,1.825000e+000,,,,,,,,,,,,,,,,,,0,3.000000e+000,1.000000e+000,10,5,2.889633e-003,0,,0,
1616462268.071,,-1.200000e+004,3.000056e+001,5.844364e-005,2.475953e-008,0.000000e+000,0.000000e+000,2,8.991805e-001,1.825000e+000,,,,,,,,,,,,,,,,,,0,3.000000e+000,1.000000e+000,10,5,2.889633e-003,0,,0,
1616462455.569,,-1.400000e+004,3.000012e+001,6.840899e-005,2.216797e-008,0.000000e+000,0.000000e+000,2,8.989837e-001,1.825000e+000,,,,,,,,,,,,,,,,,,0,3.000000e+000,1.000000e+000,10,5,4.339218e-003,0,,0,
1616462650.148,,-1.600000e+004,3.000070e+001,7.842021e-005,5.376349e-008,0.000000e+000,0.000000e+000,2,8.985829e-001,1.825000e+000,,,,,,,,,,,,,,,,,,0,3.000000e+000,1.000000e+000,10,5,2.889633e-003,0,,0,
1616462844.987,,-1.800000e+004,3.000099e+001,8.838807e-005,5.360183e-008,0.000000e+000,0.000000e+000,2,8.980480e-001,1.825000e+000,,,,,,,,,,,,,,,,,,0,3.000000e+000,1.000000e+000,10,5,2.889633e-003,0,,0,
1616463034.246,,-2.000000e+004,3.000056e+001,9.835843e-005,5.809726e-008,0.000000e+000,0.000000e+000,2,8.979605e-001,1.825000e+000,,,,,,,,,,,,,,,,,,0,3.000000e+000,1.000000e+000,10,5,2.889633e-003,0,,0,
1616463241.705,,-2.500000e+004,3.000084e+001,1.234306e-004,7.965697e-008,0.000000e+000,0.000000e+000,2,8.974029e-001,1.825000e+000,,,,,,,,,,,,,,,,,,0,3.000000e+000,1.000000e+000,10,5,1.449585e-003,0,,0,
1616463450.654,,-3.000000e+004,3.000041e+001,1.484576e-004,1.523601e-007,0.000000e+000,0.000000e+000,2,8.972520e-001,1.825000e+000,,,,,,,,,,,,,,,,,,0,3.000000e+000,1.000000e+000,10,5,4.339218e-003,0,,0,
1616463687.512,,-3.500000e+004,2.999954e+001,1.735625e-004,1.206778e-007,0.000000e+000,0.000000e+000,2,8.971162e-001,1.825000e+000,,,,,,,,,,,,,,,,,,0,3.000000e+000,1.000000e+000,10,5,2.899170e-003,0,,0,
1616463892.001,,-4.000000e+004,3.000099e+001,1.986520e-004,1.749655e-007,0.000000e+000,0.000000e+000,2,8.969853e-001,1.825000e+000,,,,,,,,,,,,,,,,,,0,3.000000e+000,1.000000e+000,10,5,0.000000e+000,0,,0,
1616464096.680,,-4.500000e+004,3.000084e+001,2.236969e-004,2.515048e-007,0.000000e+000,0.000000e+000,2,8.970601e-001,1.825000e+000,,,,,,,,,,,,,,,,,,0,3.000000e+000,1.000000e+000,10,5,2.889633e-003,0,,0,
1616464305.088,,-5.000000e+004,3.000142e+001,2.486935e-004,1.051811e-007,0.000000e+000,0.000000e+000,2,8.968567e-001,1.825000e+000,,,,,,,,,,,,,,,,,,0,3.000000e+000,1.000000e+000,10,5,4.339218e-003,0,,0,
1616464515.707,,-4.500000e+004,3.000070e+001,2.237515e-004,2.698650e-008,0.000000e+000,0.000000e+000,2,8.968968e-001,1.825000e+000,,,,,,,,,,,,,,,,,,0,3.000000e+000,1.000000e+000,10,5,4.339218e-003,0,,0,
1616464726.646,,-4.000000e+004,3.000084e+001,1.985559e-004,1.350409e-007,0.000000e+000,0.000000e+000,2,8.970959e-001,1.825000e+000,,,,,,,,,,,,,,,,,,0,3.000000e+000,1.000000e+000,10,5,2.889633e-003,0,,0,
1616464942.625,,-3.500000e+004,3.000027e+001,1.734921e-004,1.941911e-007,0.000000e+000,0.000000e+000,2,8.967957e-001,1.825000e+000,,,,,,,,,,,,,,,,,,0,3.000000e+000,1.000000e+000,10,5,2.899170e-003,0,,0,
1616465151.604,,-3.000000e+004,3.000055e+001,1.483895e-004,1.128019e-007,0.000000e+000,0.000000e+000,2,8.969153e-001,1.825000e+000,,,,,,,,,,,,,,,,,,0,3.000000e+000,1.000000e+000,10,5,2.889633e-003,0,,0,
1616465360.213,,-2.500000e+004,3.000012e+001,1.233229e-004,7.396100e-008,0.000000e+000,0.000000e+000,2,8.972396e-001,1.825000e+000,,,,,,,,,,,,,,,,,,0,3.000000e+000,1.000000e+000,10,5,2.889633e-003,0,,0,
1616465560.262,,-2.000000e+004,3.000128e+001,9.828680e-005,5.314557e-008,0.000000e+000,0.000000e+000,2,8.972940e-001,1.825000e+000,,,,,,,,,,,,,,,,,,0,3.000000e+000,1.000000e+000,10,5,4.339218e-003,0,,0,
1616465754.142,,-1.800000e+004,3.000055e+001,8.833913e-005,7.986741e-008,0.000000e+000,0.000000e+000,2,8.983020e-001,1.825000e+000,,,,,,,,,,,,,,,,,,0,3.000000e+000,1.000000e+000,10,5,4.339218e-003,0,,0,
1616465948.271,,-1.600000e+004,3.000056e+001,7.831239e-005,4.272753e-008,0.000000e+000,0.000000e+000,2,8.982308e-001,1.825000e+000,,,,,,,,,,,,,,,,,,0,3.000000e+000,1.000000e+000,10,5,2.889633e-003,0,,0,
1616466139.600,,-1.400000e+004,3.000055e+001,6.830233e-005,4.110451e-008,0.000000e+000,0.000000e+000,2,8.991386e-001,1.825000e+000,,,,,,,,,,,,,,,,,,0,3.000000e+000,1.000000e+000,10,5,2.889633e-003,0,,0,
1616466326.249,,-1.200000e+004,3.000084e+001,5.832597e-005,1.207315e-008,0.000000e+000,0.000000e+000,2,8.992389e-001,1.825000e+000,,,,,,,,,,,,,,,,,,0,3.000000e+000,1.000000e+000,10,5,4.339218e-003,0,,0,
1616466516.328,,-1.000000e+004,3.000099e+001,4.836313e-005,4.023365e-008,0.000000e+000,0.000000e+000,2,8.995122e-001,1.825000e+000,,,,,,,,,,,,,,,,,,0,3.000000e+000,1.000000e+000,10,5,4.339218e-003,0,,0,
1616466714.317,,-9.000000e+003,2.999983e+001,4.336083e-005,3.270886e-008,0.000000e+000,0.000000e+000,2,9.000664e-001,1.825000e+000,,,,,,,,,,,,,,,,,,0,3.000000e+000,1.000000e+000,10,5,1.449585e-003,0,,0,
1616466944.596,,-8.000000e+003,3.000026e+001,3.835721e-005,2.683961e-008,0.000000e+000,0.000000e+000,2,9.003531e-001,1.825000e+000,,,,,,,,,,,,,,,,,,0,3.000000e+000,1.000000e+000,10,5,4.339218e-003,0,,0,
1616467143.955,,-7.000000e+003,3.000099e+001,3.338134e-005,4.007908e-008,0.000000e+000,0.000000e+000,2,9.005855e-001,1.825000e+000,,,,,,,,,,,,,,,,,,0,3.000000e+000,1.000000e+000,10,5,2.889633e-003,0,,0,
1616467337.504,,-6.000000e+003,3.000070e+001,2.842671e-005,2.053532e-008,0.000000e+000,0.000000e+000,2,9.013781e-001,1.825000e+000,,,,,,,,,,,,,,,,,,0,3.000000e+000,1.000000e+000,10,5,1.449585e-003,0,,0,
1616467536.573,,-5.000000e+003,3.000041e+001,2.344671e-005,2.419369e-008,0.000000e+000,0.000000e+000,2,9.011245e-001,1.825000e+000,,,,,,,,,,,,,,,,,,0,3.000000e+000,1.000000e+000,10,5,2.889633e-003,0,,0,
1616467735.872,,-4.000000e+003,3.000012e+001,1.850553e-005,1.761241e-008,0.000000e+000,0.000000e+000,2,9.012650e-001,1.825000e+000,,,,,,,,,,,,,,,,,,0,3.000000e+000,1.000000e+000,10,5,1.449585e-003,0,,0,
1616468006.931,,-3.500000e+003,3.000056e+001,1.601393e-005,2.418539e-008,0.000000e+000,0.000000e+000,2,8.993829e-001,1.825000e+000,,,,,,,,,,,,,,,,,,0,3.000000e+000,1.000000e+000,10,5,4.339218e-003,0,,0,
1616468239.700,,-3.000000e+003,2.999998e+001,1.353814e-005,2.704501e-008,0.000000e+000,0.000000e+000,2,8.968301e-001,1.825000e+000,,,,,,,,,,,,,,,,,,0,3.000000e+000,1.000000e+000,10,5,2.899170e-003,0,,0,
1616468489.198,,-2.500000e+003,2.999998e+001,1.108905e-005,2.756686e-008,0.000000e+000,0.000000e+000,2,8.958511e-001,1.825000e+000,,,,,,,,,,,,,,,,,,0,3.000000e+000,1.000000e+000,10,5,5.790710e-003,0,,0,
1616468703.017,,-2.000000e+003,2.999983e+001,8.618757e-006,1.388464e-008,0.000000e+000,0.000000e+000,2,8.934057e-001,1.825000e+000,,,,,,,,,,,,,,,,,,0,3.000000e+000,1.000000e+000,10,5,2.899170e-003,0,,0,
1616468898.946,,-1.500000e+003,3.000099e+001,6.177582e-006,5.909891e-008,0.000000e+000,0.000000e+000,2,8.720868e-001,1.825000e+000,,,,,,,,,,,,,,,,,,0,3.000000e+000,1.000000e+000,10,5,2.889633e-003,0,,0,
1616469093.246,,-1.000000e+003,3.000041e+001,3.821664e-006,4.681553e-008,0.000000e+000,0.000000e+000,2,8.444098e-001,1.825000e+000,,,,,,,,,,,,,,,,,,0,3.000000e+000,1.000000e+000,10,5,1.449585e-003,0,,0,
1616469282.045,,-8.000000e+002,3.000056e+001,2.860564e-006,6.833196e-008,0.000000e+000,0.000000e+000,2,8.185778e-001,1.825000e+000,,,,,,,,,,,,,,,,,,0,3.000000e+000,1.000000e+000,10,5,2.889633e-003,0,,0,
1616469470.564,,-6.000000e+002,3.000055e+001,1.983159e-006,5.955960e-008,0.000000e+000,0.000000e+000,2,7.858197e-001,1.825000e+000,,,,,,,,,,,,,,,,,,0,3.000000e+000,1.000000e+000,10,5,2.889633e-003,0,,0,
1616469659.563,,-4.000000e+002,3.000099e+001,1.150991e-006,7.016936e-008,0.000000e+000,0.000000e+000,2,6.849965e-001,1.825000e+000,,,,,,,,,,,,,,,,,,0,3.000000e+000,1.000000e+000,10,5,2.889633e-003,0,,0,
1616469848.752,,-2.000000e+002,3.000012e+001,3.429835e-007,3.533718e-008,0.000000e+000,0.000000e+000,2,1.449554e-001,1.825000e+000,,,,,,,,,,,,,,,,,,0,3.000000e+000,1.000000e+000,10,5,1.449585e-003,0,,0,
1616470042.851,,0.000000e+000,3.000027e+001,-2.828060e-007,7.253954e-008,0.000000e+000,0.000000e+000,2,3.651980e-001,1.825000e+000,,,,,,,,,,,,,,,,,,0,3.000000e+000,1.000000e+000,10,5,1.449585e-003,0,,0,
1616470231.570,,2.000000e+002,2.999983e+001,-6.325975e-007,1.280995e-008,0.000000e+000,0.000000e+000,2,7.099817e-001,1.825000e+000,,,,,,,,,,,,,,,,,,0,3.000000e+000,1.000000e+000,10,5,2.899170e-003,0,,0,
1616470426.210,,4.000000e+002,3.000070e+001,-1.300218e-006,7.588832e-008,0.000000e+000,0.000000e+000,2,8.499557e-001,1.825000e+000,,,,,,,,,,,,,,,,,,0,3.000000e+000,1.000000e+000,10,5,2.889633e-003,0,,0,
1616470614.359,,6.000000e+002,3.000142e+001,-2.047841e-006,5.923312e-008,0.000000e+000,0.000000e+000,2,8.921831e-001,1.825000e+000,,,,,,,,,,,,,,,,,,0,3.000000e+000,1.000000e+000,10,5,5.788803e-003,0,,0,
1616470802.148,,8.000000e+002,3.000055e+001,-2.872317e-006,3.043275e-008,0.000000e+000,0.000000e+000,2,8.709052e-001,1.825000e+000,,,,,,,,,,,,,,,,,,0,3.000000e+000,1.000000e+000,10,5,4.339218e-003,0,,0,
1616470990.007,,1.000000e+003,3.000056e+001,-3.806504e-006,4.821374e-008,0.000000e+000,0.000000e+000,2,8.809427e-001,1.825000e+000,,,,,,,,,,,,,,,,,,0,3.000000e+000,1.000000e+000,10,5,2.889633e-003,0,,0,
1616471201.856,,1.500000e+003,3.000099e+001,-6.253581e-006,1.263330e-008,0.000000e+000,0.000000e+000,2,8.985736e-001,1.825000e+000,,,,,,,,,,,,,,,,,,0,3.000000e+000,1.000000e+000,10,5,2.889633e-003,0,,0,
1616471438.435,,2.000000e+003,3.000099e+001,-8.697329e-006,4.640226e-008,0.000000e+000,0.000000e+000,2,9.060975e-001,1.825000e+000,,,,,,,,,,,,,,,,,,0,3.000000e+000,1.000000e+000,10,5,2.889633e-003,0,,0,
1616471629.664,,2.500000e+003,3.000056e+001,-1.111507e-005,2.947693e-008,0.000000e+000,0.000000e+000,2,9.100558e-001,1.825000e+000,,,,,,,,,,,,,,,,,,0,3.000000e+000,1.000000e+000,10,5,1.449585e-003,0,,0,
1616471819.143,,3.000000e+003,3.000055e+001,-1.359693e-005,3.269614e-008,0.000000e+000,0.000000e+000,2,9.138930e-001,1.825000e+000,,,,,,,,,,,,,,,,,,0,3.000000e+000,1.000000e+000,10,5,4.339218e-003,0,,0,
1616472014.723,,3.500000e+003,2.999983e+001,-1.607372e-005,6.776201e-008,0.000000e+000,0.000000e+000,2,9.126716e-001,1.825000e+000,,,,,,,,,,,,,,,,,,0,3.000000e+000,1.000000e+000,10,5,2.899170e-003,0,,0,
1616472213.072,,4.000000e+003,3.000055e+001,-1.853462e-005,3.378039e-008,0.000000e+000,0.000000e+000,2,9.137634e-001,1.825000e+000,,,,,,,,,,,,,,,,,,0,3.000000e+000,1.000000e+000,10,5,4.339218e-003,0,,0,
1616472406.811,,5.000000e+003,3.000055e+001,-2.343802e-005,4.261609e-008,0.000000e+000,0.000000e+000,2,9.152717e-001,1.825000e+000,,,,,,,,,,,,,,,,,,0,3.000000e+000,1.000000e+000,10,5,4.339218e-003,0,,0,
1616472606.400,,6.000000e+003,3.000070e+001,-2.837403e-005,3.177022e-008,0.000000e+000,0.000000e+000,2,9.135652e-001,1.825000e+000,,,,,,,,,,,,,,,,,,0,3.000000e+000,1.000000e+000,10,5,2.889633e-003,0,,0,
1616472799.519,,7.000000e+003,3.000099e+001,-3.334119e-005,1.836038e-008,0.000000e+000,0.000000e+000,2,9.130072e-001,1.825000e+000,,,,,,,,,,,,,,,,,,0,3.000000e+000,1.000000e+000,10,5,2.889633e-003,0,,0,
1616472986.529,,8.000000e+003,3.000041e+001,-3.827491e-005,3.800761e-008,0.000000e+000,0.000000e+000,2,9.113830e-001,1.825000e+000,,,,,,,,,,,,,,,,,,0,3.000000e+000,1.000000e+000,10,5,1.449585e-003,0,,0,
1616473172.808,,9.000000e+003,3.000055e+001,-4.326927e-005,5.434875e-008,0.000000e+000,0.000000e+000,2,9.097176e-001,1.825000e+000,,,,,,,,,,,,,,,,,,0,3.000000e+000,1.000000e+000,10,5,2.889633e-003,0,,0,
1616473361.487,,1.000000e+004,2.999983e+001,-4.823005e-005,4.913218e-008,0.000000e+000,0.000000e+000,2,9.083709e-001,1.825000e+000,,,,,,,,,,,,,,,,,,0,3.000000e+000,1.000000e+000,10,5,2.899170e-003,0,,0,
1616473546.526,,1.200000e+004,3.000012e+001,-5.825591e-005,2.137557e-008,0.000000e+000,0.000000e+000,2,9.065181e-001,1.825000e+000,,,,,,,,,,,,,,,,,,0,3.000000e+000,1.000000e+000,10,5,4.339218e-003,0,,0,
1616473739.576,,1.400000e+004,3.000027e+001,-6.823090e-005,1.757776e-008,0.000000e+000,0.000000e+000,2,9.048955e-001,1.825000e+000,,,,,,,,,,,,,,,,,,0,3.000000e+000,1.000000e+000,10,5,4.339218e-003,0,,0,
1616473933.635,,1.600000e+004,3.000012e+001,-7.815970e-005,2.936803e-008,0.000000e+000,0.000000e+000,2,9.040357e-001,1.825000e+000,,,,,,,,,,,,,,,,,,0,3.000000e+000,1.000000e+000,10,5,4.339218e-003,0,,0,
1616474127.744,,1.800000e+004,3.000070e+001,-8.820847e-005,5.142304e-008,0.000000e+000,0.000000e+000,2,9.030634e-001,1.825000e+000,,,,,,,,,,,,,,,,,,0,3.000000e+000,1.000000e+000,10,5,2.889633e-003,0,,0,
1616474321.703,,2.000000e+004,3.000113e+001,-9.822544e-005,8.361863e-008,0.000000e+000,0.000000e+000,2,9.023510e-001,1.825000e+000,,,,,,,,,,,,,,,,,,0,3.000000e+000,1.000000e+000,10,5,4.339218e-003,0,,0,
1616474530.753,,2.500000e+004,3.000113e+001,-1.232240e-004,1.151789e-007,0.000000e+000,0.000000e+000,2,9.011880e-001,1.825000e+000,,,,,,,,,,,,,,,,,,0,3.000000e+000,1.000000e+000,10,5,2.889633e-003,0,,0,
1616474739.942,,3.000000e+004,3.000070e+001,-1.483009e-004,9.476960e-008,0.000000e+000,0.000000e+000,2,9.000673e-001,1.825000e+000,,,,,,,,,,,,,,,,,,0,3.000000e+000,1.000000e+000,10,5,2.889633e-003,0,,0,
1616474949.901,,3.500000e+004,3.000113e+001,-1.733770e-004,1.887847e-007,0.000000e+000,0.000000e+000,2,8.996095e-001,1.825000e+000,,,,,,,,,,,,,,,,,,0,3.000000e+000,1.000000e+000,10,5,2.889633e-003,0,,0,
1616475154.151,,4.000000e+004,3.000142e+001,-1.983836e-004,1.781222e-007,0.000000e+000,0.000000e+000,2,8.990972e-001,1.825000e+000,,,,,,,,,,,,,,,,,,0,3.000000e+000,1.000000e+000,10,5,2.889633e-003,0,,0,
1616475358.720,,4.500000e+004,3.000157e+001,-2.236029e-004,2.137835e-007,0.000000e+000,0.000000e+000,2,8.992291e-001,1.825000e+000,,,,,,,,,,,,,,,,,,0,3.000000e+000,1.000000e+000,10,5,2.889633e-003,0,,0,
1616475566.339,,5.000000e+004,3.000041e+001,-2.485259e-004,1.226037e-007,0.000000e+000,0.000000e+000,2,8.988305e-001,1.825000e+000,,,,,,,,,,,,,,,,,,0,3.000000e+000,1.000000e+000,10,5,5.788803e-003,0,,0,