File: SiC2/Hyst at 30K/SiC2_hyst_30K.rso.dat.csv
[Header]
TITLE,MPMS RSO Measurement
BYAPP,MPMS Measurement,1.1,Summary
FILEOPENTIME, 1616192857.810000 3/19/2021, 11:27:37 PM

INFO, APPNAME, MPMS MultiVu Application, Revision 1.61,  Build 082

INFO, NAME,
INFO, WEIGHT, 1.000
INFO, AREA, 1.000
INFO, LENGTH, 1.000
INFO, SHAPE, 0
INFO, COMMENT,
INFO, SEQUENCE FILE: H5T_Lin_NoO.seq


INFO, BACKGROUND DATA FILE:, None


STARTUPAXIS,X,4,LINEAR,AUTO,0.000000,0.000000
STARTUPAXIS,Y1,5,LINEAR,AUTO,0.000000,0.000000


STARTUPGROUP,Longitudinal
FIELDGROUP,Longitudinal,1,2,3,4,5,6,7,8,9,10,11,19,20,21,22,23,35
FIELDGROUP,Transverse,1,2,3,4,12,13,14,15,16,17,18,24,25,26,27,28,35

PLOT_APPEARANCE,ALL,HORZ_GRID_ON,VERT_GRID_ON,MARKERS_AND_LINES

[Data]
Time,Comment,Field (Oe),Temperature (K),Long Moment (emu),Long Scan Std Dev,Long Offset (cm),Long Offset Std Dev,Long Algorithm,Long Reg Fit,Long Reg Factor,Trans Moment (emu),Trans Scan Std Dev,Trans Offset (cm),Trans Offset Std Dev,Trans Algorithm,Trans Reg Fit,Trans Reg Factor,Long Moment [w/o ABS] (emu),Long Scan Std Dev [w/o ABS],Long Offset [w/o ABS] (cm),Long Offset Std Dev [w/o ABS],Long Reg Fit [w/o ABS],Trans Moment [w/o ABS] (emu),Trans Scan Std Dev [w/o ABS],Trans Offset [w/o ABS] (cm),Trans Offset Std Dev [w/o ABS],Trans Reg Fit [w/o ABS],RSO Position (deg),Amplitude (cm),Frequency,Cycles to Average,Scans per Measurement,Delta Temp (K),Error,EC Comp. Running,Using ABS,
1616192857.810,,0.000000e+000,3.000099e+001,-1.661691e-008,2.528882e-009,0.000000e+000,0.000000e+000,2,0.000000e+000,1.825000e+000,,,,,,,,,,,,,,,,,,0,3.000000e+000,1.000000e+000,10,5,2.889633e-003,0,,0,
1616193073.687,,2.000000e+002,3.000084e+001,-4.528221e-007,4.436032e-009,0.000000e+000,0.000000e+000,2,8.644943e-001,1.825000e+000,,,,,,,,,,,,,,,,,,0,3.000000e+000,1.000000e+000,10,5,2.889633e-003,0,,0,
1616193266.433,,4.000000e+002,3.000113e+001,-8.427027e-007,6.852671e-009,0.000000e+000,0.000000e+000,2,8.712934e-001,1.825000e+000,,,,,,,,,,,,,,,,,,0,3.000000e+000,1.000000e+000,10,5,2.889633e-003,0,,0,
1616193454.435,,6.000000e+002,3.000157e+001,-1.342036e-006,1.054433e-008,0.000000e+000,0.000000e+000,2,8.784742e-001,1.825000e+000,,,,,,,,,,,,,,,,,,0,3.000000e+000,1.000000e+000,10,5,1.440048e-003,0,,0,
1616193641.527,,8.000000e+002,3.000027e+001,-1.908180e-006,1.018619e-008,0.000000e+000,0.000000e+000,2,8.833496e-001,1.825000e+000,,,,,,,,,,,,,,,,,,0,3.000000e+000,1.000000e+000,10,5,4.350662e-003,0,,0,
1616193828.727,,1.000000e+003,3.000056e+001,-2.543031e-006,5.450733e-009,0.000000e+000,0.000000e+000,2,8.901863e-001,1.825000e+000,,,,,,,,,,,,,,,,,,0,3.000000e+000,1.000000e+000,10,5,4.339218e-003,0,,0,
1616194048.411,,1.500000e+003,3.000142e+001,-4.302949e-006,5.091394e-009,0.000000e+000,0.000000e+000,2,8.964555e-001,1.825000e+000,,,,,,,,,,,,,,,,,,0,3.000000e+000,1.000000e+000,10,5,2.889633e-003,0,,0,
1616194252.157,,2.000000e+003,3.000128e+001,-6.166341e-006,1.672819e-008,0.000000e+000,0.000000e+000,2,8.986310e-001,1.825000e+000,,,,,,,,,,,,,,,,,,0,3.000000e+000,1.000000e+000,10,5,2.889633e-003,0,,0,
1616194447.960,,2.500000e+003,3.000027e+001,-8.119215e-006,4.201932e-008,0.000000e+000,0.000000e+000,2,9.006582e-001,1.825000e+000,,,,,,,,,,,,,,,,,,0,3.000000e+000,1.000000e+000,10,5,1.449585e-003,0,,0,
1616194645.157,,3.000000e+003,3.000084e+001,-1.007711e-005,4.011293e-008,0.000000e+000,0.000000e+000,2,9.044167e-001,1.825000e+000,,,,,,,,,,,,,,,,,,0,3.000000e+000,1.000000e+000,10,5,2.889633e-003,0,,0,
1616194840.822,,3.500000e+003,3.000099e+001,-1.212764e-005,6.977864e-008,0.000000e+000,0.000000e+000,2,9.043110e-001,1.825000e+000,,,,,,,,,,,,,,,,,,0,3.000000e+000,1.000000e+000,10,5,2.889633e-003,0,,0,
1616195032.177,,4.000000e+003,3.000099e+001,-1.391988e-005,4.301333e-008,0.000000e+000,0.000000e+000,2,9.017804e-001,1.825000e+000,,,,,,,,,,,,,,,,,,0,3.000000e+000,1.000000e+000,10,5,2.889633e-003,0,,0,
1616195223.855,,5.000000e+003,3.000099e+001,-1.800262e-005,6.688219e-008,0.000000e+000,0.000000e+000,2,9.022919e-001,1.825000e+000,,,,,,,,,,,,,,,,,,0,3.000000e+000,1.000000e+000,10,5,0.000000e+000,0,,0,
1616195423.039,,6.000000e+003,3.000084e+001,-2.212155e-005,1.652953e-008,0.000000e+000,0.000000e+000,2,9.048802e-001,1.825000e+000,,,,,,,,,,,,,,,,,,0,3.000000e+000,1.000000e+000,10,5,2.889633e-003,0,,0,
1616195622.555,,7.000000e+003,3.000099e+001,-2.621847e-005,4.594349e-008,0.000000e+000,0.000000e+000,2,9.064867e-001,1.825000e+000,,,,,,,,,,,,,,,,,,0,3.000000e+000,1.000000e+000,10,5,2.889633e-003,0,,0,
1616195811.349,,8.000000e+003,3.000099e+001,-3.031009e-005,5.837493e-008,0.000000e+000,0.000000e+000,2,9.068862e-001,1.825000e+000,,,,,,,,,,,,,,,,,,0,3.000000e+000,1.000000e+000,10,5,2.889633e-003,0,,0,
1616195991.744,,9.000000e+003,3.000041e+001,-3.444115e-005,4.042073e-008,0.000000e+000,0.000000e+000,2,9.068877e-001,1.825000e+000,,,,,,,,,,,,,,,,,,0,3.000000e+000,1.000000e+000,10,5,2.889633e-003,0,,0,
1616196179.360,,1.000000e+004,3.000070e+001,-3.864312e-005,3.080346e-008,0.000000e+000,0.000000e+000,2,9.074184e-001,1.825000e+000,,,,,,,,,,,,,,,,,,0,3.000000e+000,1.000000e+000,10,5,2.889633e-003,0,,0,
1616196388.893,,1.200000e+004,3.000128e+001,-4.702481e-005,6.317158e-008,0.000000e+000,0.000000e+000,2,9.079858e-001,1.825000e+000,,,,,,,,,,,,,,,,,,0,3.000000e+000,1.000000e+000,10,5,2.889633e-003,0,,0,
1616196581.910,,1.400000e+004,2.999997e+001,-5.529018e-005,5.284915e-008,0.000000e+000,0.000000e+000,2,9.084657e-001,1.825000e+000,,,,,,,,,,,,,,,,,,0,3.000000e+000,1.000000e+000,10,5,5.790710e-003,0,,0,
1616196774.289,,1.600000e+004,3.000186e+001,-6.374592e-005,6.616570e-008,0.000000e+000,0.000000e+000,2,9.096158e-001,1.825000e+000,,,,,,,,,,,,,,,,,,0,3.000000e+000,1.000000e+000,10,5,2.889633e-003,0,,0,
1616196967.500,,1.800000e+004,3.000084e+001,-7.207687e-005,1.100663e-007,0.000000e+000,0.000000e+000,2,9.087402e-001,1.825000e+000,,,,,,,,,,,,,,,,,,0,3.000000e+000,1.000000e+000,10,5,2.889633e-003,0,,0,
1616197189.220,,2.000000e+004,3.000128e+001,-8.046122e-005,7.261856e-008,0.000000e+000,0.000000e+000,2,9.092453e-001,1.825000e+000,,,,,,,,,,,,,,,,,,0,3.000000e+000,1.000000e+000,10,5,4.339218e-003,0,,0,
1616197396.501,,2.500000e+004,3.000026e+001,-1.014309e-004,2.039052e-007,0.000000e+000,0.000000e+000,2,9.095820e-001,1.825000e+000,,,,,,,,,,,,,,,,,,0,3.000000e+000,1.000000e+000,10,5,4.339218e-003,0,,0,
1616197605.619,,3.000000e+004,3.000113e+001,-1.224551e-004,1.110845e-007,0.000000e+000,0.000000e+000,2,9.097044e-001,1.825000e+000,,,,,,,,,,,,,,,,,,0,3.000000e+000,1.000000e+000,10,5,2.889633e-003,0,,0,
1616197815.381,,3.500000e+004,3.000128e+001,-1.435055e-004,8.888260e-008,0.000000e+000,0.000000e+000,2,9.100158e-001,1.825000e+000,,,,,,,,,,,,,,,,,,0,3.000000e+000,1.000000e+000,10,5,2.889633e-003,0,,0,
1616198025.939,,4.000000e+004,3.000099e+001,-1.644404e-004,1.219785e-007,0.000000e+000,0.000000e+000,2,9.102015e-001,1.825000e+000,,,,,,,,,,,,,,,,,,0,3.000000e+000,1.000000e+000,10,5,2.889633e-003,0,,0,
1616198231.450,,4.500000e+004,3.000171e+001,-1.855983e-004,1.966978e-007,0.000000e+000,0.000000e+000,2,9.100209e-001,1.825000e+000,,,,,,,,,,,,,,,,,,0,3.000000e+000,1.000000e+000,10,5,2.889633e-003,0,,0,
1616198444.644,,5.000000e+004,3.000200e+001,-2.079821e-004,8.483048e-007,0.000000e+000,0.000000e+000,2,9.115325e-001,1.825000e+000,,,,,,,,,,,,,,,,,,0,3.000000e+000,1.000000e+000,10,5,1.440048e-003,0,,0,
1616198669.509,,4.500000e+004,3.000041e+001,-1.874404e-004,2.055800e-007,0.000000e+000,0.000000e+000,2,9.114262e-001,1.825000e+000,,,,,,,,,,,,,,,,,,0,3.000000e+000,1.000000e+000,10,5,4.339218e-003,0,,0,
1616198878.939,,4.000000e+004,3.000157e+001,-1.664250e-004,2.125196e-007,0.000000e+000,0.000000e+000,2,9.108333e-001,1.825000e+000,,,,,,,,,,,,,,,,,,0,3.000000e+000,1.000000e+000,10,5,1.440048e-003,0,,0,
1616199088.809,,3.500000e+004,3.000171e+001,-1.452490e-004,2.355566e-007,0.000000e+000,0.000000e+000,2,9.107659e-001,1.825000e+000,,,,,,,,,,,,,,,,,,0,3.000000e+000,1.000000e+000,10,5,1.440048e-003,0,,0,
1616199297.716,,3.000000e+004,3.000185e+001,-1.243058e-004,1.891577e-007,0.000000e+000,0.000000e+000,2,9.103968e-001,1.825000e+000,,,,,,,,,,,,,,,,,,0,3.000000e+000,1.000000e+000,10,5,4.339218e-003,0,,0,
1616199505.388,,2.500000e+004,3.000099e+001,-1.032486e-004,1.010810e-007,0.000000e+000,0.000000e+000,2,9.101921e-001,1.825000e+000,,,,,,,,,,,,,,,,,,0,3.000000e+000,1.000000e+000,10,5,0.000000e+000,0,,0,
1616199710.870,,2.000000e+004,3.000142e+001,-8.385764e-005,3.464326e-006,0.000000e+000,0.000000e+000,2,8.957700e-001,1.825000e+000,,,,,,,,,,,,,,,,,,0,3.000000e+000,1.000000e+000,10,5,2.889633e-003,0,,0,
1616199896.286,,1.800000e+004,3.000041e+001,-7.397901e-005,9.723988e-008,0.000000e+000,0.000000e+000,2,9.108943e-001,1.825000e+000,,,,,,,,,,,,,,,,,,0,3.000000e+000,1.000000e+000,10,5,2.889633e-003,0,,0,
1616200095.599,,1.600000e+004,3.000084e+001,-6.558053e-005,7.431340e-008,0.000000e+000,0.000000e+000,2,9.098203e-001,1.825000e+000,,,,,,,,,,,,,,,,,,0,3.000000e+000,1.000000e+000,10,5,2.889633e-003,0,,0,
1616200288.959,,1.400000e+004,3.000099e+001,-5.721348e-005,4.484204e-008,0.000000e+000,0.000000e+000,2,9.101380e-001,1.825000e+000,,,,,,,,,,,,,,,,,,0,3.000000e+000,1.000000e+000,10,5,0.000000e+000,0,,0,
1616200479.817,,1.200000e+004,3.000099e+001,-4.883247e-005,4.216175e-008,0.000000e+000,0.000000e+000,2,9.098042e-001,1.825000e+000,,,,,,,,,,,,,,,,,,0,3.000000e+000,1.000000e+000,10,5,0.000000e+000,0,,0,
1616200672.769,,1.000000e+004,3.000113e+001,-4.151243e-005,2.376252e-006,0.000000e+000,0.000000e+000,2,8.881459e-001,1.825000e+000,,,,,,,,,,,,,,,,,,0,3.000000e+000,1.000000e+000,10,5,2.889633e-003,0,,0,
1616200876.970,,9.000000e+003,3.000041e+001,-3.632778e-005,3.333971e-008,0.000000e+000,0.000000e+000,2,9.077898e-001,1.825000e+000,,,,,,,,,,,,,,,,,,0,3.000000e+000,1.000000e+000,10,5,2.889633e-003,0,,0,
1616201071.093,,8.000000e+003,3.000041e+001,-3.215135e-005,5.006840e-008,0.000000e+000,0.000000e+000,2,9.065183e-001,1.825000e+000,,,,,,,,,,,,,,,,,,0,3.000000e+000,1.000000e+000,10,5,4.339218e-003,0,,0,
1616201270.790,,7.000000e+003,3.000171e+001,-2.801103e-005,5.171010e-008,0.000000e+000,0.000000e+000,2,9.056890e-001,1.825000e+000,,,,,,,,,,,,,,,,,,0,3.000000e+000,1.000000e+000,10,5,2.889633e-003,0,,0,
1616201464.802,,6.000000e+003,3.000099e+001,-2.383745e-005,3.880529e-008,0.000000e+000,0.000000e+000,2,9.032809e-001,1.825000e+000,,,,,,,,,,,,,,,,,,0,3.000000e+000,1.000000e+000,10,5,0.000000e+000,0,,0,
1616201656.980,,5.000000e+003,3.000070e+001,-1.972067e-005,1.412644e-008,0.000000e+000,0.000000e+000,2,8.985801e-001,1.825000e+000,,,,,,,,,,,,,,,,,,0,3.000000e+000,1.000000e+000,10,5,2.889633e-003,0,,0,
1616201855.963,,4.000000e+003,3.000128e+001,-1.563097e-005,3.437919e-008,0.000000e+000,0.000000e+000,2,8.921253e-001,1.825000e+000,,,,,,,,,,,,,,,,,,0,3.000000e+000,1.000000e+000,10,5,2.889633e-003,0,,0,
1616202085.840,,3.500000e+003,3.000070e+001,-1.356666e-005,3.452151e-008,0.000000e+000,0.000000e+000,2,8.885925e-001,1.825000e+000,,,,,,,,,,,,,,,,,,0,3.000000e+000,1.000000e+000,10,5,2.889633e-003,0,,0,
1616202295.205,,3.000000e+003,3.000070e+001,-1.151993e-005,3.864019e-008,0.000000e+000,0.000000e+000,2,8.751774e-001,1.825000e+000,,,,,,,,,,,,,,,,,,0,3.000000e+000,1.000000e+000,10,5,1.449585e-003,0,,0,
1616202542.477,,2.500000e+003,3.000142e+001,-9.534143e-006,2.825343e-008,0.000000e+000,0.000000e+000,2,8.666839e-001,1.825000e+000,,,,,,,,,,,,,,,,,,0,3.000000e+000,1.000000e+000,10,5,1.440048e-003,0,,0,
1616202812.154,,2.000000e+003,3.000056e+001,-7.541802e-006,2.982788e-008,0.000000e+000,0.000000e+000,2,8.456939e-001,1.825000e+000,,,,,,,,,,,,,,,,,,0,3.000000e+000,1.000000e+000,10,5,1.449585e-003,0,,0,
1616203045.860,,1.500000e+003,3.000084e+001,-5.656075e-006,2.543620e-008,0.000000e+000,0.000000e+000,2,8.183234e-001,1.825000e+000,,,,,,,,,,,,,,,,,,0,3.000000e+000,1.000000e+000,10,5,4.339218e-003,0,,0,
1616203240.292,,1.000000e+003,3.000056e+001,-3.816727e-006,3.062523e-008,0.000000e+000,0.000000e+000,2,7.313155e-001,1.825000e+000,,,,,,,,,,,,,,,,,,0,3.000000e+000,1.000000e+000,10,5,1.449585e-003,0,,0,
1616203428.699,,8.000000e+002,3.000142e+001,-3.156582e-006,4.032466e-008,0.000000e+000,0.000000e+000,2,6.831151e-001,1.825000e+000,,,,,,,,,,,,,,,,,,0,3.000000e+000,1.000000e+000,10,5,4.339218e-003,0,,0,
1616203615.820,,6.000000e+002,3.000128e+001,-2.454006e-006,4.895578e-008,0.000000e+000,0.000000e+000,2,5.968803e-001,1.825000e+000,,,,,,,,,,,,,,,,,,0,3.000000e+000,1.000000e+000,10,5,2.889633e-003,0,,0,
1616203802.442,,4.000000e+002,3.000186e+001,-1.826043e-006,4.023125e-008,0.000000e+000,0.000000e+000,2,4.529117e-001,1.825000e+000,,,,,,,,,,,,,,,,,,0,3.000000e+000,1.000000e+000,10,5,4.339218e-003,0,,0,
1616203990.940,,2.000000e+002,3.000171e+001,-1.308082e-006,7.878542e-008,0.000000e+000,0.000000e+000,2,2.241870e-001,1.825000e+000,,,,,,,,,,,,,,,,,,0,3.000000e+000,1.000000e+000,10,5,4.339218e-003,0,,0,
1616204185.273,,0.000000e+000,3.000084e+001,2.266212e-006,5.236901e-008,0.000000e+000,0.000000e+000,2,5.219095e-001,1.825000e+000,,,,,,,,,,,,,,,,,,0,3.000000e+000,1.000000e+000,10,5,2.889633e-003,0,,0,
1616204374.539,,-2.000000e+002,3.000027e+001,2.379662e-006,6.282997e-008,0.000000e+000,0.000000e+000,2,5.533372e-001,1.825000e+000,,,,,,,,,,,,,,,,,,0,3.000000e+000,1.000000e+000,10,5,2.889633e-003,0,,0,
1616204568.954,,-4.000000e+002,2.999983e+001,2.752518e-006,7.752580e-008,0.000000e+000,0.000000e+000,2,5.858471e-001,1.825000e+000,,,,,,,,,,,,,,,,,,0,3.000000e+000,1.000000e+000,10,5,2.899170e-003,0,,0,
1616204757.586,,-6.000000e+002,3.000099e+001,3.156175e-006,3.295202e-008,0.000000e+000,0.000000e+000,2,6.786970e-001,1.825000e+000,,,,,,,,,,,,,,,,,,0,3.000000e+000,1.000000e+000,10,5,2.889633e-003,0,,0,
1616204947.070,,-8.000000e+002,3.000099e+001,3.644494e-006,1.388408e-007,0.000000e+000,0.000000e+000,2,7.135441e-001,1.825000e+000,,,,,,,,,,,,,,,,,,0,3.000000e+000,1.000000e+000,10,5,5.790710e-003,0,,0,
1616205135.085,,-1.000000e+003,3.000113e+001,4.348109e-006,6.235945e-008,0.000000e+000,0.000000e+000,2,7.477357e-001,1.825000e+000,,,,,,,,,,,,,,,,,,0,3.000000e+000,1.000000e+000,10,5,1.440048e-003,0,,0,
1616205356.879,,-1.500000e+003,3.000070e+001,6.040369e-006,1.851534e-008,0.000000e+000,0.000000e+000,2,8.302378e-001,1.825000e+000,,,,,,,,,,,,,,,,,,0,3.000000e+000,1.000000e+000,10,5,4.339218e-003,0,,0,
1616205580.569,,-2.000000e+003,3.000084e+001,7.907051e-006,1.240012e-008,0.000000e+000,0.000000e+000,2,8.713580e-001,1.825000e+000,,,,,,,,,,,,,,,,,,0,3.000000e+000,1.000000e+000,10,5,2.889633e-003,0,,0,
1616205816.709,,-2.500000e+003,3.000099e+001,9.854120e-006,2.054335e-008,0.000000e+000,0.000000e+000,2,8.914987e-001,1.825000e+000,,,,,,,,,,,,,,,,,,0,3.000000e+000,1.000000e+000,10,5,2.889633e-003,0,,0,
1616206044.734,,-3.000000e+003,3.000027e+001,1.186993e-005,3.719690e-008,0.000000e+000,0.000000e+000,2,9.053404e-001,1.825000e+000,,,,,,,,,,,,,,,,,,0,3.000000e+000,1.000000e+000,10,5,1.449585e-003,0,,0,
1616206285.526,,-3.500000e+003,3.000012e+001,1.389386e-005,1.992700e-008,0.000000e+000,0.000000e+000,2,9.101124e-001,1.825000e+000,,,,,,,,,,,,,,,,,,0,3.000000e+000,1.000000e+000,10,5,1.449585e-003,0,,0,
1616206475.013,,-4.000000e+003,3.000171e+001,1.592523e-005,1.042357e-007,0.000000e+000,0.000000e+000,2,9.140210e-001,1.825000e+000,,,,,,,,,,,,,,,,,,0,3.000000e+000,1.000000e+000,10,5,1.440048e-003,0,,0,
1616206673.655,,-5.000000e+003,3.000084e+001,2.001774e-005,5.312170e-008,0.000000e+000,0.000000e+000,2,9.182516e-001,1.825000e+000,,,,,,,,,,,,,,,,,,0,3.000000e+000,1.000000e+000,10,5,4.339218e-003,0,,0,
1616206867.546,,-6.000000e+003,3.000027e+001,2.419184e-005,2.587890e-008,0.000000e+000,0.000000e+000,2,9.206252e-001,1.825000e+000,,,,,,,,,,,,,,,,,,0,3.000000e+000,1.000000e+000,10,5,2.889633e-003,0,,0,
1616207082.437,,-7.000000e+003,3.000084e+001,2.834676e-005,3.436802e-008,0.000000e+000,0.000000e+000,2,9.201446e-001,1.825000e+000,,,,,,,,,,,,,,,,,,0,3.000000e+000,1.000000e+000,10,5,2.889633e-003,0,,0,
1616207307.454,,-8.000000e+003,3.000056e+001,3.246020e-005,1.732704e-008,0.000000e+000,0.000000e+000,2,9.203084e-001,1.825000e+000,,,,,,,,,,,,,,,,,,0,3.000000e+000,1.000000e+000,10,5,2.889633e-003,0,,0,
1616207496.469,,-9.000000e+003,3.000084e+001,3.663038e-005,2.563557e-008,0.000000e+000,0.000000e+000,2,9.201390e-001,1.825000e+000,,,,,,,,,,,,,,,,,,0,3.000000e+000,1.000000e+000,10,5,1.449585e-003,0,,0,
1616207685.281,,-1.000000e+004,3.000099e+001,4.082322e-005,4.019848e-008,0.000000e+000,0.000000e+000,2,9.204144e-001,1.825000e+000,,,,,,,,,,,,,,,,,,0,3.000000e+000,1.000000e+000,10,5,4.339218e-003,0,,0,
1616207870.117,,-1.200000e+004,3.000070e+001,4.911507e-005,4.045057e-008,0.000000e+000,0.000000e+000,2,9.179916e-001,1.825000e+000,,,,,,,,,,,,,,,,,,0,3.000000e+000,1.000000e+000,10,5,1.449585e-003,0,,0,
1616208063.801,,-1.400000e+004,3.000128e+001,5.749557e-005,4.359913e-008,0.000000e+000,0.000000e+000,2,9.178045e-001,1.825000e+000,,,,,,,,,,,,,,,,,,0,3.000000e+000,1.000000e+000,10,5,2.889633e-003,0,,0,
1616208249.542,,-1.600000e+004,3.000084e+001,6.582084e-005,4.024726e-008,0.000000e+000,0.000000e+000,2,9.170824e-001,1.825000e+000,,,,,,,,,,,,,,,,,,0,3.000000e+000,1.000000e+000,10,5,2.889633e-003,0,,0,
1616208436.880,,-1.800000e+004,3.000070e+001,7.422217e-005,4.939828e-008,0.000000e+000,0.000000e+000,2,9.166561e-001,1.825000e+000,,,,,,,,,,,,,,,,,,0,3.000000e+000,1.000000e+000,10,5,4.339218e-003,0,,0,
1616208672.406,,-2.000000e+004,3.000157e+001,8.252618e-005,6.900923e-008,0.000000e+000,0.000000e+000,2,9.157355e-001,1.825000e+000,,,,,,,,,,,,,,,,,,0,3.000000e+000,1.000000e+000,10,5,2.889633e-003,0,,0,
1616208881.421,,-2.500000e+004,3.000113e+001,1.035036e-004,3.555604e-008,0.000000e+000,0.000000e+000,2,9.150307e-001,1.825000e+000,,,,,,,,,,,,,,,,,,0,3.000000e+000,1.000000e+000,10,5,2.889633e-003,0,,0,
1616209090.953,,-3.000000e+004,3.000185e+001,1.243609e-004,2.148177e-007,0.000000e+000,0.000000e+000,2,9.140110e-001,1.825000e+000,,,,,,,,,,,,,,,,,,0,3.000000e+000,1.000000e+000,10,5,1.440048e-003,0,,0,
1616209300.825,,-3.500000e+004,3.000084e+001,1.455231e-004,1.726343e-007,0.000000e+000,0.000000e+000,2,9.133835e-001,1.825000e+000,,,,,,,,,,,,,,,,,,0,3.000000e+000,1.000000e+000,10,5,2.889633e-003,0,,0,
1616209510.700,,-4.000000e+004,3.000128e+001,1.664013e-004,2.314982e-007,0.000000e+000,0.000000e+000,2,9.141289e-001,1.825000e+000,,,,,,,,,,,,,,,,,,0,3.000000e+000,1.000000e+000,10,5,1.440048e-003,0,,0,
1616209723.264,,-4.500000e+004,3.000113e+001,1.875520e-004,1.793931e-007,0.000000e+000,0.000000e+000,2,9.140212e-001,1.825000e+000,,,,,,,,,,,,,,,,,,0,3.000000e+000,1.000000e+000,10,5,2.889633e-003,0,,0,
1616209949.443,,-5.000000e+004,3.000113e+001,2.086093e-004,1.476859e-007,0.000000e+000,0.000000e+000,2,9.135237e-001,1.825000e+000,,,,,,,,,,,,,,,,,,0,3.000000e+000,1.000000e+000,10,5,4.339218e-003,0,,0,
1616210166.225,,-4.500000e+004,3.000157e+001,1.874639e-004,2.636766e-007,0.000000e+000,0.000000e+000,2,9.137820e-001,1.825000e+000,,,,,,,,,,,,,,,,,,0,3.000000e+000,1.000000e+000,10,5,1.440048e-003,0,,0,
1616210375.638,,-4.000000e+004,3.000113e+001,1.663108e-004,1.450586e-007,0.000000e+000,0.000000e+000,2,9.134517e-001,1.825000e+000,,,,,,,,,,,,,,,,,,0,3.000000e+000,1.000000e+000,10,5,4.339218e-003,0,,0,
1616210584.774,,-3.500000e+004,3.000128e+001,1.453342e-004,1.039899e-007,0.000000e+000,0.000000e+000,2,9.138633e-001,1.825000e+000,,,,,,,,,,,,,,,,,,0,3.000000e+000,1.000000e+000,10,5,4.339218e-003,0,,0,
1616210785.778,,-3.000000e+004,3.000056e+001,1.243167e-004,8.750527e-008,0.000000e+000,0.000000e+000,2,9.150763e-001,1.825000e+000,,,,,,,,,,,,,,,,,,0,3.000000e+000,1.000000e+000,10,5,1.449585e-003,0,,0,
1616210992.460,,-2.500000e+004,3.000099e+001,1.033795e-004,1.223220e-007,0.000000e+000,0.000000e+000,2,9.156077e-001,1.825000e+000,,,,,,,,,,,,,,,,,,0,3.000000e+000,1.000000e+000,10,5,0.000000e+000,0,,0,
1616211204.217,,-2.000000e+004,3.000128e+001,8.241901e-005,6.686918e-008,0.000000e+000,0.000000e+000,2,9.167238e-001,1.825000e+000,,,,,,,,,,,,,,,,,,0,3.000000e+000,1.000000e+000,10,5,2.889633e-003,0,,0,
1616211390.872,,-1.800000e+004,3.000099e+001,7.407771e-005,5.276359e-008,0.000000e+000,0.000000e+000,2,9.168546e-001,1.825000e+000,,,,,,,,,,,,,,,,,,0,3.000000e+000,1.000000e+000,10,5,2.889633e-003,0,,0,
1616211584.637,,-1.600000e+004,3.000070e+001,6.564011e-005,1.072214e-007,0.000000e+000,0.000000e+000,2,9.179790e-001,1.825000e+000,,,,,,,,,,,,,,,,,,0,3.000000e+000,1.000000e+000,10,5,2.889633e-003,0,,0,
1616211777.184,,-1.400000e+004,3.000171e+001,5.731024e-005,3.203717e-008,0.000000e+000,0.000000e+000,2,9.192740e-001,1.825000e+000,,,,,,,,,,,,,,,,,,0,3.000000e+000,1.000000e+000,10,5,4.339218e-003,0,,0,
1616211970.966,,-1.200000e+004,3.000099e+001,4.898277e-005,3.834244e-008,0.000000e+000,0.000000e+000,2,9.188815e-001,1.825000e+000,,,,,,,,,,,,,,,,,,0,3.000000e+000,1.000000e+000,10,5,2.889633e-003,0,,0,
1616212164.782,,-1.000000e+004,3.000157e+001,4.063714e-005,5.385163e-008,0.000000e+000,0.000000e+000,2,9.207531e-001,1.825000e+000,,,,,,,,,,,,,,,,,,0,3.000000e+000,1.000000e+000,10,5,2.889633e-003,0,,0,
1616212368.179,,-9.000000e+003,3.000099e+001,3.651122e-005,4.461612e-008,0.000000e+000,0.000000e+000,2,9.212349e-001,1.825000e+000,,,,,,,,,,,,,,,,,,0,3.000000e+000,1.000000e+000,10,5,2.889633e-003,0,,0,
1616212574.043,,-8.000000e+003,3.000128e+001,3.233645e-005,3.871928e-008,0.000000e+000,0.000000e+000,2,9.222782e-001,1.825000e+000,,,,,,,,,,,,,,,,,,0,3.000000e+000,1.000000e+000,10,5,2.889633e-003,0,,0,
1616212779.080,,-7.000000e+003,3.000099e+001,2.815481e-005,5.727118e-008,0.000000e+000,0.000000e+000,2,9.213409e-001,1.825000e+000,,,,,,,,,,,,,,,,,,0,3.000000e+000,1.000000e+000,10,5,0.000000e+000,0,,0,
1616212972.854,,-6.000000e+003,3.000084e+001,2.402309e-005,3.276281e-008,0.000000e+000,0.000000e+000,2,9.209490e-001,1.825000e+000,,,,,,,,,,,,,,,,,,0,3.000000e+000,1.000000e+000,10,5,1.449585e-003,0,,0,
1616213171.732,,-5.000000e+003,3.000128e+001,1.987778e-005,1.694444e-008,0.000000e+000,0.000000e+000,2,9.197515e-001,1.825000e+000,,,,,,,,,,,,,,,,,,0,3.000000e+000,1.000000e+000,10,5,1.440048e-003,0,,0,
1616213385.994,,-4.000000e+003,3.000142e+001,1.580363e-005,3.011364e-008,0.000000e+000,0.000000e+000,2,9.156032e-001,1.825000e+000,,,,,,,,,,,,,,,,,,0,3.000000e+000,1.000000e+000,10,5,4.339218e-003,0,,0,
1616213611.981,,-3.500000e+003,3.000056e+001,1.375412e-005,1.704740e-008,0.000000e+000,0.000000e+000,2,9.106928e-001,1.825000e+000,,,,,,,,,,,,,,,,,,0,3.000000e+000,1.000000e+000,10,5,2.889633e-003,0,,0,
1616213845.647,,-3.000000e+003,3.000070e+001,1.171935e-005,1.828487e-008,0.000000e+000,0.000000e+000,2,9.021351e-001,1.825000e+000,,,,,,,,,,,,,,,,,,0,3.000000e+000,1.000000e+000,10,5,2.889633e-003,0,,0,
1616214078.497,,-2.500000e+003,3.000041e+001,9.677471e-006,5.694999e-008,0.000000e+000,0.000000e+000,2,8.902801e-001,1.825000e+000,,,,,,,,,,,,,,,,,,0,3.000000e+000,1.000000e+000,10,5,4.339218e-003,0,,0,
1616214308.550,,-2.000000e+003,3.000099e+001,7.701043e-006,4.635226e-008,0.000000e+000,0.000000e+000,2,8.680311e-001,1.825000e+000,,,,,,,,,,,,,,,,,,0,3.000000e+000,1.000000e+000,10,5,0.000000e+000,0,,0,
1616214536.533,,-1.500000e+003,3.000084e+001,5.846656e-006,5.337537e-008,0.000000e+000,0.000000e+000,2,8.228904e-001,1.825000e+000,,,,,,,,,,,,,,,,,,0,3.000000e+000,1.000000e+000,10,5,2.889633e-003,0,,0,
1616214730.288,,-1.000000e+003,3.000113e+001,4.013394e-006,4.946603e-008,0.000000e+000,0.000000e+000,2,7.432334e-001,1.825000e+000,,,,,,,,,,,,,,,,,,0,3.000000e+000,1.000000e+000,10,5,2.889633e-003,0,,0,
1616214919.181,,-8.000000e+002,3.000099e+001,3.322044e-006,4.454746e-008,0.000000e+000,0.000000e+000,2,6.741448e-001,1.825000e+000,,,,,,,,,,,,,,,,,,0,3.000000e+000,1.000000e+000,10,5,2.889633e-003,0,,0,
1616215107.383,,-6.000000e+002,3.000185e+001,2.706071e-006,3.389983e-008,0.000000e+000,0.000000e+000,2,5.891347e-001,1.825000e+000,,,,,,,,,,,,,,,,,,0,3.000000e+000,1.000000e+000,10,5,1.440048e-003,0,,0,
1616215293.010,,-4.000000e+002,3.000113e+001,2.045191e-006,4.283270e-008,0.000000e+000,0.000000e+000,2,4.696514e-001,1.825000e+000,,,,,,,,,,,,,,,,,,0,3.000000e+000,1.000000e+000,10,5,2.889633e-003,0,,0,
1616215481.554,,-2.000000e+002,3.000055e+001,1.499624e-006,3.862858e-008,0.000000e+000,0.000000e+000,2,2.796831e-001,1.825000e+000,,,,,,,,,,,,,,,,,,0,3.000000e+000,1.000000e+000,10,5,2.889633e-003,0,,0,
1616215675.759,,0.000000e+000,3.000084e+001,-7.540456e-007,8.433468e-008,0.000000e+000,0.000000e+000,2,0.000000e+000,1.825000e+000,,,,,,,,,,,,,,,,,,0,3.000000e+000,1.000000e+000,10,5,2.889633e-003,0,,0,
1616215862.866,,2.000000e+002,3.000084e+001,-9.657456e-007,3.744709e-008,0.000000e+000,0.000000e+000,2,0.000000e+000,1.825000e+000,,,,,,,,,,,,,,,,,,0,3.000000e+000,1.000000e+000,10,5,2.889633e-003,0,,0,
1616216055.075,,4.000000e+002,3.000056e+001,-1.210428e-006,5.938273e-008,0.000000e+000,0.000000e+000,2,1.642886e-001,1.825000e+000,,,,,,,,,,,,,,,,,,0,3.000000e+000,1.000000e+000,10,5,1.449585e-003,0,,0,
1616216243.649,,6.000000e+002,3.000027e+001,-1.580942e-006,4.873055e-008,0.000000e+000,0.000000e+000,2,3.643757e-001,1.825000e+000,,,,,,,,,,,,,,,,,,0,3.000000e+000,1.000000e+000,10,5,2.899170e-003,0,,0,
1616216432.631,,8.000000e+002,3.000099e+001,-2.227352e-006,1.617197e-007,0.000000e+000,0.000000e+000,2,5.413193e-001,1.825000e+000,,,,,,,,,,,,,,,,,,0,3.000000e+000,1.000000e+000,10,5,2.889633e-003,0,,0,
1616216619.595,,1.000000e+003,3.000070e+001,-2.726124e-006,5.551793e-008,0.000000e+000,0.000000e+000,2,6.561759e-001,1.825000e+000,,,,,,,,,,,,,,,,,,0,3.000000e+000,1.000000e+000,10,5,2.889633e-003,0,,0,
1616216831.692,,1.500000e+003,3.000099e+001,-4.484890e-006,7.099485e-009,0.000000e+000,0.000000e+000,2,7.983168e-001,1.825000e+000,,,,,,,,,,,,,,,,,,0,3.000000e+000,1.000000e+000,10,5,2.889633e-003,0,,0,
1616217066.826,,2.000000e+003,3.000056e+001,-6.350012e-006,1.449086e-008,0.000000e+000,0.000000e+000,2,8.616114e-001,1.825000e+000,,,,,,,,,,,,,,,,,,0,3.000000e+000,1.000000e+000,10,5,1.449585e-003,0,,0,
1616217256.342,,2.500000e+003,3.000099e+001,-8.326614e-006,1.865700e-008,0.000000e+000,0.000000e+000,2,8.921598e-001,1.825000e+000,,,,,,,,,,,,,,,,,,0,3.000000e+000,1.000000e+000,10,5,2.889633e-003,0,,0,
1616217460.896,,3.000000e+003,3.000012e+001,-1.026561e-005,1.793630e-008,0.000000e+000,0.000000e+000,2,9.050098e-001,1.825000e+000,,,,,,,,,,,,,,,,,,0,3.000000e+000,1.000000e+000,10,5,1.449585e-003,0,,0,
1616217658.352,,3.500000e+003,3.000084e+001,-1.228679e-005,4.802885e-008,0.000000e+000,0.000000e+000,2,9.149935e-001,1.825000e+000,,,,,,,,,,,,,,,,,,0,3.000000e+000,1.000000e+000,10,5,2.889633e-003,0,,0,
1616217853.698,,4.000000e+003,3.000142e+001,-1.423990e-005,8.441057e-008,0.000000e+000,0.000000e+000,2,9.187787e-001,1.825000e+000,,,,,,,,,,,,,,,,,,0,3.000000e+000,1.000000e+000,10,5,1.440048e-003,0,,0,
1616218086.760,,5.000000e+003,3.000084e+001,-1.835752e-005,6.034050e-008,0.000000e+000,0.000000e+000,2,9.243487e-001,1.825000e+000,,,,,,,,,,,,,,,,,,0,3.000000e+000,1.000000e+000,10,5,4.339218e-003,0,,0,
1616218285.686,,6.000000e+003,3.000113e+001,-2.251004e-005,3.203820e-008,0.000000e+000,0.000000e+000,2,9.251380e-001,1.825000e+000,,,,,,,,,,,,,,,,,,0,3.000000e+000,1.000000e+000,10,5,2.889633e-003,0,,0,
1616218485.780,,7.000000e+003,3.000056e+001,-2.659806e-005,4.942425e-008,0.000000e+000,0.000000e+000,2,9.246177e-001,1.825000e+000,,,,,,,,,,,,,,,,,,0,3.000000e+000,1.000000e+000,10,5,1.449585e-003,0,,0,
1616218671.762,,8.000000e+003,3.000099e+001,-3.085672e-005,3.091518e-007,0.000000e+000,0.000000e+000,2,9.225458e-001,1.825000e+000,,,,,,,,,,,,,,,,,,0,3.000000e+000,1.000000e+000,10,5,0.000000e+000,0,,0,
1616218851.748,,9.000000e+003,3.000142e+001,-3.490328e-005,4.355878e-008,0.000000e+000,0.000000e+000,2,9.226761e-001,1.825000e+000,,,,,,,,,,,,,,,,,,0,3.000000e+000,1.000000e+000,10,5,2.889633e-003,0,,0,
1616219031.694,,1.000000e+004,3.000070e+001,-3.907530e-005,1.980365e-008,0.000000e+000,0.000000e+000,2,9.226400e-001,1.825000e+000,,,,,,,,,,,,,,,,,,0,3.000000e+000,1.000000e+000,10,5,2.889633e-003,0,,0,
1616219230.945,,1.200000e+004,3.000041e+001,-4.742588e-005,3.432131e-008,0.000000e+000,0.000000e+000,2,9.214796e-001,1.825000e+000,,,,,,,,,,,,,,,,,,0,3.000000e+000,1.000000e+000,10,5,1.449585e-003,0,,0,
1616219424.413,,1.400000e+004,3.000041e+001,-5.567604e-005,7.390802e-008,0.000000e+000,0.000000e+000,2,9.197716e-001,1.825000e+000,,,,,,,,,,,,,,,,,,0,3.000000e+000,1.000000e+000,10,5,2.889633e-003,0,,0,
1616219610.136,,1.600000e+004,3.000099e+001,-6.411700e-005,4.762181e-008,0.000000e+000,0.000000e+000,2,9.189333e-001,1.825000e+000,,,,,,,,,,,,,,,,,,0,3.000000e+000,1.000000e+000,10,5,2.889633e-003,0,,0,
1616219803.778,,1.800000e+004,3.000041e+001,-7.243254e-005,6.238776e-008,0.000000e+000,0.000000e+000,2,9.178059e-001,1.825000e+000,,,,,,,,,,,,,,,,,,0,3.000000e+000,1.000000e+000,10,5,2.899170e-003,0,,0,
1616219998.110,,2.000000e+004,3.000128e+001,-8.081154e-005,6.495670e-008,0.000000e+000,0.000000e+000,2,9.171159e-001,1.825000e+000,,,,,,,,,,,,,,,,,,0,3.000000e+000,1.000000e+000,10,5,2.889633e-003,0,,0,
1616220223.064,,2.500000e+004,3.000056e+001,-1.018080e-004,5.098510e-008,0.000000e+000,0.000000e+000,2,9.156702e-001,1.825000e+000,,,,,,,,,,,,,,,,,,0,3.000000e+000,1.000000e+000,10,5,2.889633e-003,0,,0,
1616220437.662,,3.000000e+004,3.000113e+001,-1.219364e-004,1.757719e-006,0.000000e+000,0.000000e+000,2,9.081132e-001,1.825000e+000,,,,,,,,,,,,,,,,,,0,3.000000e+000,1.000000e+000,10,5,2.889633e-003,0,,0,
1616220641.126,,3.500000e+004,3.000084e+001,-1.437569e-004,1.562752e-007,0.000000e+000,0.000000e+000,2,9.146056e-001,1.825000e+000,,,,,,,,,,,,,,,,,,0,3.000000e+000,1.000000e+000,10,5,1.449585e-003,0,,0,
1616220851.178,,4.000000e+004,3.000128e+001,-1.648042e-004,1.891204e-007,0.000000e+000,0.000000e+000,2,9.145355e-001,1.825000e+000,,,,,,,,,,,,,,,,,,0,3.000000e+000,1.000000e+000,10,5,1.440048e-003,0,,0,
1616221057.414,,4.500000e+004,3.000055e+001,-1.859139e-004,1.577657e-007,0.000000e+000,0.000000e+000,2,9.137103e-001,1.825000e+000,,,,,,,,,,,,,,,,,,0,3.000000e+000,1.000000e+000,10,5,4.339218e-003,0,,0,
1616221264.346,,5.000000e+004,3.000186e+001,-2.067181e-004,1.736972e-007,0.000000e+000,0.000000e+000,2,9.136232e-001,1.825000e+000,,,,,,,,,,,,,,,,,,0,3.000000e+000,1.000000e+000,10,5,1.440048e-003,0,,0,