File: SiC2/Hyst at 300K/SiC2_hyst_300K.rso.dat.csv
[Header]
TITLE,MPMS RSO Measurement
BYAPP,MPMS Measurement,1.1,Summary
FILEOPENTIME, 1616160057.347000 3/19/2021, 2:20:57 PM

INFO, APPNAME, MPMS MultiVu Application, Revision 1.61,  Build 082

INFO, NAME,
INFO, WEIGHT, 1.000
INFO, AREA, 1.000
INFO, LENGTH, 1.000
INFO, SHAPE, 0
INFO, COMMENT,
INFO, SEQUENCE FILE: H5T_Lin_NoO.seq


INFO, BACKGROUND DATA FILE:, None


STARTUPAXIS,X,4,LINEAR,AUTO,0.000000,0.000000
STARTUPAXIS,Y1,5,LINEAR,AUTO,0.000000,0.000000


STARTUPGROUP,Longitudinal
FIELDGROUP,Longitudinal,1,2,3,4,5,6,7,8,9,10,11,19,20,21,22,23,35
FIELDGROUP,Transverse,1,2,3,4,12,13,14,15,16,17,18,24,25,26,27,28,35

PLOT_APPEARANCE,ALL,HORZ_GRID_ON,VERT_GRID_ON,MARKERS_AND_LINES

[Data]
Time,Comment,Field (Oe),Temperature (K),Long Moment (emu),Long Scan Std Dev,Long Offset (cm),Long Offset Std Dev,Long Algorithm,Long Reg Fit,Long Reg Factor,Trans Moment (emu),Trans Scan Std Dev,Trans Offset (cm),Trans Offset Std Dev,Trans Algorithm,Trans Reg Fit,Trans Reg Factor,Long Moment [w/o ABS] (emu),Long Scan Std Dev [w/o ABS],Long Offset [w/o ABS] (cm),Long Offset Std Dev [w/o ABS],Long Reg Fit [w/o ABS],Trans Moment [w/o ABS] (emu),Trans Scan Std Dev [w/o ABS],Trans Offset [w/o ABS] (cm),Trans Offset Std Dev [w/o ABS],Trans Reg Fit [w/o ABS],RSO Position (deg),Amplitude (cm),Frequency,Cycles to Average,Scans per Measurement,Delta Temp (K),Error,EC Comp. Running,Using ABS,
1616160057.337,,0.000000e+000,3.000056e+002,1.165688e-007,2.504336e-009,0.000000e+000,0.000000e+000,2,7.408025e-001,1.825000e+000,,,,,,,,,,,,,,,,,,0,3.000000e+000,1.000000e+000,10,5,2.288818e-002,0,,0,
1616160245.167,,2.000000e+002,3.000033e+002,-2.634359e-007,6.736002e-009,0.000000e+000,0.000000e+000,2,8.432361e-001,1.825000e+000,,,,,,,,,,,,,,,,,,0,3.000000e+000,1.000000e+000,10,5,1.150513e-002,0,,0,
1616160439.476,,4.000000e+002,2.999998e+002,-7.080598e-007,6.249719e-009,0.000000e+000,0.000000e+000,2,9.059833e-001,1.825000e+000,,,,,,,,,,,,,,,,,,0,3.000000e+000,1.000000e+000,10,5,2.301025e-002,0,,0,
1616160625.655,,6.000000e+002,3.000044e+002,-1.315699e-006,4.940888e-009,0.000000e+000,0.000000e+000,2,9.278387e-001,1.825000e+000,,,,,,,,,,,,,,,,,,0,3.000000e+000,1.000000e+000,10,5,1.150513e-002,0,,0,
1616160812.425,,8.000000e+002,3.000010e+002,-1.992839e-006,6.170502e-009,0.000000e+000,0.000000e+000,2,9.360114e-001,1.825000e+000,,,,,,,,,,,,,,,,,,0,3.000000e+000,1.000000e+000,10,5,1.150513e-002,0,,0,
1616160998.604,,1.000000e+003,3.000032e+002,-2.717643e-006,4.911170e-009,0.000000e+000,0.000000e+000,2,9.413105e-001,1.825000e+000,,,,,,,,,,,,,,,,,,0,3.000000e+000,1.000000e+000,10,5,2.288818e-002,0,,0,
1616161194.353,,1.500000e+003,3.000021e+002,-4.636659e-006,1.145715e-008,0.000000e+000,0.000000e+000,2,9.454686e-001,1.825000e+000,,,,,,,,,,,,,,,,,,0,3.000000e+000,1.000000e+000,10,5,1.150513e-002,0,,0,
1616161391.123,,2.000000e+003,2.999975e+002,-6.632470e-006,1.011273e-008,0.000000e+000,0.000000e+000,2,9.469271e-001,1.825000e+000,,,,,,,,,,,,,,,,,,0,3.000000e+000,1.000000e+000,10,5,2.301025e-002,0,,0,
1616161628.962,,2.500000e+003,3.000009e+002,-8.698406e-006,9.406424e-009,0.000000e+000,0.000000e+000,2,9.484401e-001,1.825000e+000,,,,,,,,,,,,,,,,,,0,3.000000e+000,1.000000e+000,10,5,1.150513e-002,0,,0,
1616161898.771,,3.000000e+003,3.000033e+002,-1.080086e-005,1.326871e-008,0.000000e+000,0.000000e+000,2,9.475178e-001,1.825000e+000,,,,,,,,,,,,,,,,,,0,3.000000e+000,1.000000e+000,10,5,1.150513e-002,0,,0,
1616162123.540,,3.500000e+003,3.000010e+002,-1.291768e-005,1.506676e-008,0.000000e+000,0.000000e+000,2,9.463930e-001,1.825000e+000,,,,,,,,,,,,,,,,,,0,3.000000e+000,1.000000e+000,10,5,2.288818e-002,0,,0,
1616162320.539,,4.000000e+003,2.999987e+002,-1.503583e-005,1.255765e-008,0.000000e+000,0.000000e+000,2,9.474732e-001,1.825000e+000,,,,,,,,,,,,,,,,,,0,3.000000e+000,1.000000e+000,10,5,1.150513e-002,0,,0,
1616162512.189,,5.000000e+003,2.999998e+002,-1.930272e-005,8.150111e-009,0.000000e+000,0.000000e+000,2,9.462643e-001,1.825000e+000,,,,,,,,,,,,,,,,,,0,3.000000e+000,1.000000e+000,10,5,1.150513e-002,0,,0,
1616162711.278,,6.000000e+003,3.000021e+002,-2.362849e-005,1.739254e-008,0.000000e+000,0.000000e+000,2,9.450925e-001,1.825000e+000,,,,,,,,,,,,,,,,,,0,3.000000e+000,1.000000e+000,10,5,2.288818e-002,0,,0,
1616162911.107,,7.000000e+003,3.000044e+002,-2.792419e-005,2.113820e-008,0.000000e+000,0.000000e+000,2,9.459963e-001,1.825000e+000,,,,,,,,,,,,,,,,,,0,3.000000e+000,1.000000e+000,10,5,1.150513e-002,0,,0,
1616163099.316,,8.000000e+003,3.000021e+002,-3.226745e-005,2.957109e-008,0.000000e+000,0.000000e+000,2,9.456770e-001,1.825000e+000,,,,,,,,,,,,,,,,,,0,3.000000e+000,1.000000e+000,10,5,2.288818e-002,0,,0,
1616163279.834,,9.000000e+003,2.999987e+002,-3.657494e-005,2.440013e-008,0.000000e+000,0.000000e+000,2,9.448984e-001,1.825000e+000,,,,,,,,,,,,,,,,,,0,3.000000e+000,1.000000e+000,10,5,2.288818e-002,0,,0,
1616163459.972,,1.000000e+004,3.000010e+002,-4.096166e-005,1.677570e-008,0.000000e+000,0.000000e+000,2,9.445223e-001,1.825000e+000,,,,,,,,,,,,,,,,,,0,3.000000e+000,1.000000e+000,10,5,1.150513e-002,0,,0,
1616163650.802,,1.200000e+004,2.999964e+002,-4.966529e-005,2.091820e-008,0.000000e+000,0.000000e+000,2,9.441943e-001,1.825000e+000,,,,,,,,,,,,,,,,,,0,3.000000e+000,1.000000e+000,10,5,1.150513e-002,0,,0,
1616163842.146,,1.400000e+004,2.999998e+002,-5.837712e-005,3.019700e-008,0.000000e+000,0.000000e+000,2,9.438522e-001,1.825000e+000,,,,,,,,,,,,,,,,,,0,3.000000e+000,1.000000e+000,10,5,1.150513e-002,0,,0,
1616164028.129,,1.600000e+004,2.999998e+002,-6.708530e-005,3.409328e-008,0.000000e+000,0.000000e+000,2,9.437019e-001,1.825000e+000,,,,,,,,,,,,,,,,,,0,3.000000e+000,1.000000e+000,10,5,1.150513e-002,0,,0,
1616164226.869,,1.800000e+004,2.999998e+002,-7.581667e-005,3.131638e-008,0.000000e+000,0.000000e+000,2,9.435894e-001,1.825000e+000,,,,,,,,,,,,,,,,,,0,3.000000e+000,1.000000e+000,10,5,1.150513e-002,0,,0,
1616164418.992,,2.000000e+004,3.000010e+002,-8.451688e-005,5.471183e-008,0.000000e+000,0.000000e+000,2,9.433200e-001,1.825000e+000,,,,,,,,,,,,,,,,,,0,3.000000e+000,1.000000e+000,10,5,1.150513e-002,0,,0,
1616164626.566,,2.500000e+004,2.999952e+002,-1.062856e-004,5.431093e-008,0.000000e+000,0.000000e+000,2,9.434362e-001,1.825000e+000,,,,,,,,,,,,,,,,,,0,3.000000e+000,1.000000e+000,10,5,0.000000e+000,0,,0,
1616164829.630,,3.000000e+004,3.000010e+002,-1.281509e-004,7.556852e-008,0.000000e+000,0.000000e+000,2,9.426886e-001,1.825000e+000,,,,,,,,,,,,,,,,,,0,3.000000e+000,1.000000e+000,10,5,1.150513e-002,0,,0,
1616165039.735,,3.500000e+004,2.999998e+002,-1.500114e-004,2.212582e-008,0.000000e+000,0.000000e+000,2,9.426692e-001,1.825000e+000,,,,,,,,,,,,,,,,,,0,3.000000e+000,1.000000e+000,10,5,1.150513e-002,0,,0,
1616165249.940,,4.000000e+004,3.000056e+002,-1.718049e-004,7.629930e-008,0.000000e+000,0.000000e+000,2,9.422871e-001,1.825000e+000,,,,,,,,,,,,,,,,,,0,3.000000e+000,1.000000e+000,10,5,2.288818e-002,0,,0,
1616165456.161,,4.500000e+004,2.999975e+002,-1.937515e-004,5.184586e-008,0.000000e+000,0.000000e+000,2,9.421365e-001,1.825000e+000,,,,,,,,,,,,,,,,,,0,3.000000e+000,1.000000e+000,10,5,1.150513e-002,0,,0,
1616165662.217,,5.000000e+004,3.000033e+002,-2.156206e-004,8.246056e-008,0.000000e+000,0.000000e+000,2,9.417610e-001,1.825000e+000,,,,,,,,,,,,,,,,,,0,3.000000e+000,1.000000e+000,10,5,2.301025e-002,0,,0,
1616165887.428,,4.500000e+004,3.000009e+002,-1.937014e-004,3.380712e-008,0.000000e+000,0.000000e+000,2,9.414705e-001,1.825000e+000,,,,,,,,,,,,,,,,,,0,3.000000e+000,1.000000e+000,10,5,2.301025e-002,0,,0,
1616166097.029,,4.000000e+004,2.999998e+002,-1.717639e-004,4.494037e-008,0.000000e+000,0.000000e+000,2,9.419298e-001,1.825000e+000,,,,,,,,,,,,,,,,,,0,3.000000e+000,1.000000e+000,10,5,1.150513e-002,0,,0,
1616166305.696,,3.500000e+004,3.000010e+002,-1.499507e-004,4.679750e-008,0.000000e+000,0.000000e+000,2,9.419608e-001,1.825000e+000,,,,,,,,,,,,,,,,,,0,3.000000e+000,1.000000e+000,10,5,2.301025e-002,0,,0,
1616166536.019,,3.000000e+004,3.000021e+002,-1.280680e-004,6.368056e-008,0.000000e+000,0.000000e+000,2,9.418194e-001,1.825000e+000,,,,,,,,,,,,,,,,,,0,3.000000e+000,1.000000e+000,10,5,1.150513e-002,0,,0,
1616166742.818,,2.500000e+004,2.999987e+002,-1.062357e-004,4.666571e-008,0.000000e+000,0.000000e+000,2,9.421549e-001,1.825000e+000,,,,,,,,,,,,,,,,,,0,3.000000e+000,1.000000e+000,10,5,1.150513e-002,0,,0,
1616166948.226,,2.000000e+004,2.999975e+002,-8.442692e-005,5.473724e-008,0.000000e+000,0.000000e+000,2,9.416096e-001,1.825000e+000,,,,,,,,,,,,,,,,,,0,3.000000e+000,1.000000e+000,10,5,2.301025e-002,0,,0,
1616167140.585,,1.800000e+004,2.999964e+002,-7.566001e-005,2.598062e-008,0.000000e+000,0.000000e+000,2,9.416712e-001,1.825000e+000,,,,,,,,,,,,,,,,,,0,3.000000e+000,1.000000e+000,10,5,1.150513e-002,0,,0,
1616167332.124,,1.600000e+004,2.999998e+002,-6.697178e-005,1.824898e-008,0.000000e+000,0.000000e+000,2,9.418190e-001,1.825000e+000,,,,,,,,,,,,,,,,,,0,3.000000e+000,1.000000e+000,10,5,1.150513e-002,0,,0,
1616167522.992,,1.400000e+004,2.999987e+002,-5.825105e-005,1.672476e-008,0.000000e+000,0.000000e+000,2,9.421372e-001,1.825000e+000,,,,,,,,,,,,,,,,,,0,3.000000e+000,1.000000e+000,10,5,1.150513e-002,0,,0,
1616167714.391,,1.200000e+004,2.999987e+002,-4.955034e-005,1.801779e-008,0.000000e+000,0.000000e+000,2,9.418257e-001,1.825000e+000,,,,,,,,,,,,,,,,,,0,3.000000e+000,1.000000e+000,10,5,2.301025e-002,0,,0,
1616167906.050,,1.000000e+004,3.000010e+002,-4.018483e-005,1.469846e-006,0.000000e+000,0.000000e+000,2,9.016560e-001,1.825000e+000,,,,,,,,,,,,,,,,,,0,3.000000e+000,1.000000e+000,10,5,1.150513e-002,0,,0,
1616168107.839,,9.000000e+003,2.999998e+002,-3.649959e-005,1.027249e-008,0.000000e+000,0.000000e+000,2,9.416254e-001,1.825000e+000,,,,,,,,,,,,,,,,,,0,3.000000e+000,1.000000e+000,10,5,1.150513e-002,0,,0,
1616168322.737,,8.000000e+003,2.999998e+002,-3.218254e-005,1.829546e-008,0.000000e+000,0.000000e+000,2,9.416600e-001,1.825000e+000,,,,,,,,,,,,,,,,,,0,3.000000e+000,1.000000e+000,10,5,1.150513e-002,0,,0,
1616168521.346,,7.000000e+003,2.999998e+002,-2.786717e-005,1.966668e-008,0.000000e+000,0.000000e+000,2,9.415874e-001,1.825000e+000,,,,,,,,,,,,,,,,,,0,3.000000e+000,1.000000e+000,10,5,1.150513e-002,0,,0,
1616168735.384,,6.000000e+003,2.999998e+002,-2.355006e-005,2.238919e-008,0.000000e+000,0.000000e+000,2,9.418771e-001,1.825000e+000,,,,,,,,,,,,,,,,,,0,3.000000e+000,1.000000e+000,10,5,1.150513e-002,0,,0,
1616168927.213,,5.000000e+003,3.000010e+002,-1.922609e-005,1.352939e-008,0.000000e+000,0.000000e+000,2,9.417384e-001,1.825000e+000,,,,,,,,,,,,,,,,,,0,3.000000e+000,1.000000e+000,10,5,1.150513e-002,0,,0,
1616169161.601,,4.000000e+003,2.999975e+002,-1.496597e-005,1.356008e-008,0.000000e+000,0.000000e+000,2,9.436927e-001,1.825000e+000,,,,,,,,,,,,,,,,,,0,3.000000e+000,1.000000e+000,10,5,1.150513e-002,0,,0,
1616169407.940,,3.500000e+003,2.999952e+002,-1.282565e-005,3.051955e-008,0.000000e+000,0.000000e+000,2,9.423757e-001,1.825000e+000,,,,,,,,,,,,,,,,,,0,3.000000e+000,1.000000e+000,10,5,0.000000e+000,0,,0,
1616169643.318,,3.000000e+003,3.000021e+002,-1.072213e-005,2.605895e-008,0.000000e+000,0.000000e+000,2,9.422797e-001,1.825000e+000,,,,,,,,,,,,,,,,,,0,3.000000e+000,1.000000e+000,10,5,1.150513e-002,0,,0,
1616169836.387,,2.500000e+003,3.000032e+002,-8.645042e-006,1.539975e-008,0.000000e+000,0.000000e+000,2,9.423859e-001,1.825000e+000,,,,,,,,,,,,,,,,,,0,3.000000e+000,1.000000e+000,10,5,2.288818e-002,0,,0,
1616170057.805,,2.000000e+003,3.000044e+002,-6.573783e-006,2.773288e-008,0.000000e+000,0.000000e+000,2,9.386064e-001,1.825000e+000,,,,,,,,,,,,,,,,,,0,3.000000e+000,1.000000e+000,10,5,2.288818e-002,0,,0,
1616170301.977,,1.500000e+003,2.999952e+002,-4.563549e-006,2.849157e-008,0.000000e+000,0.000000e+000,2,9.365639e-001,1.825000e+000,,,,,,,,,,,,,,,,,,0,3.000000e+000,1.000000e+000,10,5,0.000000e+000,0,,0,
1616170536.069,,1.000000e+003,2.999975e+002,-2.624349e-006,2.429911e-008,0.000000e+000,0.000000e+000,2,9.247915e-001,1.825000e+000,,,,,,,,,,,,,,,,,,0,3.000000e+000,1.000000e+000,10,5,1.150513e-002,0,,0,
1616170722.875,,8.000000e+002,3.000010e+002,-1.926526e-006,2.378785e-008,0.000000e+000,0.000000e+000,2,9.111065e-001,1.825000e+000,,,,,,,,,,,,,,,,,,0,3.000000e+000,1.000000e+000,10,5,1.150513e-002,0,,0,
1616170909.938,,6.000000e+002,3.000009e+002,-1.216579e-006,4.058809e-008,0.000000e+000,0.000000e+000,2,8.893619e-001,1.825000e+000,,,,,,,,,,,,,,,,,,0,3.000000e+000,1.000000e+000,10,5,1.150513e-002,0,,0,
1616171096.679,,4.000000e+002,2.999987e+002,-5.635875e-007,5.617095e-008,0.000000e+000,0.000000e+000,2,7.526917e-001,1.825000e+000,,,,,,,,,,,,,,,,,,0,3.000000e+000,1.000000e+000,10,5,1.150513e-002,0,,0,
1616171282.567,,2.000000e+002,2.999918e+002,-8.439231e-007,1.955817e-006,0.000000e+000,0.000000e+000,2,0.000000e+000,1.825000e+000,,,,,,,,,,,,,,,,,,0,3.000000e+000,1.000000e+000,10,5,1.150513e-002,0,,0,
1616171475.789,,0.000000e+000,3.000010e+002,4.228785e-007,3.274575e-008,0.000000e+000,0.000000e+000,2,7.136405e-001,1.825000e+000,,,,,,,,,,,,,,,,,,0,3.000000e+000,1.000000e+000,10,5,1.150513e-002,0,,0,
1616171662.101,,-2.000000e+002,2.999998e+002,5.887954e-007,2.355234e-008,0.000000e+000,0.000000e+000,2,8.271719e-001,1.825000e+000,,,,,,,,,,,,,,,,,,0,3.000000e+000,1.000000e+000,10,5,1.150513e-002,0,,0,
1616171854.975,,-4.000000e+002,3.000009e+002,9.361727e-007,3.730776e-008,0.000000e+000,0.000000e+000,2,8.864955e-001,1.825000e+000,,,,,,,,,,,,,,,,,,0,3.000000e+000,1.000000e+000,10,5,1.150513e-002,0,,0,
1616172041.389,,-6.000000e+002,3.000033e+002,1.498257e-006,5.626228e-008,0.000000e+000,0.000000e+000,2,8.940384e-001,1.825000e+000,,,,,,,,,,,,,,,,,,0,3.000000e+000,1.000000e+000,10,5,1.150513e-002,0,,0,
1616172228.010,,-8.000000e+002,2.999998e+002,2.163067e-006,2.261635e-008,0.000000e+000,0.000000e+000,2,9.061456e-001,1.825000e+000,,,,,,,,,,,,,,,,,,0,3.000000e+000,1.000000e+000,10,5,1.150513e-002,0,,0,
1616172420.641,,-1.000000e+003,2.999987e+002,2.860420e-006,1.784168e-008,0.000000e+000,0.000000e+000,2,9.274554e-001,1.825000e+000,,,,,,,,,,,,,,,,,,0,3.000000e+000,1.000000e+000,10,5,1.150513e-002,0,,0,
1616172617.878,,-1.500000e+003,3.000021e+002,4.736944e-006,4.002652e-009,0.000000e+000,0.000000e+000,2,9.410437e-001,1.825000e+000,,,,,,,,,,,,,,,,,,0,3.000000e+000,1.000000e+000,10,5,1.150513e-002,0,,0,
1616172813.591,,-2.000000e+003,2.999987e+002,6.510109e-006,4.911227e-007,0.000000e+000,0.000000e+000,2,8.710159e-001,1.825000e+000,,,,,,,,,,,,,,,,,,0,3.000000e+000,1.000000e+000,10,5,1.150513e-002,0,,0,
1616173010.515,,-2.500000e+003,2.999918e+002,8.767866e-006,2.109436e-008,0.000000e+000,0.000000e+000,2,9.416909e-001,1.825000e+000,,,,,,,,,,,,,,,,,,0,3.000000e+000,1.000000e+000,10,5,2.301025e-002,0,,0,
1616173206.743,,-3.000000e+003,2.999998e+002,1.084335e-005,1.988986e-008,0.000000e+000,0.000000e+000,2,9.381850e-001,1.825000e+000,,,,,,,,,,,,,,,,,,0,3.000000e+000,1.000000e+000,10,5,1.150513e-002,0,,0,
1616173402.626,,-3.500000e+003,2.999987e+002,1.297262e-005,2.910870e-008,0.000000e+000,0.000000e+000,2,9.387845e-001,1.825000e+000,,,,,,,,,,,,,,,,,,0,3.000000e+000,1.000000e+000,10,5,1.150513e-002,0,,0,
1616173598.193,,-4.000000e+003,2.999998e+002,1.542296e-005,7.173034e-007,0.000000e+000,0.000000e+000,2,8.520185e-001,1.825000e+000,,,,,,,,,,,,,,,,,,0,3.000000e+000,1.000000e+000,10,5,1.150513e-002,0,,0,
1616173805.587,,-5.000000e+003,3.000044e+002,1.936436e-005,2.837715e-008,0.000000e+000,0.000000e+000,2,9.403052e-001,1.825000e+000,,,,,,,,,,,,,,,,,,0,3.000000e+000,1.000000e+000,10,5,1.150513e-002,0,,0,
1616174023.178,,-6.000000e+003,2.999987e+002,2.365373e-005,2.642301e-008,0.000000e+000,0.000000e+000,2,9.405510e-001,1.825000e+000,,,,,,,,,,,,,,,,,,0,3.000000e+000,1.000000e+000,10,5,1.150513e-002,0,,0,
1616174222.203,,-7.000000e+003,2.999998e+002,2.797678e-005,1.745872e-008,0.000000e+000,0.000000e+000,2,9.396226e-001,1.825000e+000,,,,,,,,,,,,,,,,,,0,3.000000e+000,1.000000e+000,10,5,2.301025e-002,0,,0,
1616174408.787,,-8.000000e+003,2.999987e+002,3.226653e-005,1.476382e-008,0.000000e+000,0.000000e+000,2,9.401845e-001,1.825000e+000,,,,,,,,,,,,,,,,,,0,3.000000e+000,1.000000e+000,10,5,1.150513e-002,0,,0,
1616174590.410,,-9.000000e+003,3.000021e+002,3.660737e-005,2.803869e-008,0.000000e+000,0.000000e+000,2,9.396918e-001,1.825000e+000,,,,,,,,,,,,,,,,,,0,3.000000e+000,1.000000e+000,10,5,1.150513e-002,0,,0,
1616174771.190,,-1.000000e+004,2.999998e+002,4.094303e-005,1.873794e-008,0.000000e+000,0.000000e+000,2,9.404127e-001,1.825000e+000,,,,,,,,,,,,,,,,,,0,3.000000e+000,1.000000e+000,10,5,2.301025e-002,0,,0,
1616174962.901,,-1.200000e+004,3.000021e+002,4.961086e-005,1.132195e-008,0.000000e+000,0.000000e+000,2,9.397090e-001,1.825000e+000,,,,,,,,,,,,,,,,,,0,3.000000e+000,1.000000e+000,10,5,1.150513e-002,0,,0,
1616175155.076,,-1.400000e+004,2.999998e+002,5.830994e-005,1.506843e-008,0.000000e+000,0.000000e+000,2,9.395282e-001,1.825000e+000,,,,,,,,,,,,,,,,,,0,3.000000e+000,1.000000e+000,10,5,1.150513e-002,0,,0,
1616175347.712,,-1.600000e+004,2.999987e+002,6.700826e-005,3.486312e-008,0.000000e+000,0.000000e+000,2,9.390393e-001,1.825000e+000,,,,,,,,,,,,,,,,,,0,3.000000e+000,1.000000e+000,10,5,1.150513e-002,0,,0,
1616175568.510,,-1.800000e+004,2.999975e+002,7.574465e-005,2.297165e-008,0.000000e+000,0.000000e+000,2,9.389024e-001,1.825000e+000,,,,,,,,,,,,,,,,,,0,3.000000e+000,1.000000e+000,10,5,2.301025e-002,0,,0,
1616175755.585,,-2.000000e+004,2.999941e+002,8.447695e-005,2.777421e-008,0.000000e+000,0.000000e+000,2,9.390226e-001,1.825000e+000,,,,,,,,,,,,,,,,,,0,3.000000e+000,1.000000e+000,10,5,2.301025e-002,0,,0,
1616175963.818,,-2.500000e+004,2.999964e+002,1.062599e-004,2.311322e-008,0.000000e+000,0.000000e+000,2,9.384921e-001,1.825000e+000,,,,,,,,,,,,,,,,,,0,3.000000e+000,1.000000e+000,10,5,2.301025e-002,0,,0,
1616176171.806,,-3.000000e+004,2.999952e+002,1.281001e-004,1.792398e-008,0.000000e+000,0.000000e+000,2,9.387879e-001,1.825000e+000,,,,,,,,,,,,,,,,,,0,3.000000e+000,1.000000e+000,10,5,2.301025e-002,0,,0,
1616176381.290,,-3.500000e+004,2.999975e+002,1.499570e-004,3.446806e-008,0.000000e+000,0.000000e+000,2,9.387727e-001,1.825000e+000,,,,,,,,,,,,,,,,,,0,3.000000e+000,1.000000e+000,10,5,1.150513e-002,0,,0,
1616176592.550,,-4.000000e+004,3.000021e+002,1.718017e-004,6.714773e-008,0.000000e+000,0.000000e+000,2,9.384156e-001,1.825000e+000,,,,,,,,,,,,,,,,,,0,3.000000e+000,1.000000e+000,10,5,1.150513e-002,0,,0,
1616176803.722,,-4.500000e+004,2.999998e+002,1.937034e-004,3.449212e-008,0.000000e+000,0.000000e+000,2,9.385067e-001,1.825000e+000,,,,,,,,,,,,,,,,,,0,3.000000e+000,1.000000e+000,10,5,1.150513e-002,0,,0,
1616177016.629,,-5.000000e+004,3.000010e+002,2.156018e-004,3.920417e-008,0.000000e+000,0.000000e+000,2,9.383788e-001,1.825000e+000,,,,,,,,,,,,,,,,,,0,3.000000e+000,1.000000e+000,10,5,1.150513e-002,0,,0,
1616177248.310,,-4.500000e+004,2.999964e+002,1.937064e-004,5.835574e-008,0.000000e+000,0.000000e+000,2,9.386094e-001,1.825000e+000,,,,,,,,,,,,,,,,,,0,3.000000e+000,1.000000e+000,10,5,1.150513e-002,0,,0,
1616177457.563,,-4.000000e+004,2.999987e+002,1.717665e-004,5.759056e-008,0.000000e+000,0.000000e+000,2,9.386669e-001,1.825000e+000,,,,,,,,,,,,,,,,,,0,3.000000e+000,1.000000e+000,10,5,1.150513e-002,0,,0,
1616177666.029,,-3.500000e+004,2.999987e+002,1.499265e-004,2.464682e-008,0.000000e+000,0.000000e+000,2,9.390241e-001,1.825000e+000,,,,,,,,,,,,,,,,,,0,3.000000e+000,1.000000e+000,10,5,1.150513e-002,0,,0,
1616177873.143,,-3.000000e+004,3.000009e+002,1.280701e-004,4.033357e-008,0.000000e+000,0.000000e+000,2,9.392473e-001,1.825000e+000,,,,,,,,,,,,,,,,,,0,3.000000e+000,1.000000e+000,10,5,2.301025e-002,0,,0,
1616178079.433,,-2.500000e+004,2.999987e+002,1.062349e-004,3.388506e-008,0.000000e+000,0.000000e+000,2,9.392375e-001,1.825000e+000,,,,,,,,,,,,,,,,,,0,3.000000e+000,1.000000e+000,10,5,2.301025e-002,0,,0,
1616178291.939,,-2.000000e+004,2.999998e+002,8.440748e-005,2.414748e-008,0.000000e+000,0.000000e+000,2,9.389889e-001,1.825000e+000,,,,,,,,,,,,,,,,,,0,3.000000e+000,1.000000e+000,10,5,1.150513e-002,0,,0,
1616178483.953,,-1.800000e+004,2.999987e+002,7.565303e-005,3.961124e-008,0.000000e+000,0.000000e+000,2,9.394008e-001,1.825000e+000,,,,,,,,,,,,,,,,,,0,3.000000e+000,1.000000e+000,10,5,1.150513e-002,0,,0,
1616178676.818,,-1.600000e+004,2.999975e+002,6.697418e-005,2.076892e-008,0.000000e+000,0.000000e+000,2,9.395105e-001,1.825000e+000,,,,,,,,,,,,,,,,,,0,3.000000e+000,1.000000e+000,10,5,1.150513e-002,0,,0,
1616178867.785,,-1.400000e+004,3.000033e+002,5.824635e-005,2.667710e-008,0.000000e+000,0.000000e+000,2,9.397145e-001,1.825000e+000,,,,,,,,,,,,,,,,,,0,3.000000e+000,1.000000e+000,10,5,1.150513e-002,0,,0,
1616179053.627,,-1.200000e+004,2.999998e+002,4.954158e-005,1.157266e-008,0.000000e+000,0.000000e+000,2,9.396163e-001,1.825000e+000,,,,,,,,,,,,,,,,,,0,3.000000e+000,1.000000e+000,10,5,2.301025e-002,0,,0,
1616179245.003,,-1.000000e+004,3.000009e+002,4.083194e-005,1.811756e-008,0.000000e+000,0.000000e+000,2,9.389742e-001,1.825000e+000,,,,,,,,,,,,,,,,,,0,3.000000e+000,1.000000e+000,10,5,1.150513e-002,0,,0,
1616179439.140,,-9.000000e+003,3.000010e+002,3.651003e-005,1.278583e-008,0.000000e+000,0.000000e+000,2,9.395446e-001,1.825000e+000,,,,,,,,,,,,,,,,,,0,3.000000e+000,1.000000e+000,10,5,1.150513e-002,0,,0,
1616179625.190,,-8.000000e+003,2.999964e+002,3.218021e-005,1.708824e-008,0.000000e+000,0.000000e+000,2,9.395757e-001,1.825000e+000,,,,,,,,,,,,,,,,,,0,3.000000e+000,1.000000e+000,10,5,2.301025e-002,0,,0,
1616179823.974,,-7.000000e+003,2.999964e+002,2.785448e-005,1.284760e-008,0.000000e+000,0.000000e+000,2,9.400095e-001,1.825000e+000,,,,,,,,,,,,,,,,,,0,3.000000e+000,1.000000e+000,10,5,2.301025e-002,0,,0,
1616180030.732,,-6.000000e+003,3.000056e+002,2.354315e-005,4.654843e-009,0.000000e+000,0.000000e+000,2,9.395409e-001,1.825000e+000,,,,,,,,,,,,,,,,,,0,3.000000e+000,1.000000e+000,10,5,1.150513e-002,0,,0,
1616180230.094,,-5.000000e+003,2.999964e+002,1.923192e-005,1.868161e-008,0.000000e+000,0.000000e+000,2,9.398124e-001,1.825000e+000,,,,,,,,,,,,,,,,,,0,3.000000e+000,1.000000e+000,10,5,2.301025e-002,0,,0,
1616180427.991,,-4.000000e+003,2.999929e+002,1.496869e-005,3.316094e-008,0.000000e+000,0.000000e+000,2,9.415242e-001,1.825000e+000,,,,,,,,,,,,,,,,,,0,3.000000e+000,1.000000e+000,10,5,2.301025e-002,0,,0,
1616180668.064,,-3.500000e+003,2.999941e+002,1.284304e-005,8.667260e-009,0.000000e+000,0.000000e+000,2,9.398065e-001,1.825000e+000,,,,,,,,,,,,,,,,,,0,3.000000e+000,1.000000e+000,10,5,2.301025e-002,0,,0,
1616180913.670,,-3.000000e+003,2.999998e+002,1.072419e-005,1.355093e-008,0.000000e+000,0.000000e+000,2,9.406700e-001,1.825000e+000,,,,,,,,,,,,,,,,,,0,3.000000e+000,1.000000e+000,10,5,1.150513e-002,0,,0,
1616181144.718,,-2.500000e+003,2.999975e+002,8.637894e-006,3.678210e-008,0.000000e+000,0.000000e+000,2,9.394566e-001,1.825000e+000,,,,,,,,,,,,,,,,,,0,3.000000e+000,1.000000e+000,10,5,2.301025e-002,0,,0,
1616181380.169,,-2.000000e+003,2.999998e+002,6.571956e-006,1.038286e-008,0.000000e+000,0.000000e+000,2,9.365696e-001,1.825000e+000,,,,,,,,,,,,,,,,,,0,3.000000e+000,1.000000e+000,10,5,1.150513e-002,0,,0,
1616181638.092,,-1.500000e+003,3.000044e+002,4.559033e-006,2.925451e-008,0.000000e+000,0.000000e+000,2,9.368137e-001,1.825000e+000,,,,,,,,,,,,,,,,,,0,3.000000e+000,1.000000e+000,10,5,2.288818e-002,0,,0,
1616181868.122,,-1.000000e+003,3.000010e+002,2.594405e-006,2.485634e-008,0.000000e+000,0.000000e+000,2,9.368385e-001,1.825000e+000,,,,,,,,,,,,,,,,,,0,3.000000e+000,1.000000e+000,10,5,1.150513e-002,0,,0,
1616182080.345,,-8.000000e+002,2.999952e+002,1.947288e-006,4.230524e-008,0.000000e+000,0.000000e+000,2,9.314688e-001,1.825000e+000,,,,,,,,,,,,,,,,,,0,3.000000e+000,1.000000e+000,10,5,2.301025e-002,0,,0,
1616182267.436,,-6.000000e+002,2.999998e+002,1.200159e-006,4.703151e-008,0.000000e+000,0.000000e+000,2,8.935158e-001,1.825000e+000,,,,,,,,,,,,,,,,,,0,3.000000e+000,1.000000e+000,10,5,1.150513e-002,0,,0,
1616182455.474,,-4.000000e+002,2.999987e+002,5.316400e-007,2.130690e-008,0.000000e+000,0.000000e+000,2,8.069780e-001,1.825000e+000,,,,,,,,,,,,,,,,,,0,3.000000e+000,1.000000e+000,10,5,1.150513e-002,0,,0,
1616182649.276,,-2.000000e+002,3.000010e+002,-2.506611e-008,2.316322e-008,0.000000e+000,0.000000e+000,2,0.000000e+000,1.825000e+000,,,,,,,,,,,,,,,,,,0,3.000000e+000,1.000000e+000,10,5,1.150513e-002,0,,0,
1616182843.267,,0.000000e+000,2.999952e+002,-4.114811e-007,3.434174e-008,0.000000e+000,0.000000e+000,2,7.371329e-001,1.825000e+000,,,,,,,,,,,,,,,,,,0,3.000000e+000,1.000000e+000,10,5,2.301025e-002,0,,0,
1616183029.664,,2.000000e+002,2.999941e+002,-5.635193e-007,2.069716e-008,0.000000e+000,0.000000e+000,2,7.485670e-001,1.825000e+000,,,,,,,,,,,,,,,,,,0,3.000000e+000,1.000000e+000,10,5,2.301025e-002,0,,0,
1616183224.278,,4.000000e+002,2.999975e+002,-9.502380e-007,1.679459e-008,0.000000e+000,0.000000e+000,2,9.002677e-001,1.825000e+000,,,,,,,,,,,,,,,,,,0,3.000000e+000,1.000000e+000,10,5,1.150513e-002,0,,0,
1616183411.061,,6.000000e+002,3.000032e+002,-1.473825e-006,3.005705e-008,0.000000e+000,0.000000e+000,2,8.907635e-001,1.825000e+000,,,,,,,,,,,,,,,,,,0,3.000000e+000,1.000000e+000,10,5,2.288818e-002,0,,0,
1616183597.769,,8.000000e+002,2.999998e+002,-2.167978e-006,4.434786e-008,0.000000e+000,0.000000e+000,2,9.355525e-001,1.825000e+000,,,,,,,,,,,,,,,,,,0,3.000000e+000,1.000000e+000,10,5,1.150513e-002,0,,0,
1616183790.262,,1.000000e+003,2.999941e+002,-2.853514e-006,1.817135e-008,0.000000e+000,0.000000e+000,2,9.175171e-001,1.825000e+000,,,,,,,,,,,,,,,,,,0,3.000000e+000,1.000000e+000,10,5,2.301025e-002,0,,0,
1616183999.747,,1.500000e+003,2.999987e+002,-4.731918e-006,1.118011e-008,0.000000e+000,0.000000e+000,2,9.381098e-001,1.825000e+000,,,,,,,,,,,,,,,,,,0,3.000000e+000,1.000000e+000,10,5,2.301025e-002,0,,0,
1616184220.145,,2.000000e+003,2.999998e+002,-6.723106e-006,7.711465e-009,0.000000e+000,0.000000e+000,2,9.401410e-001,1.825000e+000,,,,,,,,,,,,,,,,,,0,3.000000e+000,1.000000e+000,10,5,1.150513e-002,0,,0,
1616184409.041,,2.500000e+003,3.000021e+002,-8.767217e-006,2.710500e-008,0.000000e+000,0.000000e+000,2,9.405926e-001,1.825000e+000,,,,,,,,,,,,,,,,,,0,3.000000e+000,1.000000e+000,10,5,1.150513e-002,0,,0,
1616184605.406,,3.000000e+003,3.000010e+002,-1.086911e-005,3.574835e-008,0.000000e+000,0.000000e+000,2,9.403512e-001,1.825000e+000,,,,,,,,,,,,,,,,,,0,3.000000e+000,1.000000e+000,10,5,1.150513e-002,0,,0,
1616184801.509,,3.500000e+003,2.999964e+002,-1.298331e-005,3.629059e-008,0.000000e+000,0.000000e+000,2,9.385207e-001,1.825000e+000,,,,,,,,,,,,,,,,,,0,3.000000e+000,1.000000e+000,10,5,2.301025e-002,0,,0,
1616184998.755,,4.000000e+003,2.999998e+002,-1.509096e-005,3.400142e-008,0.000000e+000,0.000000e+000,2,9.379746e-001,1.825000e+000,,,,,,,,,,,,,,,,,,0,3.000000e+000,1.000000e+000,10,5,1.150513e-002,0,,0,
1616185206.410,,5.000000e+003,3.000044e+002,-1.935898e-005,4.632433e-008,0.000000e+000,0.000000e+000,2,9.381295e-001,1.825000e+000,,,,,,,,,,,,,,,,,,0,3.000000e+000,1.000000e+000,10,5,2.288818e-002,0,,0,
1616185398.471,,6.000000e+003,3.000010e+002,-2.362999e-005,1.833622e-008,0.000000e+000,0.000000e+000,2,9.392423e-001,1.825000e+000,,,,,,,,,,,,,,,,,,0,3.000000e+000,1.000000e+000,10,5,1.150513e-002,0,,0,
1616185597.175,,7.000000e+003,3.000010e+002,-2.795873e-005,1.506533e-008,0.000000e+000,0.000000e+000,2,9.386533e-001,1.825000e+000,,,,,,,,,,,,,,,,,,0,3.000000e+000,1.000000e+000,10,5,1.150513e-002,0,,0,
1616185814.003,,8.000000e+003,3.000010e+002,-3.225211e-005,1.693861e-008,0.000000e+000,0.000000e+000,2,9.385050e-001,1.825000e+000,,,,,,,,,,,,,,,,,,0,3.000000e+000,1.000000e+000,10,5,1.150513e-002,0,,0,
1616186022.285,,9.000000e+003,2.999952e+002,-3.660315e-005,1.588875e-008,0.000000e+000,0.000000e+000,2,9.388351e-001,1.825000e+000,,,,,,,,,,,,,,,,,,0,3.000000e+000,1.000000e+000,10,5,0.000000e+000,0,,0,
1616186202.495,,1.000000e+004,3.000021e+002,-4.091254e-005,2.227691e-008,0.000000e+000,0.000000e+000,2,9.387958e-001,1.825000e+000,,,,,,,,,,,,,,,,,,0,3.000000e+000,1.000000e+000,10,5,1.150513e-002,0,,0,
1616186394.244,,1.200000e+004,3.000021e+002,-4.961254e-005,1.934923e-008,0.000000e+000,0.000000e+000,2,9.384596e-001,1.825000e+000,,,,,,,,,,,,,,,,,,0,3.000000e+000,1.000000e+000,10,5,1.150513e-002,0,,0,
1616186585.726,,1.400000e+004,2.999975e+002,-5.830300e-005,2.699499e-008,0.000000e+000,0.000000e+000,2,9.380821e-001,1.825000e+000,,,,,,,,,,,,,,,,,,0,3.000000e+000,1.000000e+000,10,5,1.150513e-002,0,,0,
1616186777.538,,1.600000e+004,3.000021e+002,-6.698845e-005,3.330725e-008,0.000000e+000,0.000000e+000,2,9.383212e-001,1.825000e+000,,,,,,,,,,,,,,,,,,0,3.000000e+000,1.000000e+000,10,5,1.150513e-002,0,,0,
1616186970.085,,1.800000e+004,2.999941e+002,-7.571811e-005,2.263470e-008,0.000000e+000,0.000000e+000,2,9.381800e-001,1.825000e+000,,,,,,,,,,,,,,,,,,0,3.000000e+000,1.000000e+000,10,5,2.301025e-002,0,,0,
1616187163.019,,2.000000e+004,2.999987e+002,-8.442839e-005,1.371341e-008,0.000000e+000,0.000000e+000,2,9.377295e-001,1.825000e+000,,,,,,,,,,,,,,,,,,0,3.000000e+000,1.000000e+000,10,5,2.301025e-002,0,,0,
1616187386.738,,2.500000e+004,2.999998e+002,-1.062314e-004,2.051399e-008,0.000000e+000,0.000000e+000,2,9.378329e-001,1.825000e+000,,,,,,,,,,,,,,,,,,0,3.000000e+000,1.000000e+000,10,5,1.150513e-002,0,,0,
1616187594.369,,3.000000e+004,2.999987e+002,-1.280961e-004,2.213058e-008,0.000000e+000,0.000000e+000,2,9.377889e-001,1.825000e+000,,,,,,,,,,,,,,,,,,0,3.000000e+000,1.000000e+000,10,5,1.150513e-002,0,,0,
1616187797.261,,3.500000e+004,3.000010e+002,-1.499503e-004,4.975400e-008,0.000000e+000,0.000000e+000,2,9.378154e-001,1.825000e+000,,,,,,,,,,,,,,,,,,0,3.000000e+000,1.000000e+000,10,5,1.150513e-002,0,,0,
1616188001.145,,4.000000e+004,2.999975e+002,-1.717808e-004,5.734318e-008,0.000000e+000,0.000000e+000,2,9.377451e-001,1.825000e+000,,,,,,,,,,,,,,,,,,0,3.000000e+000,1.000000e+000,10,5,1.150513e-002,0,,0,
1616188206.749,,4.500000e+004,2.999998e+002,-1.936453e-004,3.724923e-008,0.000000e+000,0.000000e+000,2,9.375416e-001,1.825000e+000,,,,,,,,,,,,,,,,,,0,3.000000e+000,1.000000e+000,10,5,2.288818e-002,0,,0,
1616188412.533,,5.000000e+004,3.000033e+002,-2.154985e-004,3.119788e-008,0.000000e+000,0.000000e+000,2,9.375009e-001,1.825000e+000,,,,,,,,,,,,,,,,,,0,3.000000e+000,1.000000e+000,10,5,1.150513e-002,0,,0,