File: SiC2/Temperature Dependence/SiC2_temp_dep.rso.raw
[Header]
TITLE,MPMS RSO Measurement
BYAPP,MPMS Measurement,2.1,Raw with ABS
FILEOPENTIME, 1616222331.431000 3/20/2021, 7:38:51 AM

INFO, APPNAME, MPMS MultiVu Application, Revision 1.61,  Build 082

INFO, NAME,
INFO, WEIGHT, 1.000
INFO, AREA, 1.000
INFO, LENGTH, 1.000
INFO, SHAPE, 0
INFO, COMMENT,
INFO, SEQUENCE FILE: SiC_measuring_sequence.seq


INFO, BACKGROUND DATA FILE:, None


STARTUPAXIS,X,8,LINEAR,AUTO,0.000000,0.000000
STARTUPAXIS,Y1,9,LINEAR,AUTO,0.000000,0.000000


STARTUPGROUP,Longitudinal
FIELDGROUP,Longitudinal,1,2,3,4,5,6,7,8,9,10,11,12,13,14,15,16,17,18,19,20,21,22
FIELDGROUP,Transverse,1,2,3,4,5,6,7,8,23,24,25,26,27,28,29,30,31,32,33,34,35,36

PLOT_APPEARANCE,ALL,HORZ_GRID_ON,VERT_GRID_ON,MARKERS_ONLY

[Data]
Time,Comment,Field (Oe),Start Temperature (K),End Temperature (K),Scan,Rejected,Position (cm),Long Voltage,Long Average Voltage,Long Detrended Voltage,Long Demeaned Voltage,Long Reg Fit,Long Detrended Fit,Long Demeaned Fit,Long Scaled Response,Long Avg. Scaled Response,Long Background Response,Long Response [w/ABS],Long Detrended Resp. [w/ABS],Long Fit [w/ABS],Long Detrended Fit [w/ABS],Trans Voltage,Trans Average Voltage,Trans Detrended Voltage,Trans Demeaned Voltage,Trans Reg Fit,Trans Detrended Fit,Trans Demeaned Fit,Trans Scaled Response,Trans Avg. Scaled Response,Trans Background Response,Trans Response [w/ABS],Trans Detrended Resp. [w/ABS],Trans Adjusted Fit,Trans Detrended Fit [w/ABS],
1616222331.431,,1.000000e+003,5.007720e+000,5.004261e+000,1,0,2.066969e+000,4.115421e-001,,,,,,,1.014438e-005,,,,,,,,,,,,,,,,,,,,,
1616222331.431,,1.000000e+003,5.007720e+000,5.004261e+000,1,0,2.790666e+000,4.719688e-001,,,,,,,1.163387e-005,,,,,,,,,,,,,,,,,,,,,
1616222331.431,,1.000000e+003,5.004261e+000,5.002585e+000,2,0,3.336892e+000,5.839717e-001,,,,,,,1.439471e-005,,,,,,,,,,,,,,,,,,,,,
1616222331.431,,1.000000e+003,5.002585e+000,5.002481e+000,3,0,3.460785e+000,7.339702e-001,,,,,,,1.809212e-005,,,,,,,,,,,,,,,,,,,,,
1616222331.431,,1.000000e+003,5.002481e+000,5.001225e+000,4,0,2.969617e+000,3.817866e-001,,,,,,,9.410912e-006,,,,,,,,,,,,,,,,,,,,,
1616222331.431,,1.000000e+003,5.001225e+000,5.001330e+000,5,0,2.204340e+000,4.835658e-001,4.636677e-001,-1.323388e-001,-1.080609e-001,4.263768e-001,-1.696297e-001,-1.453518e-001,1.191974e-005,1.142926e-005,,,,,,,,,,,,,,,,,,,,
1616222599.699,,1.000000e+003,1.000125e+001,1.000693e+001,1,0,1.431816e+000,5.734428e-001,,,,,,,1.413517e-005,,,,,,,,,,,,,,,,,,,,,
1616222599.699,,1.000000e+003,1.000410e+001,1.000554e+001,2,0,8.221751e-001,7.458724e-001,,,,,,,1.838551e-005,,,,,,,,,,,,,,,,,,,,,
1616222599.699,,1.000000e+003,1.000554e+001,1.000507e+001,3,0,5.070081e-001,7.757805e-001,,,,,,,1.912273e-005,,,,,,,,,,,,,,,,,,,,,
1616222599.699,,1.000000e+003,1.000507e+001,1.000318e+001,4,0,8.195100e-001,7.026887e-001,,,,,,,1.732104e-005,,,,,,,,,,,,,,,,,,,,,
1616222599.699,,1.000000e+003,1.000318e+001,1.000175e+001,5,0,1.528367e+000,5.426191e-001,5.424055e-001,-8.404821e-002,-8.138067e-002,5.832662e-001,-4.318750e-002,-4.051995e-002,1.337538e-005,1.337011e-005,,,,,,,,,,,,,,,,,,,,
1616222599.699,,1.000000e+003,1.000318e+001,1.000175e+001,5,0,2.327304e+000,5.430769e-001,5.434736e-001,-1.216595e-001,-8.031255e-002,4.796734e-001,-1.854597e-001,-1.441127e-001,1.338666e-005,1.339644e-005,,,,,,,,,,,,,,,,,,,,
1616222866.556,,1.000000e+003,1.500302e+001,1.500615e+001,1,0,2.993827e+000,5.526902e-001,,,,,,,1.362363e-005,,,,,,,,,,,,,,,,,,,,,
1616222866.556,,1.000000e+003,1.500615e+001,1.500224e+001,2,0,3.448819e+000,7.048250e-001,,,,,,,1.737370e-005,,,,,,,,,,,,,,,,,,,,,
1616222866.556,,1.000000e+003,1.500224e+001,1.500224e+001,3,0,3.351674e+000,6.350902e-001,,,,,,,1.565476e-005,,,,,,,,,,,,,,,,,,,,,
1616222866.556,,1.000000e+003,1.500146e+001,1.499990e+001,4,0,2.730381e+000,4.847865e-001,,,,,,,1.194983e-005,,,,,,,,,,,,,,,,,,,,,
1616222866.556,,1.000000e+003,1.499990e+001,1.499911e+001,5,0,1.934305e+000,5.043184e-001,4.972991e-001,-1.403187e-001,-1.222135e-001,4.927643e-001,-1.448535e-001,-1.267483e-001,1.243128e-005,1.225826e-005,,,,,,,,,,,,,,,,,,,,
1616223132.429,,1.000000e+003,2.000028e+001,1.999960e+001,1,0,1.210527e+000,5.703909e-001,,,,,,,1.405995e-005,,,,,,,,,,,,,,,,,,,,,
1616223132.429,,1.000000e+003,1.999960e+001,1.999483e+001,2,0,6.643316e-001,6.927702e-001,,,,,,,1.707655e-005,,,,,,,,,,,,,,,,,,,,,
1616223132.429,,1.000000e+003,1.999483e+001,2.000028e+001,3,0,5.403325e-001,7.405316e-001,,,,,,,1.825386e-005,,,,,,,,,,,,,,,,,,,,,
1616223132.429,,1.000000e+003,2.000028e+001,2.000233e+001,4,0,1.031504e+000,6.166264e-001,,,,,,,1.519964e-005,,,,,,,,,,,,,,,,,,,,,
1616223132.429,,1.000000e+003,2.000233e+001,2.000233e+001,5,0,1.796834e+000,4.071169e-001,4.263131e-001,-1.462462e-001,-1.455116e-001,4.566171e-001,-1.159422e-001,-1.152075e-001,1.003530e-005,1.050847e-005,,,,,,,,,,,,,,,,,,,,
1616223132.429,,1.000000e+003,2.000233e+001,2.000233e+001,5,0,2.569252e+000,4.472488e-001,4.733421e-001,-1.205213e-001,-9.848258e-002,4.341410e-001,-1.597224e-001,-1.376837e-001,1.102453e-005,1.166772e-005,,,,,,,,,,,,,,,,,,,,
1616223399.513,,1.000000e+003,2.499935e+001,2.500555e+001,1,0,3.178983e+000,4.515213e-001,,,,,,,1.112985e-005,,,,,,,,,,,,,,,,,,,,,
1616223399.513,,1.000000e+003,2.500555e+001,2.500555e+001,2,0,3.494160e+000,6.227302e-001,,,,,,,1.535009e-005,,,,,,,,,,,,,,,,,,,,,
1616223399.513,,1.000000e+003,2.500555e+001,2.500452e+001,3,0,3.181684e+000,4.618977e-001,,,,,,,1.138562e-005,,,,,,,,,,,,,,,,,,,,,
1616223399.513,,1.000000e+003,2.500452e+001,2.500142e+001,4,0,2.472864e+000,3.547777e-001,,,,,,,8.745152e-006,,,,,,,,,,,,,,,,,,,,,
1616223399.513,,1.000000e+003,2.500245e+001,2.500142e+001,5,0,1.673911e+000,3.856014e-001,4.049196e-001,-1.120880e-001,-1.060536e-001,4.300831e-001,-8.692446e-002,-8.089009e-002,9.504945e-006,9.981133e-006,,,,,,,,,,,,,,,,,,,,
1616223672.446,,1.000000e+003,3.000099e+001,3.000099e+001,1,0,1.007348e+000,5.272073e-001,,,,,,,1.299548e-005,,,,,,,,,,,,,,,,,,,,,
1616223672.446,,1.000000e+003,3.000099e+001,3.000243e+001,2,0,5.523525e-001,5.917539e-001,,,,,,,1.458654e-005,,,,,,,,,,,,,,,,,,,,,
1616223672.446,,1.000000e+003,3.000243e+001,3.000099e+001,3,0,6.495872e-001,5.635243e-001,,,,,,,1.389069e-005,,,,,,,,,,,,,,,,,,,,,
1616223672.446,,1.000000e+003,3.000099e+001,3.000099e+001,4,0,1.270866e+000,4.741051e-001,,,,,,,1.168653e-005,,,,,,,,,,,,,,,,,,,,,
1616223672.446,,1.000000e+003,3.000099e+001,3.000099e+001,5,0,2.066937e+000,2.624592e-001,2.905973e-001,-1.724370e-001,-1.724370e-001,2.879879e-001,-1.750464e-001,-1.750464e-001,6.469531e-006,7.163126e-006,,,,,,,,,,,,,,,,,,,,
1616223672.446,,1.000000e+003,3.000099e+001,3.000099e+001,5,0,2.790642e+000,3.189184e-001,3.449812e-001,-1.199398e-001,-1.180530e-001,3.549134e-001,-1.100076e-001,-1.081209e-001,7.861233e-006,8.503673e-006,,,,,,,,,,,,,,,,,,,,
1616223957.392,,1.000000e+003,3.500077e+001,3.500230e+001,1,0,3.336918e+000,3.802606e-001,,,,,,,9.373298e-006,,,,,,,,,,,,,,,,,,,,,
1616223957.392,,1.000000e+003,3.500230e+001,3.500077e+001,2,0,3.460822e+000,4.420606e-001,,,,,,,1.089665e-005,,,,,,,,,,,,,,,,,,,,,
1616223957.392,,1.000000e+003,3.500077e+001,3.500385e+001,3,0,2.969624e+000,2.775658e-001,,,,,,,6.841906e-006,,,,,,,,,,,,,,,,,,,,,
1616223957.392,,1.000000e+003,3.500000e+001,3.500230e+001,4,0,2.204367e+000,2.989288e-001,,,,,,,7.368496e-006,,,,,,,,,,,,,,,,,,,,,
1616223957.392,,1.000000e+003,3.500230e+001,3.500077e+001,5,0,1.431919e+000,3.138829e-001,3.444624e-001,-5.544665e-002,-5.924553e-002,3.713671e-001,-2.854198e-002,-3.234085e-002,7.737108e-006,8.490884e-006,,,,,,,,,,,,,,,,,,,,
1616224253.171,,1.000000e+003,4.000579e+001,3.999889e+001,1,0,8.222055e-001,4.416028e-001,,,,,,,1.088536e-005,,,,,,,,,,,,,,,,,,,,,
1616224253.171,,1.000000e+003,3.999889e+001,4.000185e+001,2,0,5.070262e-001,4.911954e-001,,,,,,,1.210780e-005,,,,,,,,,,,,,,,,,,,,,
1616224253.171,,1.000000e+003,4.000185e+001,3.999987e+001,3,0,8.195266e-001,4.361095e-001,,,,,,,1.074995e-005,,,,,,,,,,,,,,,,,,,,,
1616224253.171,,1.000000e+003,3.999987e+001,4.000087e+001,4,0,1.528317e+000,2.606281e-001,,,,,,,6.424395e-006,,,,,,,,,,,,,,,,,,,,,
1616224253.171,,1.000000e+003,3.999987e+001,4.000087e+001,4,0,2.327245e+000,2.171392e-001,,,,,,,5.352409e-006,,,,,,,,,,,,,,,,,,,,,
1616224253.171,,1.000000e+003,4.000087e+001,4.000087e+001,5,0,2.993823e+000,2.398755e-001,2.417066e-001,-1.030259e-001,-1.150767e-001,2.857730e-001,-5.895942e-002,-7.101023e-002,5.912851e-006,5.957987e-006,,,,,,,,,,,,,,,,,,,,
1616224553.500,,1.000000e+003,4.500353e+001,4.500230e+001,1,0,3.448875e+000,3.714103e-001,,,,,,,9.155139e-006,,,,,,,,,,,,,,,,,,,,,
1616224553.500,,1.000000e+003,4.500230e+001,4.500353e+001,2,0,3.351605e+000,3.141881e-001,,,,,,,7.744631e-006,,,,,,,,,,,,,,,,,,,,,
1616224553.500,,1.000000e+003,4.500353e+001,4.500230e+001,3,0,2.730316e+000,1.825007e-001,,,,,,,4.498581e-006,,,,,,,,,,,,,,,,,,,,,
1616224553.500,,1.000000e+003,4.500230e+001,4.500230e+001,4,0,1.934225e+000,1.513718e-001,,,,,,,3.731265e-006,,,,,,,,,,,,,,,,,,,,,
1616224553.500,,1.000000e+003,4.500107e+001,4.500107e+001,5,0,1.210528e+000,2.949614e-001,3.181249e-001,5.001547e-003,-3.842622e-003,3.329259e-001,1.980254e-002,1.095837e-002,7.270700e-006,7.841674e-006,,,,,,,,,,,,,,,,,,,,
1616224837.284,,1.000000e+003,5.001512e+001,5.001065e+001,1,0,6.642295e-001,4.455702e-001,,,,,,,1.098316e-005,,,,,,,,,,,,,,,,,,,,,
1616224837.284,,1.000000e+003,5.001065e+001,5.000616e+001,2,0,5.403839e-001,4.545732e-001,,,,,,,1.120508e-005,,,,,,,,,,,,,,,,,,,,,
1616224837.284,,1.000000e+003,5.000616e+001,5.000169e+001,3,0,1.031629e+000,3.445539e-001,,,,,,,8.493141e-006,,,,,,,,,,,,,,,,,,,,,
1616224837.284,,1.000000e+003,5.000169e+001,5.000021e+001,4,0,1.796916e+000,1.747185e-001,,,,,,,4.306752e-006,,,,,,,,,,,,,,,,,,,,,
1616224837.284,,1.000000e+003,5.000169e+001,5.000021e+001,4,0,2.569323e+000,1.837214e-001,,,,,,,4.528672e-006,,,,,,,,,,,,,,,,,,,,,
1616224837.284,,1.000000e+003,5.000021e+001,5.000169e+001,5,0,3.179023e+000,2.603229e-001,2.449110e-001,-6.210998e-002,-8.361536e-002,2.926165e-001,-1.440454e-002,-3.590992e-002,6.416873e-006,6.036976e-006,,,,,,,,,,,,,,,,,,,,
1616225112.618,,1.000000e+003,5.502612e+001,5.501722e+001,1,0,3.494142e+000,3.433332e-001,,,,,,,8.463050e-006,,,,,,,,,,,,,,,,,,,,,
1616225112.618,,1.000000e+003,5.501722e+001,5.501188e+001,2,0,3.181527e+000,2.221747e-001,,,,,,,5.476534e-006,,,,,,,,,,,,,,,,,,,,,
1616225112.618,,1.000000e+003,5.501188e+001,5.501009e+001,3,0,2.472742e+000,1.263466e-001,,,,,,,3.114402e-006,,,,,,,,,,,,,,,,,,,,,
1616225112.618,,1.000000e+003,5.501009e+001,5.500653e+001,4,0,1.673822e+000,1.641896e-001,,,,,,,4.047219e-006,,,,,,,,,,,,,,,,,,,,,
1616225112.618,,1.000000e+003,5.500653e+001,5.500121e+001,5,0,1.007259e+000,3.039643e-001,3.334757e-001,5.539278e-002,4.403707e-002,3.347651e-001,5.668217e-002,4.532647e-002,7.492620e-006,8.220067e-006,,,,,,,,,,,,,,,,,,,,
1616225427.433,,1.000000e+003,6.003188e+001,6.002350e+001,1,0,5.522763e-001,3.674428e-001,,,,,,,9.057344e-006,,,,,,,,,,,,,,,,,,,,,
1616225427.433,,1.000000e+003,6.002350e+001,6.001511e+001,2,0,6.496577e-001,3.765984e-001,,,,,,,9.283025e-006,,,,,,,,,,,,,,,,,,,,,
1616225427.433,,1.000000e+003,6.001511e+001,6.000672e+001,3,0,1.270995e+000,2.606281e-001,,,,,,,6.424395e-006,,,,,,,,,,,,,,,,,,,,,
1616225427.433,,1.000000e+003,6.000043e+001,6.000043e+001,4,0,2.067009e+000,8.987702e-002,,,,,,,2.215438e-006,,,,,,,,,,,,,,,,,,,,,
1616225427.433,,1.000000e+003,6.000043e+001,6.000043e+001,4,0,2.790704e+000,1.187170e-001,,,,,,,2.926335e-006,,,,,,,,,,,,,,,,,,,,,
1616225427.433,,1.000000e+003,6.000043e+001,6.000463e+001,5,0,3.336951e+000,2.183599e-001,2.329173e-001,-4.807810e-003,-3.123938e-002,2.572539e-001,1.952881e-002,-6.902754e-003,5.382500e-006,5.741333e-006,,,,,,,,,,,,,,,,,,,,
1616225711.405,,1.000000e+003,6.504213e+001,6.502995e+001,1,0,3.460736e+000,2.456740e-001,,,,,,,6.055782e-006,,,,,,,,,,,,,,,,,,,,,
1616225711.405,,1.000000e+003,6.502995e+001,6.501778e+001,2,0,2.969399e+000,1.464888e-001,,,,,,,3.610901e-006,,,,,,,,,,,,,,,,,,,,,
1616225711.405,,1.000000e+003,6.501778e+001,6.502022e+001,3,0,2.204209e+000,1.104770e-001,,,,,,,2.723221e-006,,,,,,,,,,,,,,,,,,,,,
1616225711.405,,1.000000e+003,6.502022e+001,6.500803e+001,4,0,1.431812e+000,1.889096e-001,,,,,,,4.656558e-006,,,,,,,,,,,,,,,,,,,,,
1616225711.405,,1.000000e+003,6.500803e+001,6.500803e+001,5,0,8.221059e-001,3.102207e-001,3.379009e-001,9.299783e-002,7.972050e-002,3.234414e-001,7.853834e-002,6.526101e-002,7.646836e-006,8.329145e-006,,,,,,,,,,,,,,,,,,,,
1616225997.668,,1.000000e+003,7.004892e+001,7.003772e+001,1,0,5.070296e-001,4.029969e-001,,,,,,,9.933739e-006,,,,,,,,,,,,,,,,,,,,,
1616225997.668,,1.000000e+003,7.003772e+001,7.002095e+001,2,0,8.196360e-001,3.180029e-001,,,,,,,7.838665e-006,,,,,,,,,,,,,,,,,,,,,
1616225997.668,,1.000000e+003,7.002654e+001,7.001814e+001,3,0,1.528481e+000,1.727348e-001,,,,,,,4.257854e-006,,,,,,,,,,,,,,,,,,,,,
1616225997.668,,1.000000e+003,7.002654e+001,7.001814e+001,3,0,2.327374e+000,1.054415e-001,,,,,,,2.599097e-006,,,,,,,,,,,,,,,,,,,,,
1616225997.668,,1.000000e+003,7.001814e+001,7.001254e+001,4,0,2.993890e+000,1.049837e-001,,,,,,,2.587813e-006,,,,,,,,,,,,,,,,,,,,,
1616225997.668,,1.000000e+003,7.001254e+001,7.000417e+001,5,0,3.448893e+000,2.543718e-001,2.674642e-001,4.283148e-002,1.476789e-002,2.649384e-001,4.030568e-002,1.224208e-002,6.270180e-006,6.592904e-006,,,,,,,,,,,,,,,,,,,,
1616226285.344,,1.000000e+003,7.506044e+001,7.504135e+001,1,0,3.351470e+000,2.139348e-001,,,,,,,5.273420e-006,,,,,,,,,,,,,,,,,,,,,
1616226285.344,,1.000000e+003,7.504135e+001,7.503180e+001,2,0,2.730126e+000,1.110874e-001,,,,,,,2.738267e-006,,,,,,,,,,,,,,,,,,,,,
1616226285.344,,1.000000e+003,7.503180e+001,7.502544e+001,3,0,1.934137e+000,6.439406e-002,,,,,,,1.587292e-006,,,,,,,,,,,,,,,,,,,,,
1616226285.344,,1.000000e+003,7.501907e+001,7.500636e+001,4,0,1.210458e+000,2.307199e-001,,,,,,,5.687170e-006,,,,,,,,,,,,,,,,,,,,,
1616226285.344,,1.000000e+003,7.500636e+001,7.501271e+001,5,0,6.642125e-001,3.473006e-001,3.525498e-001,1.188203e-001,1.067297e-001,3.189140e-001,8.518448e-002,7.309383e-002,8.560845e-006,8.690236e-006,,,,,,,,,,,,,,,,,,,,
1616226572.380,,1.000000e+003,8.006453e+001,8.004301e+001,1,0,5.404357e-001,3.807184e-001,,,,,,,9.384582e-006,,,,,,,,,,,,,,,,,,,,,
1616226572.380,,1.000000e+003,8.004301e+001,8.003943e+001,2,0,1.031713e+000,2.876369e-001,,,,,,,7.090155e-006,,,,,,,,,,,,,,,,,,,,,
1616226572.380,,1.000000e+003,8.003943e+001,8.001791e+001,3,0,1.796983e+000,8.758812e-002,,,,,,,2.159018e-006,,,,,,,,,,,,,,,,,,,,,
1616226572.380,,1.000000e+003,8.003943e+001,8.001791e+001,3,0,2.569386e+000,8.438368e-002,,,,,,,2.080030e-006,,,,,,,,,,,,,,,,,,,,,
1616226572.380,,1.000000e+003,8.001791e+001,8.001433e+001,4,0,3.179042e+000,1.359600e-001,,,,,,,3.351368e-006,,,,,,,,,,,,,,,,,,,,,
1616226572.380,,1.000000e+003,8.001433e+001,8.001791e+001,5,0,3.494174e+000,2.729881e-001,2.763146e-001,5.864898e-002,3.057626e-002,2.650927e-001,4.742710e-002,1.935437e-002,6.729065e-006,6.811063e-006,,,,,,,,,,,,,,,,,,,,
1616226860.504,,1.000000e+003,8.508050e+001,8.504840e+001,1,0,3.181460e+000,1.236000e-001,,,,,,,3.046698e-006,,,,,,,,,,,,,,,,,,,,,
1616226860.504,,1.000000e+003,8.504840e+001,8.504037e+001,2,0,2.472611e+000,3.753776e-002,,,,,,,9.252935e-007,,,,,,,,,,,,,,,,,,,,,
1616226860.504,,1.000000e+003,8.504037e+001,8.502435e+001,3,0,1.673758e+000,1.339763e-001,,,,,,,3.302470e-006,,,,,,,,,,,,,,,,,,,,,
1616226860.504,,1.000000e+003,8.502435e+001,8.501632e+001,4,0,1.007210e+000,3.042696e-001,,,,,,,7.500143e-006,,,,,,,,,,,,,,,,,,,,,
1616226860.504,,1.000000e+003,8.501632e+001,8.501232e+001,5,0,5.522765e-001,3.747673e-001,3.630787e-001,1.337333e-001,1.230916e-001,3.129657e-001,8.362026e-002,7.297857e-002,9.237889e-006,8.949769e-006,,,,,,,,,,,,,,,,,,,,
1616227145.883,,1.000000e+003,9.008069e+001,9.005843e+001,1,0,6.497056e-001,3.614917e-001,,,,,,,8.910652e-006,,,,,,,,,,,,,,,,,,,,,
1616227145.883,,1.000000e+003,9.005843e+001,9.003615e+001,2,0,1.271045e+000,2.151555e-001,,,,,,,5.303511e-006,,,,,,,,,,,,,,,,,,,,,
1616227145.883,,1.000000e+003,9.003615e+001,9.003615e+001,3,0,2.067040e+000,4.226813e-002,,,,,,,1.041895e-006,,,,,,,,,,,,,,,,,,,,,
1616227145.883,,1.000000e+003,9.003615e+001,9.003615e+001,3,0,2.790727e+000,6.439406e-002,,,,,,,1.587292e-006,,,,,,,,,,,,,,,,,,,,,
1616227145.883,,1.000000e+003,9.003171e+001,9.002725e+001,4,0,3.336967e+000,1.896725e-001,,,,,,,4.675365e-006,,,,,,,,,,,,,,,,,,,,,
1616227145.883,,1.000000e+003,9.002280e+001,9.001389e+001,5,0,3.460779e+000,2.465896e-001,2.488174e-001,4.199760e-002,1.324254e-002,2.475546e-001,4.073480e-002,1.197974e-002,6.078350e-006,6.133266e-006,,,,,,,,,,,,,,,,,,,,
1616227430.566,,1.000000e+003,9.509148e+001,9.506196e+001,1,0,2.969399e+000,1.763970e-001,,,,,,,4.348127e-006,,,,,,,,,,,,,,,,,,,,,
1616227430.566,,1.000000e+003,9.506196e+001,9.504722e+001,2,0,2.204132e+000,8.331553e-002,,,,,,,2.053700e-006,,,,,,,,,,,,,,,,,,,,,
1616227430.566,,1.000000e+003,9.504722e+001,9.502755e+001,3,0,1.431791e+000,1.252785e-001,,,,,,,3.088073e-006,,,,,,,,,,,,,,,,,,,,,
1616227430.566,,1.000000e+003,9.502755e+001,9.501772e+001,4,0,8.221204e-001,2.987762e-001,,,,,,,7.364734e-006,,,,,,,,,,,,,,,,,,,,,
1616227430.566,,1.000000e+003,9.502263e+001,9.501281e+001,5,0,5.070089e-001,3.106784e-001,3.364361e-001,1.099969e-001,9.813723e-002,3.017988e-001,7.535958e-002,6.349993e-002,7.658120e-006,8.293036e-006,,,,,,,,,,,,,,,,,,,,
1616227715.717,,1.000000e+003,1.000958e+002,1.000687e+002,1,0,8.197673e-001,3.157140e-001,,,,,,,7.782244e-006,,,,,,,,,,,,,,,,,,,,,
1616227715.717,,1.000000e+003,1.000687e+002,1.000525e+002,2,0,1.528558e+000,1.516770e-001,,,,,,,3.738787e-006,,,,,,,,,,,,,,,,,,,,,
1616227715.717,,1.000000e+003,1.000687e+002,1.000525e+002,2,0,2.327465e+000,1.147496e-001,,,,,,,2.828539e-006,,,,,,,,,,,,,,,,,,,,,
1616227715.717,,1.000000e+003,1.000525e+002,1.000336e+002,3,0,2.993935e+000,1.722770e-001,,,,,,,4.246570e-006,,,,,,,,,,,,,,,,,,,,,
1616227715.717,,1.000000e+003,1.000336e+002,1.000255e+002,4,0,3.448889e+000,2.414014e-001,,,,,,,5.950465e-006,,,,,,,,,,,,,,,,,,,,,
1616227715.717,,1.000000e+003,1.000228e+002,1.000282e+002,5,0,3.351516e+000,2.307199e-001,2.367321e-001,1.879461e-002,-1.256016e-002,2.623124e-001,4.437498e-002,1.302020e-002,5.687170e-006,5.835367e-006,,,,,,,,,,,,,,,,,,,,
1616227993.280,,1.000000e+003,1.051234e+002,1.050848e+002,1,0,2.730060e+000,1.655629e-001,,,,,,,4.081071e-006,,,,,,,,,,,,,,,,,,,,,
1616227993.280,,1.000000e+003,1.050848e+002,1.050582e+002,2,0,1.934092e+000,7.156590e-002,,,,,,,1.764076e-006,,,,,,,,,,,,,,,,,,,,,
1616227993.280,,1.000000e+003,1.050582e+002,1.050374e+002,3,0,1.210440e+000,2.198859e-001,,,,,,,5.420113e-006,,,,,,,,,,,,,,,,,,,,,
1616227993.280,,1.000000e+003,1.050374e+002,1.050433e+002,4,0,6.642149e-001,3.450118e-001,,,,,,,8.504425e-006,,,,,,,,,,,,,,,,,,,,,
1616227993.280,,1.000000e+003,1.050374e+002,1.050137e+002,5,0,5.403983e-001,3.590502e-001,3.455001e-001,8.903102e-002,8.327636e-002,3.311000e-001,7.463095e-002,6.887630e-002,8.850469e-006,8.516461e-006,,,,,,,,,,,,,,,,,,,,
1616228271.617,,1.000000e+003,1.101185e+002,1.100958e+002,1,0,1.031828e+000,2.694784e-001,,,,,,,6.642554e-006,,,,,,,,,,,,,,,,,,,,,
1616228271.617,,1.000000e+003,1.100699e+002,1.100505e+002,2,0,1.797072e+000,3.402814e-002,,,,,,,8.387823e-007,,,,,,,,,,,,,,,,,,,,,
1616228271.617,,1.000000e+003,1.100699e+002,1.100505e+002,2,0,2.569434e+000,9.613331e-002,,,,,,,2.369654e-006,,,,,,,,,,,,,,,,,,,,,
1616228271.617,,1.000000e+003,1.100505e+002,1.100344e+002,3,0,3.179086e+000,2.455214e-001,,,,,,,6.052021e-006,,,,,,,,,,,,,,,,,,,,,
1616228271.617,,1.000000e+003,1.100344e+002,1.100408e+002,4,0,3.494169e+000,2.868740e-001,,,,,,,7.071348e-006,,,,,,,,,,,,,,,,,,,,,
1616228271.617,,1.000000e+003,1.100408e+002,1.100376e+002,5,0,3.181469e+000,2.360607e-001,2.374950e-001,1.487915e-002,-7.418692e-004,2.547849e-001,3.216897e-002,1.654795e-002,5.818817e-006,5.854174e-006,,,,,,,,,,,,,,,,,,,,
1616228548.339,,1.000000e+003,1.151330e+002,1.150908e+002,1,0,2.472454e+000,1.326029e-001,,,,,,,3.268618e-006,,,,,,,,,,,,,,,,,,,,,
1616228548.339,,1.000000e+003,1.150908e+002,1.150768e+002,2,0,1.673577e+000,1.628163e-001,,,,,,,4.013366e-006,,,,,,,,,,,,,,,,,,,,,
1616228548.339,,1.000000e+003,1.150768e+002,1.150346e+002,3,0,1.007149e+000,2.594073e-001,,,,,,,6.394304e-006,,,,,,,,,,,,,,,,,,,,,
1616228548.339,,1.000000e+003,1.150346e+002,1.150452e+002,4,0,5.522489e-001,3.157140e-001,,,,,,,7.782244e-006,,,,,,,,,,,,,,,,,,,,,
1616228548.339,,1.000000e+003,1.150452e+002,1.150346e+002,5,0,6.497084e-001,3.636280e-001,3.446455e-001,7.751677e-002,7.302305e-002,3.337787e-001,6.664998e-002,6.215626e-002,8.963310e-006,8.495398e-006,,,,,,,,,,,,,,,,,,,,
1616228826.121,,1.000000e+003,1.201304e+002,1.200886e+002,1,0,1.271166e+000,2.008118e-001,,,,,,,4.949944e-006,,,,,,,,,,,,,,,,,,,,,
1616228826.121,,1.000000e+003,1.200886e+002,1.200582e+002,2,0,2.067180e+000,7.309183e-002,,,,,,,1.801689e-006,,,,,,,,,,,,,,,,,,,,,
1616228826.121,,1.000000e+003,1.200886e+002,1.200582e+002,2,0,2.790813e+000,1.902829e-001,,,,,,,4.690410e-006,,,,,,,,,,,,,,,,,,,,,
1616228826.121,,1.000000e+003,1.200582e+002,1.200506e+002,3,0,3.336981e+000,2.949614e-001,,,,,,,7.270700e-006,,,,,,,,,,,,,,,,,,,,,
1616228826.121,,1.000000e+003,1.200506e+002,1.200164e+002,4,0,3.460763e+000,3.086947e-001,,,,,,,7.609222e-006,,,,,,,,,,,,,,,,,,,,,
1616228826.121,,1.000000e+003,1.200164e+002,1.200392e+002,5,0,2.969391e+000,2.302621e-001,2.239448e-001,-2.454828e-002,-3.857391e-002,2.395259e-001,-8.967193e-003,-2.299282e-002,5.675885e-006,5.520165e-006,,,,,,,,,,,,,,,,,,,,
1616229106.651,,1.000000e+003,1.251256e+002,1.250887e+002,1,0,2.203988e+000,1.037629e-001,,,,,,,2.557722e-006,,,,,,,,,,,,,,,,,,,,,
1616229106.651,,1.000000e+003,1.250887e+002,1.250641e+002,2,0,1.431669e+000,1.603748e-001,,,,,,,3.953185e-006,,,,,,,,,,,,,,,,,,,,,
1616229106.651,,1.000000e+003,1.250641e+002,1.250354e+002,3,0,8.220454e-001,2.734458e-001,,,,,,,6.740349e-006,,,,,,,,,,,,,,,,,,,,,
1616229106.651,,1.000000e+003,1.250354e+002,1.250477e+002,4,0,5.070090e-001,3.415021e-001,,,,,,,8.417914e-006,,,,,,,,,,,,,,,,,,,,,
1616229106.651,,1.000000e+003,1.250477e+002,1.250149e+002,5,0,8.197227e-001,2.931303e-001,2.894070e-001,3.909088e-002,3.648454e-002,2.873684e-001,3.705225e-002,3.444591e-002,7.225564e-006,7.133787e-006,,,,,,,,,,,,,,,,,,,,
1616229388.140,,1.000000e+003,1.301440e+002,1.300867e+002,1,0,1.528694e+000,1.527451e-001,,,,,,,3.765117e-006,,,,,,,,,,,,,,,,,,,,,
1616229388.140,,1.000000e+003,1.301440e+002,1.300867e+002,1,0,2.327588e+000,1.480148e-001,,,,,,,3.648515e-006,,,,,,,,,,,,,,,,,,,,,
1616229388.140,,1.000000e+003,1.300867e+002,1.300691e+002,2,0,2.994042e+000,2.278207e-001,,,,,,,5.615704e-006,,,,,,,,,,,,,,,,,,,,,
1616229388.140,,1.000000e+003,1.300691e+002,1.300558e+002,3,0,3.448961e+000,3.248695e-001,,,,,,,8.007926e-006,,,,,,,,,,,,,,,,,,,,,
1616229388.140,,1.000000e+003,1.300558e+002,1.300382e+002,4,0,3.351497e+000,3.595081e-001,,,,,,,8.861753e-006,,,,,,,,,,,,,,,,,,,,,
1616229388.140,,1.000000e+003,1.300382e+002,1.300206e+002,5,0,2.730047e+000,1.651051e-001,2.031922e-001,-5.627587e-002,-6.477052e-002,2.092962e-001,-5.017186e-002,-5.866651e-002,4.069786e-006,5.008621e-006,,,,,,,,,,,,,,,,,,,,
1616229670.852,,1.000000e+003,1.351393e+002,1.350872e+002,1,0,1.933993e+000,8.865628e-002,,,,,,,2.185348e-006,,,,,,,,,,,,,,,,,,,,,
1616229670.852,,1.000000e+003,1.350872e+002,1.350778e+002,2,0,1.210377e+000,2.034059e-001,,,,,,,5.013887e-006,,,,,,,,,,,,,,,,,,,,,
1616229670.852,,1.000000e+003,1.350589e+002,1.350352e+002,3,0,6.641739e-001,3.228858e-001,,,,,,,7.959028e-006,,,,,,,,,,,,,,,,,,,,,
1616229670.852,,1.000000e+003,1.350352e+002,1.350258e+002,4,0,5.404215e-001,3.613392e-001,,,,,,,8.906890e-006,,,,,,,,,,,,,,,,,,,,,
1616229670.852,,1.000000e+003,1.350258e+002,1.350305e+002,5,0,1.031765e+000,2.790917e-001,2.592547e-001,-6.767502e-003,-8.677512e-003,2.653315e-001,-6.907489e-004,-2.600759e-003,6.879519e-006,6.390543e-006,,,,,,,,,,,,,,,,,,,,
1616229956.487,,1.000000e+003,1.401514e+002,1.400907e+002,1,0,1.797127e+000,1.046785e-001,,,,,,,2.580290e-006,,,,,,,,,,,,,,,,,,,,,
1616229956.487,,1.000000e+003,1.401514e+002,1.400907e+002,1,0,2.569500e+000,1.818903e-001,,,,,,,4.483536e-006,,,,,,,,,,,,,,,,,,,,,
1616229956.487,,1.000000e+003,1.400907e+002,1.400654e+002,2,0,3.179087e+000,2.946562e-001,,,,,,,7.263177e-006,,,,,,,,,,,,,,,,,,,,,
1616229956.487,,1.000000e+003,1.400654e+002,1.400502e+002,3,0,3.494152e+000,2.945036e-001,,,,,,,7.259416e-006,,,,,,,,,,,,,,,,,,,,,
1616229956.487,,1.000000e+003,1.400502e+002,1.400350e+002,4,0,3.181471e+000,2.740562e-001,,,,,,,6.755395e-006,,,,,,,,,,,,,,,,,,,,,
1616229956.487,,1.000000e+003,1.400350e+002,1.400249e+002,5,0,2.472611e+000,1.474044e-001,1.521958e-001,-1.012036e-001,-1.093416e-001,1.448623e-001,-1.085371e-001,-1.166751e-001,3.633469e-006,3.751576e-006,,,,,,,,,,,,,,,,,,,,
1616230240.431,,1.000000e+003,1.451549e+002,1.451063e+002,1,0,1.673568e+000,1.631214e-001,,,,,,,4.020889e-006,,,,,,,,,,,,,,,,,,,,,
1616230240.431,,1.000000e+003,1.451063e+002,1.450631e+002,2,0,1.007129e+000,2.638325e-001,,,,,,,6.503384e-006,,,,,,,,,,,,,,,,,,,,,
1616230240.431,,1.000000e+003,1.450631e+002,1.450469e+002,3,0,5.522544e-001,3.207496e-001,,,,,,,7.906369e-006,,,,,,,,,,,,,,,,,,,,,
1616230240.431,,1.000000e+003,1.450469e+002,1.450199e+002,4,0,6.496770e-001,3.250221e-001,,,,,,,8.011687e-006,,,,,,,,,,,,,,,,,,,,,
1616230240.431,,1.000000e+003,1.450199e+002,1.450199e+002,5,0,1.271126e+000,2.333140e-001,2.089908e-001,-6.259058e-002,-6.365702e-002,2.214771e-001,-5.010419e-002,-5.117063e-002,5.751112e-006,5.151553e-006,,,,,,,,,,,,,,,,,,,,
1616230526.528,,1.000000e+003,1.501281e+002,1.500993e+002,1,0,2.067248e+000,7.293924e-002,,,,,,,1.797928e-006,,,,,,,,,,,,,,,,,,,,,
1616230526.528,,1.000000e+003,1.501281e+002,1.500993e+002,1,0,2.790918e+000,2.008118e-001,,,,,,,4.949944e-006,,,,,,,,,,,,,,,,,,,,,
1616230526.528,,1.000000e+003,1.500993e+002,1.500705e+002,2,0,3.337016e+000,3.366192e-001,,,,,,,8.297550e-006,,,,,,,,,,,,,,,,,,,,,
1616230526.528,,1.000000e+003,1.500705e+002,1.500417e+002,3,0,3.460739e+000,3.617969e-001,,,,,,,8.918174e-006,,,,,,,,,,,,,,,,,,,,,
1616230526.528,,1.000000e+003,1.500417e+002,1.500302e+002,4,0,2.969424e+000,2.630695e-001,,,,,,,6.484577e-006,,,,,,,,,,,,,,,,,,,,,
1616230526.528,,1.000000e+003,1.500302e+002,1.500072e+002,5,0,2.204058e+000,1.011689e-001,1.230811e-001,-1.472909e-001,-1.546569e-001,1.107735e-001,-1.595985e-001,-1.669645e-001,2.493779e-006,3.033909e-006,,,,,,,,,,,,,,,,,,,,
1616230815.847,,1.000000e+003,1.551393e+002,1.550841e+002,1,0,1.431599e+000,1.409955e-001,,,,,,,3.475493e-006,,,,,,,,,,,,,,,,,,,,,
1616230815.847,,1.000000e+003,1.550841e+002,1.550719e+002,2,0,8.219928e-001,3.547777e-001,,,,,,,8.745152e-006,,,,,,,,,,,,,,,,,,,,,
1616230815.847,,1.000000e+003,1.550719e+002,1.550290e+002,3,0,5.070203e-001,3.686636e-001,,,,,,,9.087435e-006,,,,,,,,,,,,,,,,,,,,,
1616230815.847,,1.000000e+003,1.550290e+002,1.550290e+002,4,0,8.197327e-001,3.083895e-001,,,,,,,7.601700e-006,,,,,,,,,,,,,,,,,,,,,
1616230815.847,,1.000000e+003,1.550290e+002,1.550229e+002,5,0,1.528676e+000,1.464888e-001,1.520737e-001,-1.216044e-001,-1.224176e-001,1.656155e-001,-1.080626e-001,-1.088758e-001,3.610901e-006,3.748567e-006,,,,,,,,,,,,,,,,,,,,
1616230815.847,,1.000000e+003,1.550290e+002,1.550229e+002,5,0,2.327574e+000,1.351970e-001,1.417890e-001,-1.200973e-001,-1.327023e-001,1.215217e-001,-1.403646e-001,-1.529696e-001,3.332561e-006,3.495051e-006,,,,,,,,,,,,,,,,,,,,
1616231106.293,,1.000000e+003,1.601512e+002,1.600926e+002,1,0,2.994080e+000,2.441481e-001,,,,,,,6.018169e-006,,,,,,,,,,,,,,,,,,,,,
1616231106.293,,1.000000e+003,1.600926e+002,1.600666e+002,2,0,3.448927e+000,3.613392e-001,,,,,,,8.906890e-006,,,,,,,,,,,,,,,,,,,,,
1616231106.293,,1.000000e+003,1.600666e+002,1.600340e+002,3,0,3.351444e+000,3.660695e-001,,,,,,,9.023492e-006,,,,,,,,,,,,,,,,,,,,,
1616231106.293,,1.000000e+003,1.600340e+002,1.600340e+002,4,0,2.730026e+000,1.886044e-001,,,,,,,4.649035e-006,,,,,,,,,,,,,,,,,,,,,
1616231106.293,,1.000000e+003,1.600340e+002,1.600145e+002,5,0,1.933955e+000,1.615955e-001,1.241493e-001,-1.656458e-001,-1.711323e-001,1.172114e-001,-1.725837e-001,-1.780702e-001,3.983275e-006,3.060239e-006,,,,,,,,,,,,,,,,,,,,
1616231396.763,,1.000000e+003,1.651529e+002,1.650838e+002,1,0,1.210258e+000,2.139348e-001,,,,,,,5.273420e-006,,,,,,,,,,,,,,,,,,,,,
1616231396.763,,1.000000e+003,1.650838e+002,1.650562e+002,2,0,6.641309e-001,3.482162e-001,,,,,,,8.583414e-006,,,,,,,,,,,,,,,,,,,,,
1616231396.763,,1.000000e+003,1.650631e+002,1.650424e+002,3,0,5.404648e-001,3.886532e-001,,,,,,,9.580172e-006,,,,,,,,,,,,,,,,,,,,,
1616231396.763,,1.000000e+003,1.650424e+002,1.650148e+002,4,0,1.031800e+000,2.902310e-001,,,,,,,7.154098e-006,,,,,,,,,,,,,,,,,,,,,
1616231396.763,,1.000000e+003,1.650148e+002,1.650079e+002,5,0,1.797173e+000,1.243629e-001,1.172521e-001,-1.676557e-001,-1.679332e-001,1.264366e-001,-1.584713e-001,-1.587487e-001,3.065505e-006,2.890225e-006,,,,,,,,,,,,,,,,,,,,
1616231396.763,,1.000000e+003,1.650148e+002,1.650079e+002,5,0,2.569539e+000,2.064577e-001,1.966918e-001,-8.017079e-002,-8.849348e-002,1.873236e-001,-8.953900e-002,-9.786169e-002,5.089114e-006,4.848387e-006,,,,,,,,,,,,,,,,,,,,
1616231690.861,,1.000000e+003,1.701466e+002,1.700954e+002,1,0,3.179206e+000,3.227333e-001,,,,,,,7.955266e-006,,,,,,,,,,,,,,,,,,,,,
1616231690.861,,1.000000e+003,1.700954e+002,1.700661e+002,2,0,3.494131e+000,3.083895e-001,,,,,,,7.601700e-006,,,,,,,,,,,,,,,,,,,,,
1616231690.861,,1.000000e+003,1.700515e+002,1.700369e+002,3,0,3.181444e+000,3.959777e-001,,,,,,,9.760717e-006,,,,,,,,,,,,,,,,,,,,,
1616231690.861,,1.000000e+003,1.700369e+002,1.700150e+002,4,0,2.472542e+000,1.269570e-001,,,,,,,3.129448e-006,,,,,,,,,,,,,,,,,,,,,
1616231690.861,,1.000000e+003,1.700150e+002,1.700076e+002,5,0,1.673618e+000,1.185644e-001,1.412702e-001,-1.410783e-001,-1.456340e-001,1.444699e-001,-1.378786e-001,-1.424343e-001,2.922573e-006,3.482263e-006,,,,,,,,,,,,,,,,,,,,
1616231982.593,,1.000000e+003,1.751542e+002,1.750922e+002,1,0,1.007062e+000,3.103732e-001,,,,,,,7.650597e-006,,,,,,,,,,,,,,,,,,,,,
1616231982.593,,1.000000e+003,1.750922e+002,1.750613e+002,2,0,5.522576e-001,4.420606e-001,,,,,,,1.089665e-005,,,,,,,,,,,,,,,,,,,,,
1616231982.593,,1.000000e+003,1.750613e+002,1.750304e+002,3,0,6.497326e-001,4.022340e-001,,,,,,,9.914933e-006,,,,,,,,,,,,,,,,,,,,,
1616231982.593,,1.000000e+003,1.750304e+002,1.750072e+002,4,0,1.271102e+000,2.267525e-001,,,,,,,5.589374e-006,,,,,,,,,,,,,,,,,,,,,
1616231982.593,,1.000000e+003,1.750072e+002,1.750226e+002,5,0,2.067248e+000,1.495407e-001,1.426740e-001,-1.798565e-001,-1.798565e-001,1.488706e-001,-1.736600e-001,-1.736600e-001,3.686128e-006,3.516867e-006,,,,,,,,,,,,,,,,,,,,
1616231982.593,,1.000000e+003,1.750072e+002,1.750226e+002,5,0,2.790892e+000,2.806177e-001,2.727134e-001,-4.020685e-002,-4.981714e-002,2.727429e-001,-4.017734e-002,-4.978764e-002,6.917133e-006,6.722295e-006,,,,,,,,,,,,,,,,,,,,
1616232274.746,,1.000000e+003,1.801604e+002,1.801031e+002,1,0,3.337080e+000,3.340251e-001,,,,,,,8.233607e-006,,,,,,,,,,,,,,,,,,,,,
1616232274.746,,1.000000e+003,1.801031e+002,1.800460e+002,2,0,3.460683e+000,3.651540e-001,,,,,,,9.000923e-006,,,,,,,,,,,,,,,,,,,,,
1616232274.746,,1.000000e+003,1.800460e+002,1.800296e+002,3,0,2.969333e+000,2.467421e-001,,,,,,,6.082112e-006,,,,,,,,,,,,,,,,,,,,,
1616232274.746,,1.000000e+003,1.800296e+002,1.800215e+002,4,0,2.204004e+000,1.762444e-001,,,,,,,4.344366e-006,,,,,,,,,,,,,,,,,,,,,
1616232274.746,,1.000000e+003,1.800215e+002,1.800133e+002,5,0,1.431609e+000,2.374340e-001,2.114933e-001,-9.209508e-002,-9.678389e-002,2.192991e-001,-8.428924e-002,-8.897805e-002,5.852669e-006,5.213239e-006,,,,,,,,,,,,,,,,,,,,
1616232568.020,,1.000000e+003,1.851586e+002,1.850896e+002,1,0,8.219365e-001,3.860591e-001,,,,,,,9.516230e-006,,,,,,,,,,,,,,,,,,,,,
1616232568.020,,1.000000e+003,1.850896e+002,1.850551e+002,2,0,5.070357e-001,3.946043e-001,,,,,,,9.726866e-006,,,,,,,,,,,,,,,,,,,,,
1616232568.020,,1.000000e+003,1.850551e+002,1.850207e+002,3,0,8.198455e-001,4.408399e-001,,,,,,,1.086656e-005,,,,,,,,,,,,,,,,,,,,,
1616232568.020,,1.000000e+003,1.850207e+002,1.850207e+002,4,0,1.528718e+000,1.336711e-001,,,,,,,3.294947e-006,,,,,,,,,,,,,,,,,,,,,
1616232568.020,,1.000000e+003,1.850207e+002,1.850207e+002,4,0,2.327634e+000,1.203955e-001,,,,,,,2.967709e-006,,,,,,,,,,,,,,,,,,,,,
1616232568.020,,1.000000e+003,1.850207e+002,1.850035e+002,5,0,2.994115e+000,2.819910e-001,3.036287e-001,-7.358038e-003,-1.431340e-002,3.125756e-001,1.588888e-003,-5.366474e-003,6.950985e-006,7.484345e-006,,,,,,,,,,,,,,,,,,,,
1616232860.753,,1.000000e+003,1.901497e+002,1.901044e+002,1,0,3.448975e+000,3.770562e-001,,,,,,,9.294309e-006,,,,,,,,,,,,,,,,,,,,,
1616232860.753,,1.000000e+003,1.901044e+002,1.900499e+002,2,0,3.351406e+000,3.683584e-001,,,,,,,9.079912e-006,,,,,,,,,,,,,,,,,,,,,
1616232860.753,,1.000000e+003,1.900499e+002,1.900318e+002,3,0,2.729988e+000,2.778710e-001,,,,,,,6.849428e-006,,,,,,,,,,,,,,,,,,,,,
1616232860.753,,1.000000e+003,1.900318e+002,1.900227e+002,4,0,1.933910e+000,1.092563e-001,,,,,,,2.693130e-006,,,,,,,,,,,,,,,,,,,,,
1616232860.753,,1.000000e+003,1.900227e+002,1.900136e+002,5,0,1.210239e+000,2.873318e-001,2.790918e-001,-3.537126e-002,-3.930643e-002,2.806318e-001,-3.383126e-002,-3.776643e-002,7.082632e-006,6.879519e-006,,,,,,,,,,,,,,,,,,,,
1616233154.909,,1.000000e+003,1.951406e+002,1.950834e+002,1,0,6.640648e-001,4.272591e-001,,,,,,,1.053179e-005,,,,,,,,,,,,,,,,,,,,,
1616233154.909,,1.000000e+003,1.950834e+002,1.950452e+002,2,0,5.405016e-001,4.499954e-001,,,,,,,1.109224e-005,,,,,,,,,,,,,,,,,,,,,
1616233154.909,,1.000000e+003,1.950452e+002,1.950357e+002,3,0,1.031931e+000,3.909421e-001,,,,,,,9.636593e-006,,,,,,,,,,,,,,,,,,,,,
1616233154.909,,1.000000e+003,1.950357e+002,1.950166e+002,4,0,1.797199e+000,1.278726e-001,,,,,,,3.152016e-006,,,,,,,,,,,,,,,,,,,,,
1616233154.909,,1.000000e+003,1.950357e+002,1.950166e+002,4,0,2.569563e+000,2.021851e-001,,,,,,,4.983796e-006,,,,,,,,,,,,,,,,,,,,,
1616233154.909,,1.000000e+003,1.950166e+002,1.950070e+002,5,0,3.179250e+000,3.288369e-001,3.613086e-001,2.296183e-002,1.686996e-002,3.731314e-001,3.478462e-002,2.869275e-002,8.105721e-006,8.906138e-006,,,,,,,,,,,,,,,,,,,,
1616233451.069,,1.000000e+003,2.001509e+002,2.000808e+002,1,0,3.494166e+000,3.900266e-001,,,,,,,9.614025e-006,,,,,,,,,,,,,,,,,,,,,
1616233451.069,,1.000000e+003,2.000808e+002,2.000407e+002,2,0,3.181279e+000,3.675954e-001,,,,,,,9.061106e-006,,,,,,,,,,,,,,,,,,,,,
1616233451.069,,1.000000e+003,2.000407e+002,2.000307e+002,3,0,2.472373e+000,2.391125e-001,,,,,,,5.894044e-006,,,,,,,,,,,,,,,,,,,,,
1616233451.069,,1.000000e+003,2.000307e+002,2.000106e+002,4,0,1.673518e+000,2.150029e-001,,,,,,,5.299750e-006,,,,,,,,,,,,,,,,,,,,,
1616233451.069,,1.000000e+003,2.000106e+002,2.000106e+002,5,0,1.007023e+000,3.624073e-001,3.574938e-001,1.126749e-002,8.964628e-003,3.556012e-001,9.374862e-003,7.072002e-003,8.933219e-006,8.812103e-006,,,,,,,,,,,,,,,,,,,,
1616233746.728,,1.000000e+003,2.051535e+002,2.050904e+002,1,0,5.521701e-001,3.833125e-001,,,,,,,9.448525e-006,,,,,,,,,,,,,,,,,,,,,
1616233746.728,,1.000000e+003,2.050904e+002,2.050589e+002,2,0,6.498002e-001,4.684591e-001,,,,,,,1.154736e-005,,,,,,,,,,,,,,,,,,,,,
1616233746.728,,1.000000e+003,2.050589e+002,2.050273e+002,3,0,1.271253e+000,3.013703e-001,,,,,,,7.428677e-006,,,,,,,,,,,,,,,,,,,,,
1616233746.728,,1.000000e+003,2.050273e+002,2.050063e+002,4,0,2.067399e+000,1.762444e-001,,,,,,,4.344366e-006,,,,,,,,,,,,,,,,,,,,,
1616233746.728,,1.000000e+003,2.050273e+002,2.050063e+002,4,0,2.790988e+000,3.108310e-001,,,,,,,7.661881e-006,,,,,,,,,,,,,,,,,,,,,
1616233746.728,,1.000000e+003,2.050063e+002,2.049958e+002,5,0,3.337129e+000,3.888058e-001,3.949400e-001,4.873204e-002,4.321194e-002,4.037402e-001,5.753225e-002,5.201215e-002,9.583934e-006,9.735140e-006,,,,,,,,,,,,,,,,,,,,
1616234043.805,,1.000000e+003,2.101533e+002,2.100871e+002,1,0,3.460633e+000,3.915525e-001,,,,,,,9.651638e-006,,,,,,,,,,,,,,,,,,,,,
1616234043.805,,1.000000e+003,2.100871e+002,2.100540e+002,2,0,2.969212e+000,3.270058e-001,,,,,,,8.060585e-006,,,,,,,,,,,,,,,,,,,,,
1616234043.805,,1.000000e+003,2.100429e+002,2.100319e+002,3,0,2.203814e+000,1.663259e-001,,,,,,,4.099878e-006,,,,,,,,,,,,,,,,,,,,,
1616234043.805,,1.000000e+003,2.100319e+002,2.100099e+002,4,0,1.431585e+000,2.623066e-001,,,,,,,6.465770e-006,,,,,,,,,,,,,,,,,,,,,
1616234043.805,,1.000000e+003,2.100099e+002,2.100099e+002,5,0,8.219025e-001,3.898740e-001,3.890499e-001,5.118334e-002,4.914847e-002,3.809032e-001,4.303658e-002,4.100171e-002,9.610263e-006,9.589952e-006,,,,,,,,,,,,,,,,,,,,
1616234341.177,,1.000000e+003,2.151477e+002,2.150899e+002,1,0,5.070571e-001,4.908902e-001,,,,,,,1.210028e-005,,,,,,,,,,,,,,,,,,,,,
1616234341.177,,1.000000e+003,2.150899e+002,2.150437e+002,2,0,8.194498e-001,3.909421e-001,,,,,,,9.636593e-006,,,,,,,,,,,,,,,,,,,,,
1616234341.177,,1.000000e+003,2.150437e+002,2.150321e+002,3,0,1.528155e+000,2.269051e-001,,,,,,,5.593135e-006,,,,,,,,,,,,,,,,,,,,,
1616234341.177,,1.000000e+003,2.150437e+002,2.150321e+002,3,0,2.327100e+000,2.209540e-001,,,,,,,5.446443e-006,,,,,,,,,,,,,,,,,,,,,
1616234341.177,,1.000000e+003,2.150321e+002,2.150032e+002,4,0,2.993694e+000,3.683584e-001,,,,,,,9.079912e-006,,,,,,,,,,,,,,,,,,,,,
1616234341.177,,1.000000e+003,2.150032e+002,2.150032e+002,5,0,3.448799e+000,3.587451e-001,4.153569e-001,6.489515e-002,6.084418e-002,4.189424e-001,6.848061e-002,6.442964e-002,8.842947e-006,1.023841e-005,,,,,,,,,,,,,,,,,,,,
1616234681.657,,1.000000e+003,2.201483e+002,2.200817e+002,1,0,3.351616e+000,3.849910e-001,,,,,,,9.489900e-006,,,,,,,,,,,,,,,,,,,,,
1616234681.657,,1.000000e+003,2.200817e+002,2.200333e+002,2,0,2.730397e+000,2.580340e-001,,,,,,,6.360452e-006,,,,,,,,,,,,,,,,,,,,,
1616234681.657,,1.000000e+003,2.200031e+002,2.200031e+002,3,0,1.934401e+000,1.925718e-001,,,,,,,4.746831e-006,,,,,,,,,,,,,,,,,,,,,
1616234681.657,,1.000000e+003,2.200031e+002,2.200031e+002,4,0,1.210657e+000,3.178503e-001,,,,,,,7.834903e-006,,,,,,,,,,,,,,,,,,,,,
1616234681.657,,1.000000e+003,2.200031e+002,2.200031e+002,5,0,6.643615e-001,4.356517e-001,4.220405e-001,7.623775e-002,7.471046e-002,4.094243e-001,6.362156e-002,6.209427e-002,1.073867e-005,1.040316e-005,,,,,,,,,,,,,,,,,,,,
1616234997.170,,1.000000e+003,2.251515e+002,2.250882e+002,1,0,5.403709e-001,4.208502e-001,,,,,,,1.037382e-005,,,,,,,,,,,,,,,,,,,,,
1616234997.170,,1.000000e+003,2.250882e+002,2.250502e+002,2,0,1.031457e+000,3.274636e-001,,,,,,,8.071869e-006,,,,,,,,,,,,,,,,,,,,,
1616234997.170,,1.000000e+003,2.250312e+002,2.250059e+002,3,0,1.796665e+000,1.644948e-001,,,,,,,4.054741e-006,,,,,,,,,,,,,,,,,,,,,
1616234997.170,,1.000000e+003,2.250312e+002,2.250059e+002,3,0,2.569134e+000,2.404858e-001,,,,,,,5.927896e-006,,,,,,,,,,,,,,,,,,,,,
1616234997.170,,1.000000e+003,2.250059e+002,2.250059e+002,4,0,3.178859e+000,4.017762e-001,,,,,,,9.903649e-006,,,,,,,,,,,,,,,,,,,,,
1616234997.170,,1.000000e+003,2.250059e+002,2.249996e+002,5,0,3.494169e+000,4.606769e-001,4.188055e-001,6.908906e-002,6.484750e-002,4.213417e-001,7.162526e-002,6.738371e-002,1.135553e-005,1.032342e-005,,,,,,,,,,,,,,,,,,,,
1616235327.499,,1.000000e+003,2.301546e+002,2.300885e+002,1,0,3.181693e+000,4.042177e-001,,,,,,,9.963831e-006,,,,,,,,,,,,,,,,,,,,,
1616235327.499,,1.000000e+003,2.300885e+002,2.300488e+002,2,0,2.472986e+000,2.638325e-001,,,,,,,6.503384e-006,,,,,,,,,,,,,,,,,,,,,
1616235327.499,,1.000000e+003,2.300488e+002,2.300224e+002,3,0,1.674021e+000,1.773126e-001,,,,,,,4.370695e-006,,,,,,,,,,,,,,,,,,,,,
1616235327.499,,1.000000e+003,2.300026e+002,2.299960e+002,4,0,1.007616e+000,3.987243e-001,,,,,,,9.828422e-006,,,,,,,,,,,,,,,,,,,,,
1616235327.499,,1.000000e+003,2.299960e+002,2.299960e+002,5,0,5.524135e-001,4.568621e-001,4.563738e-001,9.176653e-002,9.071541e-002,4.377620e-001,7.315471e-002,7.210359e-002,1.126150e-005,1.124946e-005,,,,,,,,,,,,,,,,,,,,
1616235617.039,,1.000000e+003,2.351910e+002,2.351149e+002,1,0,6.494335e-001,4.130681e-001,,,,,,,1.018199e-005,,,,,,,,,,,,,,,,,,,,,
1616235617.039,,1.000000e+003,2.351149e+002,2.350666e+002,2,0,1.270514e+000,3.335673e-001,,,,,,,8.222323e-006,,,,,,,,,,,,,,,,,,,,,
1616235617.039,,1.000000e+003,2.350666e+002,2.350321e+002,3,0,2.066586e+000,1.515244e-001,,,,,,,3.735026e-006,,,,,,,,,,,,,,,,,,,,,
1616235617.039,,1.000000e+003,2.350666e+002,2.350321e+002,3,0,2.790368e+000,2.824488e-001,,,,,,,6.962269e-006,,,,,,,,,,,,,,,,,,,,,
1616235617.039,,1.000000e+003,2.350321e+002,2.350114e+002,4,0,3.336720e+000,4.019288e-001,,,,,,,9.907410e-006,,,,,,,,,,,,,,,,,,,,,
1616235617.039,,1.000000e+003,2.350114e+002,2.349976e+002,5,0,3.460897e+000,3.453169e-001,4.004944e-001,6.270555e-002,5.940217e-002,4.067941e-001,6.900529e-002,6.570190e-002,8.511947e-006,9.872054e-006,,,,,,,,,,,,,,,,,,,,
1616235916.004,,1.000000e+003,2.401395e+002,2.400818e+002,1,0,2.969833e+000,3.337199e-001,,,,,,,8.226085e-006,,,,,,,,,,,,,,,,,,,,,
1616235916.004,,1.000000e+003,2.400818e+002,2.400458e+002,2,0,2.204733e+000,2.558977e-001,,,,,,,6.307793e-006,,,,,,,,,,,,,,,,,,,,,
1616235916.004,,1.000000e+003,2.400458e+002,2.400242e+002,3,0,1.432234e+000,2.554399e-001,,,,,,,6.296509e-006,,,,,,,,,,,,,,,,,,,,,
1616235916.004,,1.000000e+003,2.400242e+002,2.400025e+002,4,0,8.224342e-001,3.386029e-001,,,,,,,8.346447e-006,,,,,,,,,,,,,,,,,,,,,
1616235916.004,,1.000000e+003,2.400025e+002,2.400025e+002,5,0,5.070448e-001,4.585406e-001,4.473098e-001,9.361090e-002,9.214172e-002,4.290726e-001,7.537366e-002,7.390448e-002,1.130287e-005,1.102604e-005,,,,,,,,,,,,,,,,,,,,
1616236214.777,,1.000000e+003,2.451465e+002,2.450789e+002,1,0,8.193967e-001,4.408399e-001,,,,,,,1.086656e-005,,,,,,,,,,,,,,,,,,,,,
1616236214.777,,1.000000e+003,2.450789e+002,2.450488e+002,2,0,1.528060e+000,2.665792e-001,,,,,,,6.571088e-006,,,,,,,,,,,,,,,,,,,,,
1616236214.777,,1.000000e+003,2.450789e+002,2.450488e+002,2,0,2.327031e+000,2.577288e-001,,,,,,,6.352930e-006,,,,,,,,,,,,,,,,,,,,,
1616236214.777,,1.000000e+003,2.450488e+002,2.450187e+002,3,0,2.993578e+000,3.253273e-001,,,,,,,8.019210e-006,,,,,,,,,,,,,,,,,,,,,
1616236214.777,,1.000000e+003,2.450187e+002,2.450113e+002,4,0,3.448735e+000,4.560991e-001,,,,,,,1.124269e-005,,,,,,,,,,,,,,,,,,,,,
1616236214.777,,1.000000e+003,2.450113e+002,2.450113e+002,5,0,3.351773e+000,4.290903e-001,4.239021e-001,4.544307e-002,4.345873e-002,4.358688e-001,5.740980e-002,5.542547e-002,1.057693e-005,1.044905e-005,,,,,,,,,,,,,,,,,,,,
1616236514.751,,1.000000e+003,2.501429e+002,2.500646e+002,1,0,2.730592e+000,2.641377e-001,,,,,,,6.510907e-006,,,,,,,,,,,,,,,,,,,,,
1616236514.751,,1.000000e+003,2.500646e+002,2.500411e+002,2,0,1.934651e+000,1.991333e-001,,,,,,,4.908569e-006,,,,,,,,,,,,,,,,,,,,,
1616236514.751,,1.000000e+003,2.500411e+002,2.500177e+002,3,0,1.210898e+000,3.480636e-001,,,,,,,8.579652e-006,,,,,,,,,,,,,,,,,,,,,
1616236514.751,,1.000000e+003,2.500177e+002,2.500099e+002,4,0,6.644902e-001,4.429762e-001,,,,,,,1.091922e-005,,,,,,,,,,,,,,,,,,,,,
1616236514.751,,1.000000e+003,2.500099e+002,2.500020e+002,5,0,5.402930e-001,4.347362e-001,4.454787e-001,8.856332e-002,8.802006e-002,4.316795e-001,7.476418e-002,7.422093e-002,1.071610e-005,1.098090e-005,,,,,,,,,,,,,,,,,,,,
1616236815.597,,1.000000e+003,2.551464e+002,2.550730e+002,1,0,1.031376e+000,4.344310e-001,,,,,,,1.070858e-005,,,,,,,,,,,,,,,,,,,,,
1616236815.597,,1.000000e+003,2.550730e+002,2.550404e+002,2,0,1.796510e+000,2.169866e-001,,,,,,,5.348647e-006,,,,,,,,,,,,,,,,,,,,,
1616236815.597,,1.000000e+003,2.550730e+002,2.550404e+002,2,0,2.568992e+000,2.964873e-001,,,,,,,7.308314e-006,,,,,,,,,,,,,,,,,,,,,
1616236815.597,,1.000000e+003,2.550404e+002,2.550241e+002,3,0,3.178751e+000,3.643910e-001,,,,,,,8.982117e-006,,,,,,,,,,,,,,,,,,,,,
1616236815.597,,1.000000e+003,2.550241e+002,2.550160e+002,4,0,3.494149e+000,4.237495e-001,,,,,,,1.044528e-005,,,,,,,,,,,,,,,,,,,,,
1616236815.597,,1.000000e+003,2.550160e+002,2.549997e+002,5,0,3.181842e+000,3.662221e-001,3.882565e-001,1.276221e-002,1.037344e-002,4.055581e-001,3.006385e-002,2.767509e-002,9.027253e-006,9.570393e-006,,,,,,,,,,,,,,,,,,,,
1616237117.641,,1.000000e+003,2.601447e+002,2.600768e+002,1,0,2.473127e+000,2.696310e-001,,,,,,,6.646315e-006,,,,,,,,,,,,,,,,,,,,,
1616237117.641,,1.000000e+003,2.600768e+002,2.600429e+002,2,0,1.674231e+000,2.307199e-001,,,,,,,5.687170e-006,,,,,,,,,,,,,,,,,,,,,
1616237117.641,,1.000000e+003,2.600429e+002,2.600175e+002,3,0,1.007677e+000,4.023865e-001,,,,,,,9.918695e-006,,,,,,,,,,,,,,,,,,,,,
1616237117.641,,1.000000e+003,2.600175e+002,2.600090e+002,4,0,5.524399e-001,4.370250e-001,,,,,,,1.077252e-005,,,,,,,,,,,,,,,,,,,,,
1616237117.641,,1.000000e+003,2.600090e+002,2.600090e+002,5,0,6.494028e-001,4.771569e-001,4.539934e-001,7.734523e-002,7.704535e-002,4.444791e-001,6.783096e-002,6.753108e-002,1.176176e-005,1.119078e-005,,,,,,,,,,,,,,,,,,,,
1616237420.226,,1.000000e+003,2.651443e+002,2.650914e+002,1,0,1.270617e+000,3.265481e-001,,,,,,,8.049301e-006,,,,,,,,,,,,,,,,,,,,,
1616237420.226,,1.000000e+003,2.650914e+002,2.650385e+002,2,0,2.066607e+000,1.821955e-001,,,,,,,4.491058e-006,,,,,,,,,,,,,,,,,,,,,
1616237420.226,,1.000000e+003,2.650914e+002,2.650385e+002,2,0,2.790384e+000,3.178503e-001,,,,,,,7.834903e-006,,,,,,,,,,,,,,,,,,,,,
1616237420.226,,1.000000e+003,2.650385e+002,2.650120e+002,3,0,3.336739e+000,4.460280e-001,,,,,,,1.099444e-005,,,,,,,,,,,,,,,,,,,,,
1616237420.226,,1.000000e+003,2.650120e+002,2.650032e+002,4,0,3.460903e+000,4.716636e-001,,,,,,,1.162635e-005,,,,,,,,,,,,,,,,,,,,,
1616237420.226,,1.000000e+003,2.650032e+002,2.650032e+002,5,0,2.969892e+000,3.587451e-001,3.640553e-001,-2.427531e-002,-2.540916e-002,3.764074e-001,-1.192320e-002,-1.305705e-002,8.842947e-006,8.973842e-006,,,,,,,,,,,,,,,,,,,,
1616237721.938,,1.000000e+003,2.701332e+002,2.700689e+002,1,0,2.204609e+000,2.688681e-001,,,,,,,6.627508e-006,,,,,,,,,,,,,,,,,,,,,
1616237721.938,,1.000000e+003,2.700689e+002,2.700322e+002,2,0,1.432152e+000,3.608814e-001,,,,,,,8.895606e-006,,,,,,,,,,,,,,,,,,,,,
1616237721.938,,1.000000e+003,2.700322e+002,2.700230e+002,3,0,8.224638e-001,4.139836e-001,,,,,,,1.020456e-005,,,,,,,,,,,,,,,,,,,,,
1616237721.938,,1.000000e+003,2.700230e+002,2.699955e+002,4,0,5.070408e-001,4.853969e-001,,,,,,,1.196487e-005,,,,,,,,,,,,,,,,,,,,,
1616237721.938,,1.000000e+003,2.699955e+002,2.700138e+002,5,0,8.193354e-001,4.426710e-001,4.531388e-001,5.206380e-002,5.210713e-002,4.497859e-001,4.871086e-002,4.875419e-002,1.091169e-005,1.116972e-005,,,,,,,,,,,,,,,,,,,,
1616238024.143,,1.000000e+003,2.751358e+002,2.750785e+002,1,0,1.528142e+000,2.832118e-001,,,,,,,6.981076e-006,,,,,,,,,,,,,,,,,,,,,
1616238024.143,,1.000000e+003,2.751358e+002,2.750785e+002,1,0,2.327123e+000,2.642903e-001,,,,,,,6.514668e-006,,,,,,,,,,,,,,,,,,,,,
1616238024.143,,1.000000e+003,2.750785e+002,2.750403e+002,2,0,2.993562e+000,4.313791e-001,,,,,,,1.063335e-005,,,,,,,,,,,,,,,,,,,,,
1616238024.143,,1.000000e+003,2.750403e+002,2.750117e+002,3,0,3.448775e+000,4.318369e-001,,,,,,,1.064464e-005,,,,,,,,,,,,,,,,,,,,,
1616238024.143,,1.000000e+003,2.750117e+002,2.750021e+002,4,0,3.351787e+000,3.979613e-001,,,,,,,9.809615e-006,,,,,,,,,,,,,,,,,,,,,
1616238024.143,,1.000000e+003,2.750021e+002,2.750021e+002,5,0,2.730666e+000,3.344828e-001,3.252968e-001,-7.044915e-002,-7.018137e-002,3.287989e-001,-6.694702e-002,-6.667924e-002,8.244891e-006,8.018458e-006,,,,,,,,,,,,,,,,,,,,
1616238326.236,,1.000000e+003,2.801215e+002,2.800718e+002,1,0,1.934590e+000,2.371288e-001,,,,,,,5.845146e-006,,,,,,,,,,,,,,,,,,,,,
1616238326.236,,1.000000e+003,2.800718e+002,2.800222e+002,2,0,1.210864e+000,4.252754e-001,,,,,,,1.048290e-005,,,,,,,,,,,,,,,,,,,,,
1616238326.236,,1.000000e+003,2.800222e+002,2.800123e+002,3,0,6.645167e-001,4.959258e-001,,,,,,,1.222441e-005,,,,,,,,,,,,,,,,,,,,,
1616238326.236,,1.000000e+003,2.800123e+002,2.800024e+002,4,0,5.402713e-001,4.956206e-001,,,,,,,1.221688e-005,,,,,,,,,,,,,,,,,,,,,
1616238326.236,,1.000000e+003,2.800024e+002,2.800024e+002,5,0,1.031280e+000,4.100162e-001,4.230476e-001,8.047814e-003,8.086562e-003,4.286383e-001,1.363852e-002,1.367727e-002,1.010676e-005,1.042798e-005,,,,,,,,,,,,,,,,,,,,
1616238629.321,,1.000000e+003,2.851173e+002,2.850761e+002,1,0,1.796620e+000,2.815332e-001,,,,,,,6.939701e-006,,,,,,,,,,,,,,,,,,,,,
1616238629.321,,1.000000e+003,2.851173e+002,2.850761e+002,1,0,2.569085e+000,3.532518e-001,,,,,,,8.707538e-006,,,,,,,,,,,,,,,,,,,,,
1616238629.321,,1.000000e+003,2.850761e+002,2.850349e+002,2,0,3.178820e+000,4.336680e-001,,,,,,,1.068977e-005,,,,,,,,,,,,,,,,,,,,,
1616238629.321,,1.000000e+003,2.850349e+002,2.850143e+002,3,0,3.494151e+000,4.814295e-001,,,,,,,1.186708e-005,,,,,,,,,,,,,,,,,,,,,
1616238629.321,,1.000000e+003,2.850143e+002,2.850040e+002,4,0,3.181885e+000,4.098636e-001,,,,,,,1.010300e-005,,,,,,,,,,,,,,,,,,,,,
1616238629.321,,1.000000e+003,2.850040e+002,2.849937e+002,5,0,2.473174e+000,2.992340e-001,3.007294e-001,-1.203910e-001,-1.212154e-001,2.930030e-001,-1.281174e-001,-1.289417e-001,7.376018e-006,7.412879e-006,,,,,,,,,,,,,,,,,,,,
1616238971.279,,1.000000e+003,2.901345e+002,2.900596e+002,1,0,1.674206e+000,2.760399e-001,,,,,,,6.804292e-006,,,,,,,,,,,,,,,,,,,,,
1616238971.279,,1.000000e+003,2.900596e+002,2.900276e+002,2,0,1.007681e+000,4.547258e-001,,,,,,,1.120884e-005,,,,,,,,,,,,,,,,,,,,,
1616238971.279,,1.000000e+003,2.900276e+002,2.900062e+002,3,0,5.524511e-001,5.256813e-001,,,,,,,1.295787e-005,,,,,,,,,,,,,,,,,,,,,
1616238971.279,,1.000000e+003,2.900062e+002,2.900062e+002,4,0,6.493751e-001,4.519791e-001,,,,,,,1.114113e-005,,,,,,,,,,,,,,,,,,,,,
1616238971.279,,1.000000e+003,2.900062e+002,2.900062e+002,5,0,1.270511e+000,3.703421e-001,3.663137e-001,-4.497628e-002,-4.495367e-002,3.774578e-001,-3.383214e-002,-3.380954e-002,9.128810e-006,9.029510e-006,,,,,,,,,,,,,,,,,,,,
1616239275.649,,1.000000e+003,2.951198e+002,2.950756e+002,1,0,2.066684e+000,2.290414e-001,,,,,,,5.645795e-006,,,,,,,,,,,,,,,,,,,,,
1616239275.649,,1.000000e+003,2.951198e+002,2.950756e+002,1,0,2.790438e+000,3.669851e-001,,,,,,,9.046060e-006,,,,,,,,,,,,,,,,,,,,,
1616239275.649,,1.000000e+003,2.950756e+002,2.950201e+002,2,0,3.336719e+000,4.759361e-001,,,,,,,1.173167e-005,,,,,,,,,,,,,,,,,,,,,
1616239275.649,,1.000000e+003,2.950201e+002,2.950091e+002,3,0,3.460866e+000,5.162206e-001,,,,,,,1.272467e-005,,,,,,,,,,,,,,,,,,,,,
1616239275.649,,1.000000e+003,2.950091e+002,2.949980e+002,4,0,2.969850e+000,3.674428e-001,,,,,,,9.057344e-006,,,,,,,,,,,,,,,,,,,,,
1616239275.649,,1.000000e+003,2.949980e+002,2.949980e+002,5,0,2.204632e+000,2.526933e-001,2.625813e-001,-1.643255e-001,-1.641842e-001,2.526705e-001,-1.742363e-001,-1.740950e-001,6.228805e-006,6.472540e-006,,,,,,,,,,,,,,,,,,,,
1616239616.630,,1.000000e+003,3.001445e+002,3.000641e+002,1,0,1.432118e+000,4.167303e-001,,,,,,,1.027226e-005,,,,,,,,,,,,,,,,,,,,,
1616239616.630,,1.000000e+003,3.000641e+002,3.000296e+002,2,0,8.224046e-001,4.498428e-001,,,,,,,1.108848e-005,,,,,,,,,,,,,,,,,,,,,
1616239616.630,,1.000000e+003,3.000296e+002,3.000067e+002,3,0,5.070655e-001,4.919584e-001,,,,,,,1.212661e-005,,,,,,,,,,,,,,,,,,,,,
1616239616.630,,1.000000e+003,2.999952e+002,3.000181e+002,4,0,8.192886e-001,4.895169e-001,,,,,,,1.206643e-005,,,,,,,,,,,,,,,,,,,,,
1616239616.630,,1.000000e+003,3.000181e+002,2.999952e+002,5,0,1.528046e+000,3.267007e-001,3.219398e-001,-1.055923e-001,-1.054537e-001,3.367693e-001,-9.076279e-002,-9.062418e-002,8.053062e-006,7.935708e-006,,,,,,,,,,,,,,,,,,,,
1616239616.630,,1.000000e+003,3.000181e+002,2.999952e+002,5,0,2.326999e+000,2.969451e-001,2.941069e-001,-1.354351e-001,-1.332866e-001,2.697007e-001,-1.598413e-001,-1.576928e-001,7.319598e-006,7.249637e-006,,,,,,,,,,,,,,,,,,,,
1616239616.630,,1.000000e+003,3.000181e+002,2.999952e+002,5,0,2.198691e+000,2.822962e-001,2.797326e-001,-1.498440e-001,-1.476609e-001,2.544043e-001,-1.751724e-001,-1.729892e-001,6.958508e-006,6.895317e-006,,,,,,,,,,,,,,,,,,,,